Workbook

Sheet POER AC 2.0 CD 4X4 TM DIESEL
A1: PLAN DE MANTENIMIENTO POER AC 2.0 CD 4X4 TM DIESEL
A2: GWM POER DIESEL | B2: 5.000 KM | C2: 10.000 KM | D2: 15.000 KM | E2: 20.000 KM | F2: 25.000 KM | G2: 30.000 KM | H2: 35.000 KM | I2: 40.000 KM | J2: 45.000 KM | K2: 50.000 KM | L2: 55.000 KM | M2: 60.000 KM | N2: 65.000 KM | O2: 70.000 KM | P2: 75.000 KM | Q2: 80.000 KM | R2: 85.000 KM | S2: 90.000 KM | T2: 95.000 KM | U2: 100.000 KM | V2: 105.000 KM | W2: 110.000 KM | X2: 115.000 KM | Y2: 120.000 KM | Z2: 125.000 KM | AA2: 130.000 KM | AB2: 135.000 KM | AC2: 140.000 KM | AD2: 145.000 KM | AE2: 150.000 KM | AF2: 155.000 KM | AG2: 160.000 KM | AH2: 165.000 KM | AI2: 170.000 KM | AJ2: 175.000 KM | AK2: 180.000 KM | AL2: 185.000 KM | AM2: 190.000 KM | AN2: 195.000 KM | AO2: 200.000 KM
A3: FILTRO DE ACEITE | B3: =11.84+2.5 -> 14.34 | C3: =11.84+2.5 -> 14.34 | D3: =11.84+2.5 -> 14.34 | E3: =11.84+2.5 -> 14.34 | F3: =11.84+2.5 -> 14.34 | G3: =11.84+2.5 -> 14.34 | H3: =11.84+2.5 -> 14.34 | I3: =11.84+2.5 -> 14.34 | ... AO3: =11.84+2.5 -> 14.34
A4: FILTRO DE COMBUSTIBLE | B4: =32.76+2.5 -> 35.26 | C4: =32.76+2.5 -> 35.26 | D4: =32.76+2.5 -> 35.26 | E4: =32.76+2.5 -> 35.26 | F4: =32.76+2.5 -> 35.26 | G4: =32.76+2.5 -> 35.26 | H4: =32.76+2.5 -> 35.26 | I4: =32.76+2.5 -> 35.26 | ... AO4: =32.76+2.5 -> 35.26
A5: FILTRO DE AIRE | C5: 20.99 | E5: 20.99 | G5: 20.99 | I5: 20.99 | K5: 20.99 | M5: 20.99 | O5: 20.99 | Q5: 20.99 | S5: 20.99 | U5: 20.99 | W5: 20.99 | Y5: 20.99 | AA5: 20.99 | AC5: 20.99 | AE5: 20.99 | AG5: 20.99 | AI5: 20.99 | AK5: 20.99 | AM5: 20.99 | AO5: 20.99
A6: PASTILLAS DE FRENO DEL | C6: 76.09 | E6: 76.09 | G6: 76.09 | I6: 76.09 | K6: 76.09 | M6: 76.09 | O6: 76.09 | Q6: 76.09 | S6: 76.09 | U6: 76.09 | W6: 76.09 | Y6: 76.09 | AA6: 76.09 | AC6: 76.09 | AE6: 76.09 | AG6: 76.09 | AI6: 76.09 | AK6: 76.09 | AM6: 76.09 | AO6: 76.09
A7: PASTILLAS DE FRENO POST | E7: 55.85 | I7: 55.85 | M7: 55.85 | Q7: 55.85 | U7: 55.85 | Y7: 55.85 | AC7: 55.85 | AG7: 55.85 | AK7: 55.85 | AO7: 55.85
A8: BANDA DE ACCESORIOS | Q8: 79.87 | AK8: 79.87
A9: FILTRO DE CABINA A/C | C9: 21.25 | E9: 21.25 | G9: 21.25 | I9: 21.25 | K9: 21.25 | M9: 21.25 | O9: 21.25 | Q9: 21.25 | S9: 21.25 | U9: 21.25 | W9: 21.25 | Y9: 21.25 | AA9: 21.25 | AC9: 21.25 | AE9: 21.25 | AG9: 21.25 | AI9: 21.25 | AK9: 21.25 | AM9: 21.25 | AO9: 21.25
A10: TERMOSTATO | K10: 12.71 | U10: 12.71 | AE10: 12.71 | AO10: 12.71
A11: BASE TERMOSTATO | K11: 11 | U11: 11 | AE11: 11 | AO11: 11
A12: TEMPLADOR BANDA DISTRIBUCION 4D20M | U12: 125.9 | AO12: 125.9
A13: RODAMIENTO BANDA DISTRIBUCION 4D20M | U13: 38 | AO13: 38
A14: BANDA DE DISTRIBUCION | U14: 88.84 | AO14: 88.84
A15: RODAMIENTO BANDA DISTRIBUCION | U15: 71.41 | AO15: 71.41
A16: ARANDELA DE TAPON DE CARTER | B16: 7.5 | C16: 7.5 | D16: 7.5 | E16: 7.5 | F16: 7.5 | G16: 7.5 | H16: 7.5 | I16: 7.5 | J16: 7.5 | K16: 7.5 | L16: 7.5 | M16: 7.5 | N16: 7.5 | O16: 7.5 | P16: 7.5 | Q16: 7.5 | R16: 7.5 | S16: 7.5 | T16: 7.5 | U16: 7.5 | V16: 7.5 | W16: 7.5 | X16: 7.5 | Y16: 7.5 | Z16: 7.5 | AA16: 7.5 | AB16: 7.5 | AC16: 7.5 | AD16: 7.5 | AE16: 7.5 | AF16: 7.5 | AG16: 7.5 | AH16: 7.5 | AI16: 7.5 | AJ16: 7.5 | AK16: 7.5 | AL16: 7.5 | AM16: 7.5 | AN16: 7.5 | AO16: 7.5
A17: TUBERIA ENTRADA RADIADOR POER | Z17: 25
A18: TUBERIA SALIDA RADIADOR POER | Z18: 71
A19: MANGUERA ENTRADA CALEFACTOR POER | Z19: 18
A20: MANGUERA SALIDA CALEFACTOR POER | Z20: 18
A21: BOMBA DE AGUA | Z21: 237.77
A22: EMPAQUE BOMBA DE AGUA | Z22: 5
A23: RODAMIENTO EJE DE ENTRADA | AD23: 48.62
A24: RODAMIENTO DE AGUJAS (H5-2.0TCI) | AD24: 6.95
A25: RODAMIENTO AGUJAS PIÑON 2DA | AD25: 9.65
A26: RODAMIENTO ENGRANAJE 1ERA | AD26: 13.37
A27: RODAM. CONTRA EJE DEL /31RUKSS2NRC3 | AD27: 53.36
A28: RODAMIENTO DE AGUJAS | AD28: 11.39
A29: RODAMIENTO AGUJAS PIÑON 4TA | AD29: 8.9
A30: RODAM. DE AGUJAS PIÑON DE REVERSA | AD30: 6.68
A31: RODAMIENTO | AD31: 32.61
A32: RODAMIENTO | AD32: 28.28
A33: ANILLO EXTERIOR COJINETE ESTAMPADO | AD33: 34.9
A34: ANILLO EXTERIOR COJINETE ESTAMPADO | AD34: 34.9
... A43: RODAMIENTO VOLANTE | AD43: 10
A44: EMPAQUE TAPA CABEZOTE 4D20M | AJ44: 52.5
A45: RETENEDOR ARBOL LEVAS MOT, 4D20 | AJ45: 8.12
A46: VALVULA DE ESCAPE 4D20M (8) | AJ46: 85.6
A47: VALVULA DE ADMISIÓN 4D20M (8) | AJ47: 76.08
A48: SELLO DE VALVULAS 4D20 - H6D (16) | AJ48: 48
...

Sheet POER AC 2.0 CD 4X2 TM DIESE
A1: PLAN DE MANTENIMIENTO POER AC 2.0 CD 4X2 TM DIESEL
A2: GWM POER DIESEL | B2: 5.000 KM | C2: 10.000 KM | D2: 15.000 KM | E2: 20.000 KM | F2: 25.000 KM | G2: 30.000 KM | H2: 35.000 KM | I2: 40.000 KM | J2: 45.000 KM | K2: 50.000 KM | L2: 55.000 KM | M2: 60.000 KM | N2: 65.000 KM | O2: 70.000 KM | P2: 75.000 KM | Q2: 80.000 KM | R2: 85.000 KM | S2: 90.000 KM | T2: 95.000 KM | U2: 100.000 KM | V2: 105.000 KM | W2: 110.000 KM | X2: 115.000 KM | Y2: 120.000 KM | Z2: 125.000 KM | AA2: 130.000 KM | AB2: 135.000 KM | AC2: 140.000 KM | AD2: 145.000 KM | AE2: 150.000 KM | AF2: 155.000 KM | AG2: 160.000 KM | AH2: 165.000 KM | AI2: 170.000 KM | AJ2: 175.000 KM | AK2: 180.000 KM | AL2: 185.000 KM | AM2: 190.000 KM | AN2: 195.000 KM | AO2: 200.000 KM
A3: FILTRO DE ACEITE | B3: =11.84+2.5 -> 14.34 | C3: =11.84+2.5 -> 14.34 | D3: =11.84+2.5 -> 14.34 | E3: =11.84+2.5 -> 14.34 | F3: =11.84+2.5 -> 14.34 | G3: =11.84+2.5 -> 14.34 | H3: =11.84+2.5 -> 14.34 | I3: =11.84+2.5 -> 14.34 | ... AO3: =11.84+2.5 -> 14.34
A4: FILTRO DE COMBUSTIBLE | B4: =32.76+2.5 -> 35.26 | C4: =32.76+2.5 -> 35.26 | D4: =32.76+2.5 -> 35.26 | E4: =32.76+2.5 -> 35.26 | F4: =32.76+2.5 -> 35.26 | G4: =32.76+2.5 -> 35.26 | H4: =32.76+2.5 -> 35.26 | I4: =32.76+2.5 -> 35.26 | ... AO4: =32.76+2.5 -> 35.26
A5: FILTRO DE AIRE | C5: 20.99 | E5: 20.99 | G5: 20.99 | I5: 20.99 | K5: 20.99 | M5: 20.99 | O5: 20.99 | Q5: 20.99 | S5: 20.99 | U5: 20.99 | W5: 20.99 | Y5: 20.99 | AA5: 20.99 | AC5: 20.99 | AE5: 20.99 | AG5: 20.99 | AI5: 20.99 | AK5: 20.99 | AM5: 20.99 | AO5: 20.99
A6: PASTILLAS DE FRENO DEL | C6: 76.09 | E6: 76.09 | G6: 76.09 | I6: 76.09 | K6: 76.09 | M6: 76.09 | O6: 76.09 | Q6: 76.09 | S6: 76.09 | U6: 76.09 | W6: 76.09 | Y6: 76.09 | AA6: 76.09 | AC6: 76.09 | AE6: 76.09 | AG6: 76.09 | AI6: 76.09 | AK6: 76.09 | AM6: 76.09 | AO6: 76.09
A7: PASTILLAS DE FRENO POST | E7: 55.85 | I7: 55.85 | M7: 55.85 | Q7: 55.85 | U7: 55.85 | Y7: 55.85 | AC7: 55.85 | AG7: 55.85 | AK7: 55.85 | AO7: 55.85
A8: BANDA DE ACCESORIOS | Q8: 79.87 | AK8: 79.87
A9: FILTRO DE CABINA A/C | C9: 21.25 | E9: 21.25 | G9: 21.25 | I9: 21.25 | K9: 21.25 | M9: 21.25 | O9: 21.25 | Q9: 21.25 | S9: 21.25 | U9: 21.25 | W9: 21.25 | Y9: 21.25 | AA9: 21.25 | AC9: 21.25 | AE9: 21.25 | AG9: 21.25 | AI9: 21.25 | AK9: 21.25 | AM9: 21.25 | AO9: 21.25
A10: TERMOSTATO | K10: 12.71 | U10: 12.71 | AE10: 12.71 | AO10: 12.71
A11: BASE TERMOSTATO | K11: 11 | U11: 11 | AE11: 11 | AO11: 11
A12: TEMPLADOR BANDA DISTRIBUCION 4D20M | U12: 125.9 | AO12: 125.9
A13: RODAMIENTO BANDA DISTRIBUCION 4D20M | U13: 38 | AO13: 38
A14: BANDA DE DISTRIBUCION | U14: 88.84 | AO14: 88.84
A15: RODAMIENTO BANDA DISTRIBUCION | U15: 71.41 | AO15: 71.41
A16: ARANDELA DE TAPON DE CARTER | B16: 7.5 | C16: 7.5 | D16: 7.5 | E16: 7.5 | F16: 7.5 | G16: 7.5 | H16: 7.5 | I16: 7.5 | J16: 7.5 | K16: 7.5 | L16: 7.5 | M16: 7.5 | N16: 7.5 | O16: 7.5 | P16: 7.5 | Q16: 7.5 | R16: 7.5 | S16: 7.5 | T16: 7.5 | U16: 7.5 | V16: 7.5 | W16: 7.5 | X16: 7.5 | Y16: 7.5 | Z16: 7.5 | AA16: 7.5 | AB16: 7.5 | AC16: 7.5 | AD16: 7.5 | AE16: 7.5 | AF16: 7.5 | AG16: 7.5 | AH16: 7.5 | AI16: 7.5 | AJ16: 7.5 | AK16: 7.5 | AL16: 7.5 | AM16: 7.5 | AN16: 7.5 | AO16: 7.5
A17: TUBERIA ENTRADA RADIADOR POER | Z17: 25
A18: TUBERIA SALIDA RADIADOR POER | Z18: 71
A19: MANGUERA ENTRADA CALEFACTOR POER | Z19: 18
A20: MANGUERA SALIDA CALEFACTOR POER | Z20: 18
A21: BOMBA DE AGUA | Z21: 237.77
A22: EMPAQUE BOMBA DE AGUA | Z22: 5
A23: RODAMIENTO EJE DE ENTRADA | AD23: 48.62
A24: RODAMIENTO DE AGUJAS (H5-2.0TCI) | AD24: 6.95
A25: RODAMIENTO AGUJAS PIÑON 2DA | AD25: 9.65
A26: RODAMIENTO ENGRANAJE 1ERA | AD26: 13.37
A27: RODAM. CONTRA EJE DEL /31RUKSS2NRC3 | AD27: 53.36
A28: RODAMIENTO DE AGUJAS | AD28: 11.39
A29: RODAMIENTO AGUJAS PIÑON 4TA | AD29: 8.9
A30: RODAM. DE AGUJAS PIÑON DE REVERSA | AD30: 6.68
A31: RODAMIENTO | AD31: 32.61
A32: RODAMIENTO | AD32: 28.28
A33: ANILLO EXTERIOR COJINETE ESTAMPADO | AD33: 34.9
A34: ANILLO EXTERIOR COJINETE ESTAMPADO | AD34: 34.9
... A43: RODAMIENTO VOLANTE | AD43: 10
A44: EMPAQUE TAPA CABEZOTE 4D20M | AJ44: 52.5
A45: RETENEDOR ARBOL LEVAS MOT, 4D20 | AJ45: 8.12
A46: VALVULA DE ESCAPE 4D20M (8) | AJ46: 85.6
A47: VALVULA DE ADMISIÓN 4D20M (8) | AJ47: 76.08
A48: SELLO DE VALVULAS 4D20 - H6D (16) | AJ48: 48
...

Sheet CRONOGRAMA MANT POER 4X4
A1: CRONOGRAMA DE MANTENIMIENTO POER AC 2.0 CD 4X4 TM DIESEL
A2: GWM POER DIESEL | B2: A/F | C2: 5.000 KM | D2: 10.000 KM | E2: 15.000 KM | F2: 20.000 KM | G2: 25.000 KM | H2: 30.000 KM | I2: 35.000 KM | J2: 40.000 KM | K2: 45.000 KM | L2: 50.000 KM | M2: 55.000 KM | N2: 60.000 KM | O2: 65.000 KM | P2: 70.000 KM | Q2: 75.000 KM | R2: 80.000 KM | S2: 85.000 KM | T2: 90.000 KM | U2: 95.000 KM | V2: 100.000 KM | W2: 105.000 KM | X2: 110.000 KM | Y2: 115.000 KM | Z2: 120.000 KM
A3: FILTRO DE ACEITE | B3: X | C3: 11.84 | D3: 11.84 | E3: 11.84 | F3: 11.84 | G3: 11.84 | H3: 11.84 | I3: 11.84 | J3: 11.84 | K3: 11.84 | L3: 11.84 | M3: 11.84 | N3: 11.84 | O3: 11.84 | P3: 11.84 | Q3: 11.84 | R3: 11.84 | S3: 11.84 | T3: 11.84 | U3: 11.84 | V3: 11.84 | W3: 11.84 | X3: 11.84 | Y3: 11.84 | Z3: 11.84
A4: FILTRO DE COMBUSTIBLE | B4: 32.76 | C4: 32.76 | D4: 32.76 | E4: 32.76 | F4: 32.76 | G4: 32.76 | H4: 32.76 | I4: 32.76 | J4: 32.76 | K4: 32.76 | L4: 32.76 | M4: 32.76 | N4: 32.76 | O4: 32.76 | P4: 32.76 | Q4: 32.76 | R4: 32.76 | S4: 32.76 | T4: 32.76 | U4: 32.76 | V4: 32.76 | W4: 32.76 | X4: 32.76 | Y4: 32.76 | Z4: 32.76
A5: FILTRO DE AIRE | D5: 20.99 | F5: 20.99 | H5: 20.99 | J5: 20.99 | L5: 20.99 | N5: 20.99 | P5: 20.99 | R5: 20.99 | T5: 20.99 | V5: 20.99 | X5: 20.99 | Z5: 20.99
A6: PASTILLAS DE FRENO DEL | F6: 76.09 | H6: 76.09 | J6: 76.09 | L6: 76.09 | N6: 76.09 | P6: 76.09 | R6: 76.09 | T6: 76.09 | V6: 76.09 | Z6: 76.09
A7: PASTILLAS DE FRENO POST | D7: 0 | F7: 55.85 | J7: 55.85 | N7: 55.85 | R7: 55.85 | V7: 55.85 | X7: 0 | Z7: 55.85
A8: TOTAL REPUESTOS | B8: =SUM(B3:B7) -> 32.76 | C8: =SUM(C3:C7) -> 44.6 | D8: =SUM(D3:D7) -> 65.59 | E8: =SUM(E3:E7) -> 44.6 | F8: =SUM(F3:F7) -> 197.53 | G8: =SUM(G3:G7) -> 44.6 | H8: =SUM(H3:H7) -> 141.68 | I8: =SUM(I3:I7) -> 44.6 | ... Z8: =SUM(Z3:Z7) -> 197.53
A9: ACEITE MOTOR | B9: 40.32 | C9: 40.32 | D9: 40.32 | E9: 40.32 | F9: 40.32 | G9: 40.32 | H9: 40.32 | I9: 40.32 | J9: 40.32 | K9: 40.32 | L9: 40.32 | M9: 40.32 | N9: 40.32 | O9: 40.32 | P9: 40.32 | Q9: 40.32 | R9: 40.32 | S9: 40.32 | T9: 40.32 | U9: 40.32 | V9: 40.32 | W9: 40.32 | X9: 40.32 | Y9: 40.32 | Z9: 40.32
A10: LIQUIDO INYECTORES | F10: 7.71 | J10: 7.71 | N10: 7.71 | R10: 7.71 | V10: 7.71 | Z10: 7.71
A11: LIMPIADOR DE FRENOS | D11: 6.16 | F11: 6.16 | H11: 6.16 | J11: 6.16 | L11: 6.16 | N11: 6.16 | P11: 6.16 | R11: 6.16 | T11: 6.16 | V11: 6.16 | X11: 6.16 | Z11: 6.16
A12: LIMPIADOR DE ADMISION | D12: 6.62 | F12: 6.62 | H12: 6.62 | J12: 6.62 | L12: 6.62 | N12: 6.62 | P12: 6.62 | R12: 6.62 | T12: 6.62 | V12: 6.62 | X12: 6.62 | Z12: 6.62
A13: REFRIGERANTE | L13: 17.73 | V13: 17.73
A14: ACEITE DE CAJA Y TRANS | C14: 54.81 | L14: 54.81 | V14: 54.81
A15: SUMINISTROS | B15: 3.5 | C15: 3.5 | D15: 3.5 | E15: 3.5 | F15: 3.5 | G15: 3.5 | H15: 3.5 | I15: 3.5 | J15: 3.5 | K15: 3.5 | L15: 3.5 | M15: 3.5 | N15: 3.5 | O15: 3.5 | P15: 3.5 | Q15: 3.5 | R15: 3.5 | S15: 3.5 | T15: 3.5 | U15: 3.5 | V15: 3.5 | W15: 3.5 | X15: 3.5 | Y15: 3.5 | Z15: 3.5
A16: LIQUIDO DE FRENOS | F16: 3.59 | J16: 3.59 | N16: 3.59 | R16: 3.59 | V16: 3.59 | Z16: 3.59
A17: TOTAL LUBRICANTES | B17: =SUM(B9:B16) -> 43.82 | C17: =SUM(C9:C16) -> 98.63 | D17: =SUM(D9:D16) -> 56.6 | E17: =SUM(E9:E16) -> 43.82 | F17: =SUM(F9:F16) -> 67.9 | G17: =SUM(G9:G16) -> 43.82 | H17: =SUM(H9:H16) -> 56.6 | I17: =SUM(I9:I16) -> 43.82 | ... Z17: =SUM(Z9:Z16) -> 67.9
A18: MANO DE OBRA | B18: 15.18 | C18: 20.79 | D18: 137.28 | E18: 15.18 | F18: 146.19 | G18: 15.18 | H18: 157.08 | I18: 15.18 | J18: 181.5 | K18: 15.18 | L18: 150.81 | M18: 15.18 | N18: 163.35 | O18: 15.18 | P18: 128.04 | Q18: 15.18 | R18: 147.51 | S18: 15.18 | T18: 161.04 | U18: 15.18 | V18: 289.74 | W18: 15.18 | X18: 137.28 | Y18: 15.18 | Z18: 163.35
A19: ALINEACION Y BALANCEO | B19: 0 | C19: 0 | D19: 17.16 | E19: 0 | F19: 17.16 | G19: 0 | H19: 17.16 | I19: 0 | J19: 17.16 | K19: 0 | L19: 17.16 | M19: 0 | N19: 17.16 | O19: 0 | P19: 17.16 | Q19: 0 | R19: 17.16 | S19: 0 | T19: 17.16 | U19: 0 | V19: 17.16 | W19: 0 | X19: 17.16 | Y19: 0 | Z19: 17.16
A20: BALANCEO | D20: 15.84 | F20: 15.84 | H20: 15.84 | J20: 15.84 | L20: 15.84 | N20: 15.84 | P20: 15.84 | R20: 15.84 | T20: 15.84 | V20: 15.84 | X20: 15.84 | Z20: 15.84
A21: LIMPIEZA DE INYECTORES | B21: 0 | C21: 0 | D21: 0 | E21: 0 | F21: 16.5 | G21: 0 | H21: 0 | I21: 0 | J21: 16.5 | K21: 0 | L21: 0 | M21: 0 | N21: 16.5 | O21: 0 | P21: 0 | Q21: 0 | R21: 16.5 | S21: 0 | T21: 0 | U21: 0 | V21: 16.5 | W21: 0 | X21: 0 | Y21: 0 | Z21: 16.5
A22: LAVADO | D22: 9.9 | F22: 9.9 | H22: 9.9 | J22: 9.9 | L22: 9.9 | N22: 9.9 | P22: 9.9 | R22: 9.9 | T22: 9.9 | V22: 9.9 | X22: 9.9 | Z22: 9.9
A23: TOTAL M/O | B23: =SUM(B18:B22) -> 15.18 | C23: =SUM(C18:C22) -> 20.79 | D23: =SUM(D18:D22) -> 180.18 | E23: =SUM(E18:E22) -> 15.18 | F23: =SUM(F18:F22) -> 205.59 | G23: =SUM(G18:G22) -> 15.18 | H23: =SUM(H18:H22) -> 199.98 | I23: =SUM(I18:I22) -> 15.18 | ... Z23: =SUM(Z18:Z22) -> 222.75
A24: TOTAL MANTENIMIENTO X KM | B24: =+B8+B17+B23 -> 91.76 | C24: =+C8+C17+C23 -> 164.02 | D24: =+D8+D17+D23 -> 302.37 | E24: =+E8+E17+E23 -> 103.6 | F24: =+F8+F17+F23 -> 471.02 | G24: =+G8+G17+G23 -> 103.6 | H24: =+H8+H17+H23 -> 398.26 | I24: =+I8+I17+I23 -> 103.6 | ... Z24: =+Z8+Z17+Z23 -> 488.18

Sheet CONSOLIDADO DE VALORES
B2: COSTOS MANTENIMIENTO POER 4X4 | G2: CANTIDAD DE VEHICULOS
B3: 1 | C3: Total Repuestos | D3: Mantenimiento preventivo | E3: ='POER AC 2.0 CD 4X4 TM DIESEL'!AP55*G3 -> 8178.91 | G3: 1
B4: 2 | C4: Total Lubricantes | E4: ='POER AC 2.0 CD 4X4 TM DIESEL'!AP67*G3 -> 3019.67
B5: 3 | C5: Total Mano de Obra | E5: ='POER AC 2.0 CD 4X4 TM DIESEL'!AP76*G3 -> 6104.45
B6: 4 | C6: Mantenimiento correctivo | D6: Se considera un valor aproximado del 30% del costo total de mantenimientos preventivos | E6: =(E3+E4+E5)*0.3 -> 5190.909
B7: Total 1 + 2 + 3 + 4 | E7: =SUM(E3:E6) -> 22493.939
B8: Costos no incluyen IVA
B11: COSTOS MANTENIMIENTO POER 4X2 | G11: CANTIDAD DE VEHICULOS
B12: 1 | C12: Total Repuestos | D12: Mantenimiento preventivo | E12: ='POER AC 2.0 CD 4X2 TM DIESE'!AP55*G12 -> 8178.91 | G12: 1
B13: 2 | C13: Total Lubricantes | E13: ='POER AC 2.0 CD 4X2 TM DIESE'!AP65*G12 -> 2816.94
B14: 3 | C14: Total Mano de Obra | E14: ='POER AC 2.0 CD 4X2 TM DIESE'!AP74*G12 -> 6104.45
B15: 4 | C15: Mantenimiento correctivo | D15: Se considera un valor aproximado del 30% del costo total de mantenimientos preventivos | E15: =(E12+E13+E14)*0.3 -> 5130.09
B16: Total 1 + 2 + 3 + 4 | E16: =SUM(E12:E15) -> 22230.39
B17: Costos no incluyen IVA

Sheet REF MANT CORRECTIVO
A1: MARCA | B1: GWM
A2: MODELO | B2: POER 2.0 AC | C2: MANTENIMIENTOS CORRECTIVOS
A3: ITEM | B3: DESCRIPCION | C3: TOTAL REPUESTOS | D3: Total M/O | E3: TOTAL LUBRICANTES | F3: SUBTOTAL
A4: 1 | B4: BOMBA DE COMBUSTIBLE ALTA PRESION | C4: =G4*1.1 -> 1172.952 | D4: 264 | F4: =C4+D4+E4 -> 1436.952 | G4: 1066.32 | H4: 72.6 | J4: 0.15
A5: 2 | B5: TURBO | C5: 966 | D5: =34*8 -> 272 | F5: =C5+D5+E5 -> 1238
A6: 3 | B6: BOMBA AGUA | C6: =G6*1.1 -> 237.765 | D6: 165 | E6: 35.44 | F6: =C6+D6+E6 -> 438.205 | G6: 216.15 | H6: 57.75
A7: 4 | B7: BOMBA DIRECCION HIDRAULICA | C7: =G7*1.1 -> 300.465 | D7: 132 | E7: =8.71*2 -> 17.42 | F7: =C7+D7+E7 -> 449.885 | G7: 273.15 | H7: 67.65
A8: 5 | B8: AMORTIGUADORE DELANTERO (1) | C8: =G8*1.1 -> 187.396 | D8: 49.5 | F8: =C8+D8+E8 -> 236.896 | G8: 170.36 | H8: 79.2
A9: 6 | B9: AMORTIGUADOR POSTERIOR (1) | C9: =G9*1.1 -> 125.411 | D9: 49.5 | F9: =C9+D9+E9 -> 174.911 | G9: 114.01 | H9: 56.1
A10: 7 | B10: DISCO Y PLATO EMBRAGUE | C10: 350 | D10: 165 | F10: =+C10+D10+E10+C11+C12 -> 575
A11: 8 | B11: RODAMIENTO EMBRAGUE | C11: 50
A12: 9 | B12: RODAMIENTO VOLANTE | C12: 10
A13: 10 | B13: RODAMIENTO MANZANA RUEDA DELT POER (1) | C13: 100 | D13: 68 | F13: =C13+D13+E13 -> 168 | G13: 81.47 | H13: 61.05
A14: 11 | B14: DISCO DE FRENO DELANTERO (1) | C14: 135 | D14: 49.5 | F14: =C14+D14+E14 -> 184.5 | G14: 128.79 | H14: 16.5
A15: 12 | B15: DISCO DE FRENO POSTERIOR (1) | C15: 120 | D15: 49.5 | F15: =C15+D15+E15 -> 169.5 | G15: 94.12 | H15: 16.5
A16: 13 | B16: BUJES DEL COLGANTE DEL PAQUETE POSTERIOR (8) | C16: 30 | D16: 82.5 | F16: =C16+D16+E16 -> 112.5 | G16: 189.85 | H16: 41.25
A17: 14 | B17: PAQUETE POSTERIOR | C17: 230.24 | D17: 115.5 | F17: =C17+D17+E17 -> 345.74
A18: 15 | B18: EJE CARDAN COMPLETO | C18: 385.5 | D18: 66 | F18: =C18+D18+E18 -> 451.5 | G18: 35 | H18: 66
A19: 16 | B19: CRUCETA CARDAN POER BJXPJ | C19: 30 | D19: 68 | F19: =C19+D19+E19 -> 98
A20: 17 | B20: BOMBA DE FRENO | C20: =G20*1.1 -> 199.496 | D20: 165 | E20: 15 | F20: =C20+D20+E20 -> 379.496 | G20: 181.36 | H20: 41.25
A21: 18 | B21: BOMBA DE EMBRAGUE (PRINCIPAL) | C21: 75 | D21: 66 | E21: 15 | F21: =C21+D21+E21 -> 156 | G21: 58.05 | H21: 61.05
A22: 19 | B22: INYECTORES | C22: =G22*1.1 -> 352.781 | D22: 49.5 | F22: =C22+D22+E22 -> 402.281 | G22: 320.71 | H22: 41.25
A23: 20 | B23: CREMALLERA DE DIRECCION | C23: 650.53 | D23: 132 | E23: =8.71*2 -> 17.42 | F23: =C23+D23+E23 -> 799.95 | G23: 544.66 | H23: 74.25 | I23: 14.85
A24: 21 | B24: TERMINAL DE LA DIRECCIÓN RH | C24: 70 | D24: 66 | F24: =C24+D24+E24 -> 136
A25: 22 | B25: TERMINAL DE LA CIRECCIÓN LH | C25: 70 | D25: 66 | F25: =C25+D25+E25 -> 136
A26: 23 | B26: MESA SUPERIOR | C26: 190.41 | D26: 66 | F26: =C26+D26+E26 -> 256.41
A27: 24 | B27: MESA INFERIOR | C27: 394.61 | D27: 66 | F27: =C27+D27+E27 -> 460.61
A28: 25 | B28: COMPRESOR A/C | C28: 488 | D28: 99 | F28: =C28+D28+E28 -> 587 | G28: 413.24 | H28: 49.5
A29: 26 | B29: BANDA DE SERVICIO | C29: =G29*1.1 -> 37.686 | D29: 16.5 | F29: =C29+D29+E29 -> 54.186 | G29: 34.26 | H29: 14.85
A30: 27 | B30: SENSOR TPMS | C30: 62 | D30: 33 | F30: =C30+D30+E30 -> 95 | G30: 52.84 | H30: 26.4
A31: 28 | B31: PLUMAS LH(LIMPIAPRABRISAS) | C31: 81.99 | D31: 8.5 | F31: =+C31+D31+E31 -> 90.49
A32: 29 | B32: PLUMAS RH(LIMPIAPRABRISAS)
A33: 30 | B33: PASTILLAS DE FRENO DEL | C33: 76.09 | D33: 42.5 | F33: =SUM(C33:E33) -> 118.59
A34: 31 | B34: PASTILLAS DE FRENO POST | C34: 55.85 | D34: 42.5 | F34: =SUM(C34:E34) -> 98.35
A35: 32 | B35: FOCOS 1 CONTACTO | C35: 1.25 | D35: 6.6 | F35: =SUM(C35:E35) -> 7.85 | G35: 12 | H35: 6.6
A36: 33 | B36: FOCOS 2 CONTACTOS | C36: 1.3 | D36: 6.6 | F36: =SUM(C36:E36) -> 7.9
A37: 34 | B37: FOCO HALÓGENO | C37: 12 | D37: 6.6 | F37: =SUM(C37:E37) -> 18.6
A38: 35 | B38: BATERIA | C38: 180 | D38: 10 | F38: =SUM(C38:E38) -> 190
A39: 36 | B39: ENLLANTAJE C/U | C39: 0 | D39: 6.5 | F39: =SUM(C39:E39) -> 6.5
A40: 37 | B40: PARCHE NEUMÁTICO C/U | C40: 0 | D40: 15 | F40: =SUM(C40:E40) -> 15
...
