Workbook

Sheet W7 DIESEL 120K
A1: WINGLE 7 DIESEL | B1: INTERMEDIOS | C1: 5000 | D1: 10000 | E1: 20000 | F1: 30000 | G1: 40000 | H1: 50000 | I1: 60000 | J1: 70000 | K1: 80000 | L1: 90000 | M1: 100000 | N1: 110000 | O1: 120000 | R1: CANTIDAD MANT. INTERMEDIOS | U1: INTERMEDIOS
A2: ACEITE MOTOR | B2: =$R$2*U2 -> 245.88 | C2: 40.98 | D2: 40.98 | E2: 40.98 | F2: 40.98 | G2: 40.98 | H2: 40.98 | I2: 40.98 | J2: 40.98 | R2: 6 | U2: =40.98 -> 40.98
A3: FILTRO DE ACEITE | B3: =$R$2*U3 -> 36.06 | C3: 6.01 | D3: 6.01 | E3: 6.01 | F3: 6.01 | G3: 6.01 | H3: 6.01 | I3: 6.01 | J3: 6.01 | U3: =6.01 -> 6.01
A4: FILTROS DE COMBUSTIBLE | B4: =$R$2*U4 -> 39 | C4: 6.5 | D4: 6.5 | E4: 6.5 | F4: 6.5 | G4: 6.5 | H4: 6.5 | I4: 6.5 | J4: 6.5 | U4: =6.5 -> 6.5
A5: FILTRO TRAMPA DE AGUA/COMB | B5: =$R$2*U5 -> 105.3 | C5: 17.55 | D5: 17.55 | E5: 17.55 | F5: 17.55 | G5: 17.55 | H5: 17.55 | I5: 17.55 | J5: 17.55 | U5: =17.55 -> 17.55
A6: FILTRO DE AIRE | B6: =$R$2*U6 -> 0 | D6: 10.45 | E6: 10.45 | F6: 10.45 | G6: 10.45 | H6: 10.45 | I6: 10.45 | J6: 10.45
A7: FILTRO DE CABINA A/C | B7: =$R$2*U7 -> 0 | D7: 7.69 | E7: 7.69 | F7: 7.69 | G7: 7.69 | H7: 7.69 | I7: 7.69 | J7: 7.69
A8: PASTILLAS DE FRENO DEL | B8: =$R$2*U8 -> 0 | D8: 26.87 | F8: 26.87 | H8: 26.87 | J8: 26.87
A9: PASTILLAS DE FRENOS POST | B9: =$R$2*U9 -> 0 | D9: 27 | F9: 27 | H9: 27 | J9: 27
A10: LIQUIDO INYECTORES | B10: =$R$2*U10 -> 0 | E10: 6.5 | G10: 6.5 | I10: 6.5
A11: LIMPIADOR DE FRENOS | B11: =$R$2*U11 -> 0 | D11: 5 | E11: 5 | F11: 5 | G11: 5 | H11: 5 | I11: 5 | J11: 5
A12: LIMPIADOR DE ADMISION | B12: =$R$2*U12 -> 0 | D12: 5.4 | E12: 5.4 | F12: 5.4 | G12: 5.4 | H12: 5.4 | I12: 5.4 | J12: 5.4
A13: REFRIGERANTE | B13: =$R$2*U13 -> 0 | G13: 15
A14: DISTRIBUCION | B14: =$R$2*U14 -> 0
A15: ACEITE DE CAJA | B15: =$R$2*U15 -> 0 | C15: 31.56 | H15: 31.56
A16: ACEITE DIFERENCIAL/TRANSFER | B16: =$R$2*U16 -> 0 | C16: 22.5 | H16: 22.5
A17: SUMINISTROS | B17: =$R$2*U17 -> 21 | C17: 3.5 | D17: 3.5 | E17: 3.5 | F17: 3.5 | G17: 3.5 | H17: 3.5 | I17: 3.5 | J17: 3.5 | U17: =3.5 -> 3.5
A18: ACEITE DIRECCION HIDRAULICA | B18: =$R$2*U18 -> 0 | F18: 7.33 | I18: 7.33
A19: LIQUIDO DE FRENOS | B19: =R19*U19 -> 0 | C19: 0 | D19: 0 | E19: 12 | F19: 0 | G19: 12 | H19: 0 | I19: 12 | J19: 0 | U19: 0
A20: TOTAL REPUESTOS | B20: =B3+B4+B5+B6+B8+B9+B10+B11+B12+B14+B17+B7 -> 201.36 | C20: =C3+C4+C5+C6+C8+C9+C10+C11+C12+C14+C17+C7 -> 33.56 | D20: =D3+D4+D5+D6+D8+D9+D10+D11+D12+D14+D17+D7 -> 115.97 | E20: =E3+E4+E5+E6+E8+E9+E10+E11+E12+E14+E17+E7 -> 68.6 | F20: =F3+F4+F5+F6+F8+F9+F10+F11+F12+F14+F17+F7 -> 115.97 | G20: =G3+G4+G5+G6+G8+G9+G10+G11+G12+G14+G17+G7 -> 68.6 | H20: =H3+H4+H5+H6+H8+H9+H10+H11+H12+H14+H17+H7 -> 115.97 | I20: =I3+I4+I5+I6+I8+I9+I10+I11+I12+I14+I17+I7 -> 68.6 | J20: =J3+J4+J5+J6+J8+J9+J10+J11+J12+J14+J17+J7 -> 115.97 | P20: =SUM(B20:O20) -> 904.6 | U20: =U3+U4+U5+U6+U8+U9+U10+U11+U12+U14+U17+U7 -> 33.56
A21: TOTAL MANO DE OBRA | B21: =R2*U21 -> 88.68 | C21: 19.4 | D21: 157 | E21: 181.69 | F21: 175.34 | G21: 213.44 | H21: 169.34 | I21: 196.51 | J21: 148.18 | P21: =SUM(B21:O21) -> 1349.58 | U21: =14.78 -> 14.78
A22: ALINEACION | B22: 0 | C22: 0 | D22: 17.16 | E22: 17.16 | F22: 17.16 | G22: 17.16 | H22: 17.16 | I22: 17.16 | J22: 17.16 | U22: 0
A23: BALANCEO | D23: 15.84 | E23: 15.84 | F23: 15.84 | G23: 15.84 | H23: 15.84 | I23: 15.84 | J23: 15.84
A24: LIMPIEZA DE INYECTORES | B24: 0 | C24: 0 | D24: 0 | E24: 16.5 | F24: 0 | G24: 16.5 | H24: 0 | I24: 16.5 | J24: 0 | U24: 0
A25: TOTAL M/O | B25: =SUM(B21:B24) -> 88.68 | F25: =SUM(F21:F24) -> 208.34 | G25: =SUM(G21:G24) -> 262.94 | H25: =SUM(H21:H24) -> 202.34 | I25: =SUM(I21:I24) -> 246.01 | J25: =SUM(J21:J24) -> 181.18 | U25: =SUM(U21:U24) -> 14.78
A26: TOTAL | B26: =+B20+B25 -> 290.04 | F26: =+F20+F25 -> 324.31 | G26: =+G20+G25 -> 331.54 | H26: =+H20+H25 -> 318.31 | I26: =+I20+I25 -> 314.61 | J26: =+J20+J25 -> 297.15 | U26: =+U20+U25 -> 48.34
A27: *LUBRICANTES | B27: =B2+B13+B15+B16+B18+B19 -> 245.88 | C27: =C2+C13+C15+C16+C18+C19 -> 95.04 | D27: =D2+D13+D15+D16+D18+D19 -> 40.98 | E27: =E2+E13+E15+E16+E18+E19 -> 52.98 | F27: =F2+F13+F15+F16+F18+F19 -> 48.31 | G27: =G2+G13+G15+G16+G18+G19 -> 67.98 | H27: =H2+H13+H15+H16+H18+H19 -> 95.04 | I27: =I2+I13+I15+I16+I18+I19 -> 60.31 | J27: =J2+J13+J15+J16+J18+J19 -> 40.98 | P27: =SUM(B27:O27) -> 747.5 | Q27: 30% MANT. PREV. | U27: =U2+U13+U15+U16+U18+U19 -> 40.98
B28: =B20+B21+B27 -> 535.92 | C28: =C20+C21+C27 -> 148 | D28: =D20+D21+D27 -> 313.95 | E28: =E20+E21+E27 -> 303.27 | F28: =F20+F21+F27 -> 339.62 | G28: =G20+G21+G27 -> 350.02 | H28: =H20+H21+H27 -> 380.35 | I28: =I20+I21+I27 -> 325.42 | ... O28: =O20+O21+O27 -> 0 | P28: =SUM(P20:P27) -> 3001.68 | Q28: =P28*0.3 -> 900.504
J29: =SUM(B28:J28) -> 3001.68 | O29: =SUM(B28:O28) -> 3001.68 | P29: TOTAL
A30: WINGLE 7 PLAN DE MANTENIMIENTO | P30: =SUM(P28:Q28) -> 3902.184
A31: MOTORES DIESEL | B31: INTERMEDIO | C31: 5000 | D31: 10000 | E31: 20000 | F31: 30000 | G31: 40000 | H31: 50000 | I31: 60000 | J31: 70000 | K31: 80000 | L31: 90000 | M31: 100000 | N31: 110000 | O31: 120000
A32: ACEITE MOTOR | B32: X | C32: X | D32: X | E32: X | F32: X | G32: X | H32: X | I32: X | J32: X | K32: X | L32: X | M32: X | N32: X | O32: X
A33: FILTRO DE ACEITE | B33: X | C33: X | D33: X | E33: X | F33: X | G33: X | H33: X | I33: X | J33: X | K33: X | L33: X | M33: X | N33: X | O33: X
A34: FILTROS DE COMBUSTIBLE | B34: X | C34: X | D34: X | E34: X | F34: X | G34: X | H34: X | I34: X | J34: X | K34: X | L34: X | M34: X | N34: X | O34: X
A35: FILTRO DE AIRE | D35: X | E35: X | F35: X | G35: X | H35: X | I35: X | J35: X | K35: X | L35: X | M35: X | N35: X | O35: X
A36: PASTILLAS DE FRENO | D36: X | F36: X | H36: X | J36: X | L36: X | N36: X
A37: LIQUIDO INYECTORES | E37: X | G37: X | I37: X | K37: X | M37: X | O37: X
A38: LIMPIADOR DE FRENOS | D38: X | E38: X | F38: X | G38: X | H38: X | I38: X | J38: X | K38: X | L38: X | M38: X | N38: X | O38: X
A39: LIMPIADOR DE ADMISION | D39: X | E39: X | F39: X | G39: X | H39: X | I39: X | J39: X | K39: X | L39: X | M39: X | N39: X | O39: X
A40: REFRIGERANTE | G40: X | K40: X | O40: X
...

Sheet DETALLADO MANT 4X4
A1: PLAN DE MANTENIMIENTO PREVENTIVO WINGLE 7 4X4
A2: WINGLE 7 DIESEL | B2: 5000 | C2: 10000 | D2: 15000 | E2: 20000 | F2: 25000 | G2: 30000 | H2: 35000 | I2: 40000 | J2: 45000 | K2: 50000 | L2: 55000 | M2: 60000 | N2: 65000 | O2: 70000 | P2: 75000 | Q2: 80000 | R2: 85000 | S2: 90000 | T2: 95000 | U2: 100000 | V2: 105000 | W2: 110000 | X2: 115000 | Y2: 120000 | Z2: 125000 | AA2: 130000 | AB2: 135000 | AC2: 140000 | AD2: 145000 | AE2: 150000 | AF2: 155000 | AG2: 160000 | AH2: 165000 | AI2: 170000 | AJ2: 175000 | AK2: 180000 | AL2: 185000 | AM2: 190000 | AN2: 195000 | AO2: 200000 | AP2: 205000 | AQ2: 210000 | AR2: 215000 | AS2: 220000 | AT2: 225000 | AU2: 230000 | AV2: 235000 | AW2: 240000 | AX2: 245000 | AY2: 250000
A3: ACEITE MOTOR (10W40) 6lt | B3: 43.98 | C3: 43.98 | D3: 43.98 | E3: 43.98 | F3: 43.98 | G3: 43.98 | H3: 43.98 | I3: 43.98 | J3: 43.98 | K3: 43.98 | L3: 43.98 | M3: 43.98 | N3: 43.98 | O3: 43.98 | P3: 43.98 | Q3: 43.98 | R3: 43.98 | S3: 43.98 | T3: 43.98 | U3: 43.98 | V3: 43.98 | W3: 43.98 | X3: 43.98 | Y3: 43.98 | Z3: 43.98 | AA3: 43.98 | AB3: 43.98 | AC3: 43.98 | AD3: 43.98 | AE3: 43.98 | AF3: 43.98 | AG3: 43.98 | AH3: 43.98 | AI3: 43.98 | AJ3: 43.98 | AK3: 43.98 | AL3: 43.98 | AM3: 43.98 | AN3: 43.98 | AO3: 43.98 | AP3: 43.98 | AQ3: 43.98 | AR3: 43.98 | AS3: 43.98 | AT3: 43.98 | AU3: 43.98 | AV3: 43.98 | AW3: 43.98 | AX3: 43.98 | AY3: 43.98
A4: ACEITE DE CAJA (75W90) 3lt | K4: 28.23 | U4: 28.23 | AD4: 28.23 | AK4: 28.23 | AQ4: 28.23 | AW4: 28.23
A5: ACEITE DIFERENCIAL DELANTERO (80W90) 3lt | K5: 26.61 | U5: 26.61 | AE5: 26.61 | AK5: 26.61 | AQ5: 26.61 | AW5: 26.61 | AY5: 26.61
A6: ACEITE DIFERENCIAL POSTERIOR (80W90) 3lt | K6: 26.61 | U6: 26.61 | AE6: 26.61 | AK6: 26.61 | AQ6: 26.61 | AW6: 26.61 | AY6: 26.61
A7: ACEITE TRANSFER (ATF3-DEXRON3) 3 lt | K7: 26.13 | U7: 26.13 | AE7: 26.13 | AK7: 26.13 | AQ7: 26.13 | AW7: 26.13 | AY7: 26.13
A8: ACEITE DIRECCION HIDRAULICA | K8: 8.71 | U8: 8.71 | Z8: 8.71 | AE8: 8.71 | AO8: 8.71 | AY8: 8.71
A9: REFRIGERANTE 8lt | K9: 35.44 | U9: 35.44 | Z9: 35.44 | AE9: 35.44 | AJ9: 35.44 | AO9: 35.44 | AY9: 35.44
A10: LIQUIDO DE FRENOS (2 de 500ml) | G10: 18 | M10: 18 | S10: 18 | Y10: 18 | AE10: 18 | AK10: 18 | AQ10: 18 | AW10: 18
A11: TOTAL LUBRICANTES | B11: =SUM(B3:B10) -> 43.98 | C11: =SUM(C3:C10) -> 43.98 | D11: =SUM(D3:D10) -> 43.98 | E11: =SUM(E3:E10) -> 43.98 | F11: =SUM(F3:F10) -> 43.98 | G11: =SUM(G3:G10) -> 61.98 | H11: =SUM(H3:H10) -> 43.98 | I11: =SUM(I3:I10) -> 43.98 | ... AY11: =SUM(AY3:AY10) -> 167.48 | AZ11: =SUM(B11:AY11) -> 3368.17
A12: FILTRO DE ACEITE | B12: =7.07+1.5 -> 8.57 | C12: =7.07+1.5 -> 8.57 | D12: =7.07+1.5 -> 8.57 | E12: =7.07+1.5 -> 8.57 | F12: =7.07+1.5 -> 8.57 | G12: =7.07+1.5 -> 8.57 | H12: =7.07+1.5 -> 8.57 | I12: =7.07+1.5 -> 8.57 | ... AY12: =7.07+1.5 -> 8.57
A13: FILTROS DE COMBUSTIBLE | B13: =6.5+1.5 -> 8 | C13: =6.5+1.5 -> 8 | D13: =6.5+1.5 -> 8 | E13: =6.5+1.5 -> 8 | F13: =6.5+1.5 -> 8 | G13: =6.5+1.5 -> 8 | H13: =6.5+1.5 -> 8 | I13: =6.5+1.5 -> 8 | ... AY13: =6.5+1.5 -> 8
A14: FILTRO TRAMPA DE AGUA/COMB | B14: =19.09+1.5 -> 20.59 | C14: =19.09+1.5 -> 20.59 | D14: =19.09+1.5 -> 20.59 | E14: =19.09+1.5 -> 20.59 | F14: =19.09+1.5 -> 20.59 | G14: =19.09+1.5 -> 20.59 | H14: =19.09+1.5 -> 20.59 | I14: =19.09+1.5 -> 20.59 | ... AY14: =19.09+1.5 -> 20.59
A15: FILTRO DE AIRE | C15: 10.45 | E15: 10.45 | G15: 10.45 | I15: 10.45 | K15: 10.45 | M15: 10.45 | O15: 10.45 | Q15: 10.45 | S15: 10.45 | U15: 10.45 | W15: 10.45 | Y15: 10.45 | AA15: 10.45 | AC15: 10.45 | AE15: 10.45 | AG15: 10.45 | AI15: 10.45 | AK15: 10.45 | AM15: 10.45 | AO15: 10.45 | AQ15: 10.45 | AS15: 10.45 | AU15: 10.45 | AW15: 10.45 | AY15: 10.45
A16: FILTRO DE CABINA A/C | C16: 8.77 | E16: 8.77 | G16: 8.77 | I16: 8.77 | K16: 8.77 | M16: 8.77 | O16: 8.77 | Q16: 8.77 | S16: 8.77 | U16: 8.77 | W16: 8.77 | Y16: 8.77 | AA16: 8.77 | AC16: 8.77 | AE16: 8.77 | AG16: 8.77 | AI16: 8.77 | AK16: 8.77 | AM16: 8.77 | AO16: 8.77 | AQ16: 8.77 | AS16: 8.77 | AU16: 8.77 | AW16: 8.77 | AY16: 8.77
A17: PASTILLAS DE FRENO DEL | C17: 29.16 | E17: 29.16 | G17: 29.16 | I17: 29.16 | K17: 29.16 | M17: 29.16 | O17: 29.16 | Q17: 29.16 | S17: 29.16 | U17: 29.16 | W17: 29.16 | Y17: 29.16 | AA17: 29.16 | AC17: 29.16 | AE17: 29.16 | AG17: 29.16 | AI17: 29.16 | AK17: 29.16 | AM17: 29.16 | AO17: 29.16 | AQ17: 29.16 | AS17: 29.16 | AU17: 29.16 | AW17: 29.16 | AY17: 29.16
A18: PASTILLAS DE FRENOS POST | C18: 29.63 | E18: 29.63 | G18: 29.63 | I18: 29.63 | K18: 29.63 | M18: 29.63 | O18: 29.63 | Q18: 29.63 | S18: 29.63 | U18: 29.63 | W18: 29.63 | Y18: 29.63 | AA18: 29.63 | AC18: 29.63 | AE18: 29.63 | AG18: 29.63 | AI18: 29.63 | AK18: 29.63 | AM18: 29.63 | AO18: 29.63 | AQ18: 29.63 | AS18: 29.63 | AU18: 29.63 | AW18: 29.63 | AY18: 29.63
A19: LIQUIDO INYECTORES | C19: 7.01 | E19: 7.01 | G19: 7.01 | I19: 7.01 | K19: 7.01 | M19: 7.01 | O19: 7.01 | Q19: 7.01 | S19: 7.01 | U19: 7.01 | W19: 7.01 | Y19: 7.01 | AA19: 7.01 | AC19: 7.01 | AE19: 7.01 | AG19: 7.01 | AI19: 7.01 | AK19: 7.01 | AM19: 7.01 | AO19: 7.01 | AQ19: 7.01 | AS19: 7.01 | AU19: 7.01 | AW19: 7.01 | AY19: 7.01
A20: LIMPIADOR DE FRENOS | C20: 5.6 | E20: 5.6 | G20: 5.6 | I20: 5.6 | K20: 5.6 | M20: 5.6 | O20: 5.6 | Q20: 5.6 | S20: 5.6 | U20: 5.6 | W20: 5.6 | Y20: 5.6 | AA20: 5.6 | AC20: 5.6 | AE20: 5.6 | AG20: 5.6 | AI20: 5.6 | AK20: 5.6 | AM20: 5.6 | AO20: 5.6 | AQ20: 5.6 | AS20: 5.6 | AU20: 5.6 | AW20: 5.6 | AY20: 5.6
A21: LIMPIADOR DE ADMISION | C21: 6.02 | E21: 6.02 | G21: 6.02 | I21: 6.02 | K21: 6.02 | M21: 6.02 | O21: 6.02 | Q21: 6.02 | S21: 6.02 | U21: 6.02 | W21: 6.02 | Y21: 6.02 | AA21: 6.02 | AC21: 6.02 | AE21: 6.02 | AG21: 6.02 | AI21: 6.02 | AK21: 6.02 | AM21: 6.02 | AO21: 6.02 | AQ21: 6.02 | AS21: 6.02 | AU21: 6.02 | AW21: 6.02 | AY21: 6.02
A22: REFRIGERANTE
A23: KIT DE DISTRIBUCIÓN | U23: 172.86 | AO23: 172.86
A24: BASE TERMOSTATO | K24: 11.47 | U24: 11.47 | AE24: 11.47 | AO24: 11.47 | AY24: 11.47
A25: TERMOSTATO | K25: 12.23 | U25: 12.23 | AE25: 12.23 | AO25: 12.23 | AY25: 12.23
A26: BANDA DE SERVICIO/ACCESORIOS | O26: 32 | AC26: 32 | AQ26: 32
A27: BOMBA DE AGUA WINGLE 7 | Z27: 178.2 | AY27: 178.2
A28: MANGUERA SALIDA RADIADOR | Z28: 25.12 | AY28: 25.12
A29: MANGUERA ENTRADA RADIADOR | Z29: 28.17 | AY29: 28.17
A30: COBERTOR TERMOSTATO MOTOR | Z30: 16 | AY30: 16
A31: TUBERIA ENTRADA AGUA A EGR | Z31: 4 | AY31: 4
A32: MANGUERA SALIDA REFRIGERANTE | Z32: 7.25 | AY32: 7.25
A33: MANGUERA DE CALEFACCION 1 | Z33: 20 | AY33: 20
A34: MANGUERA DE CALEFACCION 2 | Z34: 25 | AY34: 25
A35: KIT CAÑERIAS D/H WINGLE 7 | AE35: 100.75
A36: RETENEDOR DELT BOMBA DE ACEITE | Z36: 7.74 | AY36: 7.74
A37: RETENEDOR ARBOL DE LEVAS | Z37: 6.65 | AJ37: 6.65 | AY37: 6.65
A38: DUCTO METALICO SALIDA AGUA | Z38: 16 | AY38: 16
A39: MANGUERA AGUA CABEZOTE | Z39: 23.83 | AY39: 23.83
A40: SINCRONIZADO 5TA/6TA (2) | AD40: 56.5
...

Sheet CORRECTIVO
A1: MARCA | B1: GWM
A2: MODELO | B2: WINGLE 7 DIESEL | C2: MANTENIMIENTOS CORRECTIVOS
A3: ITEM | B3: DESCRIPCION | C3: CANTIDAD | D3: VALOR UNI | E3: TOTAL REPUESTOS | F3: MANO DE OBRA | H3: OBSERVACION DE TRABAJOS ADICIONALES | I3: Total M/O | J3: TOTAL LUBRICANTES | K3: SUBTOTAL | L3: IVA | M3: TOTAL
A4: 1 | B4: BOMBA DE COMBUSTIBLE ALTA PRESION | C4: 1 | D4: 1170 | E4: =D4*C4 -> 1170 | F4: Cambio bomba de combustible | G4: 72.6 | H4: contemplar desmontaje de banda de distribución mas 75.00 | I4: 147.6 | K4: =+E4+I4+J4 -> 1317.6 | L4: =+K4*0.12 -> 158.112 | M4: =+K4+L4 -> 1475.712
A5: 2 | B5: BOMBA AGUA | C5: 1 | D5: 99.09 | E5: 126.34 | F5: Cambio bomba de agua | G5: 57.75 | H5: contemplar desmontaje de banda de distribución mas 75.00 | I5: 132.75 | K5: =+E5+I5+J5 -> 259.09 | L5: =+K5*0.12 -> 31.0908 | M5: =+K5+L5 -> 290.1808
A6: 3 | B6: BOMBA DIRECCION HIDRAULICA | C6: 1 | D6: 187.49 | E6: =D6*C6 -> 187.49 | F6: Cambio bomba de dirección Hidráulica | G6: 49.5 | H6: mas dranado del sistema 33.00 | I6: 82.5 | J6: 15 | K6: =+E6+I6+J6 -> 284.99 | L6: =+K6*0.12 -> 34.1988 | M6: =+K6+L6 -> 319.1888
A7: 4 | B7: AMORTIGUADORES DELANTEROS | C7: 2 | D7: 78.76 | E7: =D7*C7 -> 157.52 | F7: Cambio amortiguadores delanteros | G7: 28.5 | I7: 28.5 | K7: =+E7+I7+J7 -> 186.02 | L7: =+K7*0.12 -> 22.3224 | M7: =+K7+L7 -> 208.3424
A8: 5 | B8: AMORTIGUADORES POSTERIORES | C8: 2 | D8: 58 | E8: 81.42 | F8: Cambio amortiguadores posteriores | G8: 28.5 | I8: 28.5 | K8: =+E8+I8+J8 -> 109.92 | L8: =+K8*0.12 -> 13.1904 | M8: =+K8+L8 -> 123.1104
A9: 6 | B9: KIT EMBRAGUE COMPLETO | C9: 1 | D9: =23.31+68+113.13 -> 204.44 | E9: 271.51 | F9: Cambio Kit de embrague | G9: 123.75 | I9: 123.75 | K9: =+E9+I9+J9 -> 395.26 | L9: =+K9*0.12 -> 47.4312 | M9: =+K9+L9 -> 442.6912
A10: 7 | B10: RODAMIENTOS PUNTAS DE EJE DELANTEROS (4) | C10: 4 | D10: 12.22 | E10: 50.66 | F10: Cambio y engrase de rodamientos de puntas de eje delanteras | G10: 61.05 | I10: 61.05 | K10: =+E10+I10+J10 -> 111.71 | L10: =+K10*0.12 -> 13.4052 | M10: =+K10+L10 -> 125.1152
A11: 8 | B11: RETENEDORES EJE DELANTEROS (2) | C11: 2 | D11: 3.88 | E11: =D11*C11 -> 7.76 | F11: Cambio retenedores puntas de eje delanteras | G11: 82 | I11: 82 | K11: =+E11+I11+J11 -> 89.76 | L11: =+K11*0.12 -> 10.7712 | M11: =+K11+L11 -> 100.5312
A12: 9 | B12: DISCOS DE FRENO DELANTEROS | C12: 2 | D12: 59.59 | E12: =D12*C12 -> 119.18 | F12: Cambio discos de freno delanteros | G12: 30 | I12: 30 | K12: =+E12+I12+J12 -> 149.18 | L12: =+K12*0.12 -> 17.9016 | M12: =+K12+L12 -> 167.0816
A13: 10 | B13: DISCOS DE FRENO POSTERIORES | C13: 2 | D13: 70.74 | E13: =D13*C13 -> 141.48 | F13: Cambio de discos de freno | G13: 30 | I13: 30 | K13: =+E13+I13+J13 -> 171.48 | L13: =+K13*0.12 -> 20.5776 | M13: =+K13+L13 -> 192.0576
A14: 11 | B14: BUJES DE PAQUETES DE RESORTES | C14: 4 | D14: 10 | E14: 38.96 | F14: Cambio bujes de paquetes | G14: 82.5 | I14: 82.5 | K14: =+E14+I14+J14 -> 121.46 | L14: =+K14*0.12 -> 14.5752 | M14: =+K14+L14 -> 136.0352
A15: 12 | B15: CRUCETAS DE CARDAN | C15: 1 | D15: 12.96 | E15: =D15*C15 -> 12.96 | F15: Cambio crucetas | G15: 49.5 | H15: mas desmontaje de cardan 33 | I15: 82.5 | K15: =+E15+I15+J15 -> 95.46 | L15: =+K15*0.12 -> 11.4552 | M15: =+K15+L15 -> 106.9152
A16: 13 | B16: BOMBA DE FRENO | C16: 1 | D16: 201.37 | E16: 188.24 | F16: Cambio bomba de freno | G16: 61.05 | H16: mas purgado de liquido 25 | I16: 86.05 | K16: =+E16+I16+J16 -> 274.29 | L16: =+K16*0.12 -> 32.9148 | M16: =+K16+L16 -> 307.2048
A17: 14 | B17: BOMBA DE EMBRAGUE | C17: 1 | D17: 30.44 | E17: =D17*C17 -> 30.44 | F17: Cambio bomba de embrague | G17: 25.05 | H17: mas purgado de liquido 25 | I17: 50.05 | K17: =+E17+I17+J17 -> 80.49 | L17: =+K17*0.12 -> 9.6588 | M17: =+K17+L17 -> 90.1488
A18: 15 | B18: INYECTORES | C18: 4 | D18: 389.39 | E18: =D18*C18 -> 1557.56 | F18: Cambio y diagnóstico de inyectores | G18: 41.25 | I18: 41.25 | K18: =+E18+I18+J18 -> 1598.81 | L18: =+K18*0.12 -> 191.8572 | M18: =+K18+L18 -> 1790.6672
A19: 16 | B19: TURBO GEOMETRIA VARIABLE | C19: 1 | D19: 1340.14 | E19: =D19*C19 -> 1340.14 | F19: Cambio turbo | G19: 49.5 | H19: mas limpieza de sistema intercooler 50.00 | I19: 99.5 | K19: =+E19+I19+J19 -> 1439.64 | L19: =+K19*0.12 -> 172.7568 | M19: =+K19+L19 -> 1612.3968
A20: 17 | B20: CREMALLERA DE DIRECCION | C20: 1 | D20: 500 | E20: 642.3 | F20: Cambio cremallera de dirección y sangrado sistema | G20: 82.5 | I20: 82.5 | J20: 15 | K20: =+E20+I20+J20 -> 739.8 | L20: =+K20*0.12 -> 88.776 | M20: =+K20+L20 -> 828.576
A21: 18 | B21: ROTULAS SUPERIORES | C21: 2 | D21: 35.68 | E21: =D21*C21 -> 71.36 | F21: Cambio rotulas de suspensión | G21: 33 | H21: mas alineación 18.00 | I21: 51 | K21: =+E21+I21+J21 -> 122.36 | L21: =+K21*0.12 -> 14.6832 | M21: =+K21+L21 -> 137.0432
A22: 19 | B22: ROTULAS INFERIORES | C22: 2 | D22: 35.54 | E22: =D22*C22 -> 71.08 | F22: Cambio rotulas de suspensión | G22: 33 | H22: mas alineación 18.00 | I22: 51 | K22: =+E22+I22+J22 -> 122.08 | L22: =+K22*0.12 -> 14.6496 | M22: =+K22+L22 -> 136.7296
A23: 20 | B23: COMPRESOR A/C | C23: 1 | D23: 390.18 | E23: 352.87 | F23: Cambio compresor de A/C | G23: 49.5 | H23: mas carga de aire 60 | I23: 109.5 | K23: =+E23+I23+J23 -> 462.37 | L23: =+K23*0.12 -> 55.4844 | M23: =+K23+L23 -> 517.8544
A24: 21 | B24: BANDA DE SERVICIO | C24: 1 | D24: 48.27 | E24: 26.6 | F24: Cambio banda de servicio | G24: 14.85 | I24: 14.85 | K24: =+E24+I24+J24 -> 41.45 | L24: =+K24*0.12 -> 4.974 | M24: =+K24+L24 -> 46.424
A25: 22 | B25: RODAMIENTAS DE CAJA DE CAMBIOS | C25: 1 | D25: =35.53+28.1+21.75+4.84+16.97+10.45+16.55+14.43+10.45+18.77 -> 177.84 | E25: 172.6 | F25: Cambio rodamientas de caja | G25: 165 | H25: mas DM caja 75.00 mas lubricantes 48 | I25: 240 | J25: 48 | K25: =+E25+I25+J25 -> 460.6 | L25: =+K25*0.12 -> 55.272 | M25: =+K25+L25 -> 515.872
A26: 23 | B26: SINCRONIZADOS DE CAJA DE CAMBIOS | C26: 1 | D26: =42.99+66.16+26.91+28.13*2 -> 192.32 | E26: 161.59 | F26: Cambio sincronizados de caja | G26: 165 | H26: mas DM caja 75.00 mas lubricantes 48 | I26: 240 | J26: 48 | K26: =+E26+I26+J26 -> 449.59 | L26: =+K26*0.12 -> 53.9508 | M26: =+K26+L26 -> 503.5408
A27: 24 | B27: PAQUETES DE RESORTES POSTERIORES | C27: 2 | D27: 164.59 | E27: 184.34 | F27: Cambio paquetes de resortes posteriores | G27: 66 | I27: 66 | K27: =+E27+I27+J27 -> 250.34 | L27: =+K27*0.12 -> 30.0408 | M27: =+K27+L27 -> 280.3808
B28: SUBTOTAL | E28: =SUM(E4:E27) -> 7164.4 | I28: =SUM(I4:I27) -> 2043.35 | J28: =SUM(J4:J27) -> 126 | K28: =SUM(K4:K27) -> 9333.75 | L28: =SUM(L4:L27) -> 1120.05 | M28: =SUM(M4:M27) -> 10453.8
B29: IVA | E29: =+E28*0.12 -> 859.728 | I29: =+I28*0.12 -> 245.202 | J29: =+J28*0.12 -> 15.12 | K29: =+K28*0.12 -> 1120.05 | L29: =+L28*0.12 -> 134.406 | M29: =+M28*0.12 -> 1254.456
B30: TOTAL | E30: =+E28+E29 -> 8024.128 | I30: =+I28+I29 -> 2288.552 | J30: =+J28+J29 -> 141.12 | K30: =+K28+K29 -> 10453.8 | L30: =+L28+L29 -> 1254.456 | M30: =+M28+M29 -> 11708.256

Sheet TABLA GRAL MO-REP
A1: TABLA COSTOS MANTENIMIENTO PREVENTIVO CAMIONETA WINGLE 7, SEGÚN PLAN MANTENIMIENTO FABRICANTE
A2: CANTIDAD TOTAL DE VEHICULOS | F2: 21
A3: KILOMETRAJE (km) | C3: TOTAL LUBRICANTES | D3: TOTAL REPUESTOS | E3: TOTAL MANO DE OBRA | F3: SUBTOTAL/CAMIONETA
B4: 5000 | C4: ='W7 DIESEL 120K'!C27 -> 95.04 | D4: ='W7 DIESEL 120K'!C20 -> 33.56 | E4: ='W7 DIESEL 120K'!C21 -> 19.4 | F4: =SUM(C4:E4) -> 148
B5: 10000 | C5: ='W7 DIESEL 120K'!D27 -> 40.98 | D5: ='W7 DIESEL 120K'!D20 -> 115.97 | E5: ='W7 DIESEL 120K'!D21 -> 157 | F5: =SUM(C5:E5) -> 313.95
B6: 15000 | C6: 40.98 | D6: 33.56 | E6: 14.11 | F6: =SUM(C6:E6) -> 88.65
B7: 20000 | C7: ='W7 DIESEL 120K'!E27 -> 52.98 | D7: ='W7 DIESEL 120K'!E20 -> 68.6 | E7: ='W7 DIESEL 120K'!E21 -> 181.69 | F7: =SUM(C7:E7) -> 303.27
B8: 25000 | C8: 40.98 | D8: 33.56 | E8: 14.11 | F8: =SUM(C8:E8) -> 88.65
B9: 30000 | C9: ='W7 DIESEL 120K'!F27 -> 48.31 | D9: ='W7 DIESEL 120K'!F20 -> 115.97 | E9: ='W7 DIESEL 120K'!F21 -> 175.34 | F9: =SUM(C9:E9) -> 339.62
B10: 35000 | C10: 40.98 | D10: 33.56 | E10: 14.11 | F10: =SUM(C10:E10) -> 88.65
B11: 40000 | C11: ='W7 DIESEL 120K'!G27 -> 67.98 | D11: ='W7 DIESEL 120K'!G20 -> 68.6 | E11: ='W7 DIESEL 120K'!G21 -> 213.44 | F11: =SUM(C11:E11) -> 350.02
B12: 45000 | C12: 40.98 | D12: 33.56 | E12: 14.11 | F12: =SUM(C12:E12) -> 88.65
B13: 50000 | C13: ='W7 DIESEL 120K'!H27 -> 95.04 | D13: ='W7 DIESEL 120K'!H20 -> 115.97 | E13: ='W7 DIESEL 120K'!H21 -> 169.34 | F13: =SUM(C13:E13) -> 380.35
B14: 55000 | C14: 40.98 | D14: 33.56 | E14: 14.11 | F14: =SUM(C14:E14) -> 88.65
B15: 60000 | C15: ='W7 DIESEL 120K'!I27 -> 60.31 | D15: ='W7 DIESEL 120K'!I20 -> 68.6 | E15: ='W7 DIESEL 120K'!I21 -> 196.51 | F15: =SUM(C15:E15) -> 325.42
B16: 65000 | C16: 40.98 | D16: 33.56 | E16: 14.11 | F16: =SUM(C16:E16) -> 88.65
B17: 70000 | C17: ='W7 DIESEL 120K'!J27 -> 40.98 | D17: ='W7 DIESEL 120K'!J20 -> 115.97 | E17: ='W7 DIESEL 120K'!J21 -> 148.18 | F17: =SUM(C17:E17) -> 305.13
B18: 75000 | C18: 40.98 | D18: 33.56 | E18: 14.11 | F18: =SUM(C18:E18) -> 88.65
B19: 80000 | C19: ='W7 DIESEL 120K'!K27 -> 0 | D19: ='W7 DIESEL 120K'!K20 -> 0 | E19: ='W7 DIESEL 120K'!K21 -> 0 | F19: =SUM(C19:E19) -> 0
B20: 85000 | C20: 40.98 | D20: 33.56 | E20: 14.11 | F20: =SUM(C20:E20) -> 88.65
B21: 90000 | C21: ='W7 DIESEL 120K'!L27 -> 0 | D21: ='W7 DIESEL 120K'!L20 -> 0 | E21: ='W7 DIESEL 120K'!L21 -> 0 | F21: =SUM(C21:E21) -> 0
B22: 95000 | C22: 40.98 | D22: 33.56 | E22: 14.11 | F22: =SUM(C22:E22) -> 88.65
B23: 100000 | C23: ='W7 DIESEL 120K'!M27 -> 0 | D23: ='W7 DIESEL 120K'!M20 -> 0 | E23: ='W7 DIESEL 120K'!M21 -> 0 | F23: =SUM(C23:E23) -> 0
B24: 105000 | C24: 40.98 | D24: 33.56 | E24: 14.11 | F24: =SUM(C24:E24) -> 88.65
B25: 110000 | C25: ='W7 DIESEL 120K'!N27 -> 0 | D25: ='W7 DIESEL 120K'!N20 -> 0 | E25: ='W7 DIESEL 120K'!N21 -> 0 | F25: =SUM(C25:E25) -> 0
B26: 115000 | C26: 40.98 | D26: 33.56 | E26: 14.11 | F26: =SUM(C26:E26) -> 88.65
B27: 120000 | C27: ='W7 DIESEL 120K'!O27 -> 0 | D27: ='W7 DIESEL 120K'!O20 -> 0 | E27: ='W7 DIESEL 120K'!O21 -> 0 | F27: =SUM(C27:E27) -> 0
B28: SUBTOTAL UNITARIO | C28: =SUM(C4:C27) -> 952.4 | D28: =SUM(D4:D27) -> 1072.4 | E28: =SUM(E4:E27) -> 1416.11 | F28: =SUM(F4:F27) -> 3440.91
B29: SUBTOTAL (21 VEHICULOS) | C29: =C28*$F$2 -> 20000.4 | D29: =D28*$F$2 -> 22520.4 | E29: =E28*$F$2 -> 29738.31 | F29: =SUM(C29:E29) -> 72259.11
A30: MANTENIMIENTO CORRECTIVO (30% MANTENIMIENTO PREVENTIVO) | C30: =C29*0.3 -> 6000.12 | D30: =D29*0.3 -> 6756.12 | E30: =E29*0.3 -> 8921.493 | F30: =SUM(C30:E30) -> 21677.733
A31: TOTAL | C31: =C29+C30 -> 26000.52 | D31: =D29+D30 -> 29276.52 | E31: =E29+E30 -> 38659.803 | F31: =SUM(C31:E31) -> 93936.843
B32: IVA | C32: =C31*0.12 -> 3120.0624 | D32: =D31*0.12 -> 3513.1824 | E32: =E31*0.12 -> 4639.1764 | F32: =SUM(C32:E32) -> 11272.421
B33: TOTAL | C33: =SUM(C31:C32) -> 29120.582 | D33: =SUM(D31:D32) -> 32789.702 | E33: =SUM(E31:E32) -> 43298.979 | F33: =SUM(C33:E33) -> 105209.26

Sheet MANT. CORRECTIVOS SOLICITADOS
B1: MANTENIMIENTOS CORRECTIVOS ESTIMADOS
B2: ITEM | C2: CÓDIGO CPC | D2: DESCRIPCIÓN | E2: CANTIDAD | F2: UNIDAD | G2: COSTO | H2: SUBTOTAL (SIN IVA)
B3: 1 | D3: DISCO DE FRENO DELANTERO | E3: 18 | F3: UNIDAD | G3: 59.59 | H3: =E3*G3 -> 1072.62
B4: 2 | D4: DISCOS DE FRENOS POSTERIORES | E4: 18 | F4: UNIDAD | G4: 70.74 | H4: =E4*G4 -> 1273.32
B5: 3 | D5: PLATO DE EMBRAGUE | E5: 9 | F5: UNIDAD | G5: 95 | H5: =E5*G5 -> 855
B6: 4 | D6: DISCO DE EMBRAGUE | E6: 9 | F6: UNIDAD | G6: 135 | H6: =E6*G6 -> 1215
B7: 5 | D7: RODAMIENTO DE EMBRAGUE | E7: 9 | F7: UNIDAD | G7: 27.63 | H7: =E7*G7 -> 248.67
B8: 6 | D8: BANDA DE ACCESORIOS | E8: 9 | F8: UNIDAD | G8: 26.6 | H8: =E8*G8 -> 239.4
B9: 7 | D9: TEMPLADOR DE BANDA | E9: 9 | F9: UNIDAD | G9: 123.23 | H9: =E9*G9 -> 1109.07
B10: 8 | D10: CAMBIO DE BANDA Y TEMPLADOR | E10: 9 | F10: UNIDAD | G10: 72.6 | H10: =E10*G10 -> 653.4
B11: 9 | D11: MANTENIMIENTO DE AIRE ACONDICIONADO (CADA 40000 KILOMETROS) | E11: 27 | F11: UNIDAD | G11: 55 | H11: =E11*G11 -> 1485
B12: 10 | D12: CAMBIO DE DISCOS DE FRENOS DELANTEROS | E12: 9 | F12: UNIDAD | G12: 16.5 | H12: =E12*G12 -> 148.5
B13: 11 | D13: CAMBIO DE DISCOS DE FRENOS POSTERIORES | E13: 9 | F13: UNIDAD | G13: 16.5 | H13: =E13*G13 -> 148.5
B14: 12 | D14: CAMBIO DE KIT DE EMBRAGUE | E14: 9 | F14: UNIDAD | G14: 123.75 | H14: =E14*G14 -> 1113.75
B15: 13 | D15: RECTIFICADA DE DISCOS | E15: 9 | F15: UNIDAD | G15: 17.82 | H15: =E15*G15 -> 160.38
B16: TOTAL (SIN IVA) | H16: =SUM(H3:H15) -> 9722.61

Sheet DETALLADO MANT 4X2
A1: PLAN DE MANTENIMIENTO PREVENTIVO WINGLE 7 4X2
A2: WINGLE 7 DIESEL | B2: INTERMEDIOS | C2: 5000 | D2: 10000 | E2: 15000 | F2: 20000 | G2: 25000 | H2: 30000 | I2: 35000 | J2: 40000 | K2: 45000 | L2: 50000 | M2: 55000 | N2: 60000 | O2: 65000 | P2: 70000 | Q2: 75000 | R2: 80000 | S2: 85000 | T2: 90000 | U2: 95000 | V2: 100000 | W2: 105000 | X2: 110000 | Y2: 115000 | Z2: 120000 | AA2: 125000 | AB2: 130000 | AC2: 135000 | AD2: 140000 | AE2: 145000 | AF2: 150000 | AG2: 155000 | AH2: 160000 | AI2: 165000 | AJ2: 170000 | AK2: 175000 | AL2: 180000 | AM2: 185000 | AN2: 190000 | AO2: 195000 | AP2: 200000
A3: ACEITE MOTOR (10W40) 6lt | B3: ='W7 DIESEL 120K'!U2 -> 40.98 | C3: 43.98 | D3: 43.98 | E3: 43.98 | F3: 43.98 | G3: 43.98 | H3: 43.98 | I3: 43.98 | J3: 43.98 | K3: 43.98 | L3: 43.98 | M3: 43.98 | N3: 43.98 | O3: 43.98 | P3: 43.98 | Q3: 43.98 | R3: 43.98 | S3: 43.98 | T3: 43.98 | U3: 43.98 | V3: 43.98 | W3: 43.98 | X3: 43.98 | Y3: 43.98 | Z3: 43.98 | AA3: 43.98 | AB3: 43.98 | AC3: 43.98 | AD3: 43.98 | AE3: 43.98 | AF3: 43.98 | AG3: 43.98 | AH3: 43.98 | AI3: 43.98 | AJ3: 43.98 | AK3: 43.98 | AL3: 43.98 | AM3: 43.98 | AN3: 43.98 | AO3: 43.98 | AP3: 43.98
A4: ACEITE DE CAJA (75W90) 3lt | B4: ='W7 DIESEL 120K'!#REF! -> #REF! | H4: 28.23 | N4: 28.23 | T4: 28.23 | V4: 28.23 | Z4: 28.23 | AF4: 28.23 | AL4: 28.23
A5: ACEITE DIFERENCIAL DELANTERO (80W90) 3lt | B5: ='W7 DIESEL 120K'!#REF! -> #REF!
A6: ACEITE DIFERENCIAL POSTERIOR (80W90) 3lt | H6: 26.61 | N6: 26.61 | T6: 26.61 | Z6: 26.61 | AF6: 26.61 | AL6: 26.61
A7: ACEITE TRANSFER (ATF3-DEXRON3) 3 lt
A8: ACEITE DIRECCION HIDRAULICA | B8: ='W7 DIESEL 120K'!U1 -> INTERMEDIOS | L8: 8.71 | V8: 8.71 | AF8: 8.71 | AP8: 8.71
A9: REFRIGERANTE 8lt | L9: 35.44 | V9: 35.44 | AF9: 35.44 | AP9: 35.44
A10: LIQUIDO DE FRENOS | B10: ='W7 DIESEL 120K'!U3 -> 6.01 | H10: 12 | N10: 12 | T10: 12 | Z10: 12 | AF10: 12 | AL10: 12
A11: TOTAL LUBRICANTES | C11: =SUM(C3:C10) -> 43.98 | D11: =SUM(D3:D10) -> 43.98 | E11: =SUM(E3:E10) -> 43.98 | F11: =SUM(F3:F10) -> 43.98 | G11: =SUM(G3:G10) -> 43.98 | H11: =SUM(H3:H10) -> 110.82 | I11: =SUM(I3:I10) -> 43.98 | J11: =SUM(J3:J10) -> 43.98 | ... Z11: =SUM(Z3:Z10) -> 110.82 | AA11: 43.98 | AB11: =SUM(AB3:AB10) -> 43.98 | AC11: 43.98 | AD11: =SUM(AD3:AD10) -> 43.98 | AE11: 43.98 | AF11: =SUM(AF3:AF10) -> 154.97 | AG11: 43.98 | AH11: =SUM(AH3:AH10) -> 43.98 | AI11: 43.98 | AJ11: =SUM(AJ3:AJ10) -> 43.98 | AK11: 43.98 | AL11: =SUM(AL3:AL10) -> 110.82 | AM11: 43.98 | AN11: =SUM(AN3:AN10) -> 43.98 | AO11: 43.98 | AP11: =SUM(AP3:AP10) -> 88.13
A12: FILTRO DE ACEITE | B12: ='W7 DIESEL 120K'!U3 -> 6.01 | C12: 7.07 | D12: 7.07 | E12: 7.07 | F12: 7.07 | G12: 7.07 | H12: 7.07 | I12: 7.07 | J12: 7.07 | K12: 7.07 | L12: 7.07 | M12: 7.07 | N12: 7.07 | O12: 7.07 | P12: 7.07 | Q12: 7.07 | R12: 7.07 | S12: 7.07 | T12: 7.07 | U12: 7.07 | V12: 7.07 | W12: 7.07 | X12: 7.07 | Y12: 7.07 | Z12: 7.07 | AA12: 7.07 | AB12: 7.07 | AC12: 7.07 | AD12: 7.07 | AE12: 7.07 | AF12: 7.07 | AG12: 7.07 | AH12: 7.07 | AI12: 7.07 | AJ12: 7.07 | AK12: 7.07 | AL12: 7.07 | AM12: 7.07 | AN12: 7.07 | AO12: 7.07 | AP12: 7.07
A13: FILTROS DE COMBUSTIBLE | B13: ='W7 DIESEL 120K'!U4 -> 6.5 | C13: 6.5 | D13: 6.5 | E13: 6.5 | F13: 6.5 | G13: 6.5 | H13: 6.5 | I13: 6.5 | J13: 6.5 | K13: 6.5 | L13: 6.5 | M13: 6.5 | N13: 6.5 | O13: 6.5 | P13: 6.5 | Q13: 6.5 | R13: 6.5 | S13: 6.5 | T13: 6.5 | U13: 6.5 | V13: 6.5 | W13: 6.5 | X13: 6.5 | Y13: 6.5 | Z13: 6.5 | AA13: 6.5 | AB13: 6.5 | AC13: 6.5 | AD13: 6.5 | AE13: 6.5 | AF13: 6.5 | AG13: 6.5 | AH13: 6.5 | AI13: 6.5 | AJ13: 6.5 | AK13: 6.5 | AL13: 6.5 | AM13: 6.5 | AN13: 6.5 | AO13: 6.5 | AP13: 6.5
A14: FILTRO TRAMPA DE AGUA/COMB | B14: ='W7 DIESEL 120K'!U5 -> 17.55 | C14: 19.09 | D14: 19.09 | E14: 19.09 | F14: 19.09 | G14: 19.09 | H14: 19.09 | I14: 19.09 | J14: 19.09 | K14: 19.09 | L14: 19.09 | M14: 19.09 | N14: 19.09 | O14: 19.09 | P14: 19.09 | Q14: 19.09 | R14: 19.09 | S14: 19.09 | T14: 19.09 | U14: 19.09 | V14: 19.09 | W14: 19.09 | X14: 19.09 | Y14: 19.09 | Z14: 19.09 | AA14: 19.09 | AB14: 19.09 | AC14: 19.09 | AD14: 19.09 | AE14: 19.09 | AF14: 19.09 | AG14: 19.09 | AH14: 19.09 | AI14: 19.09 | AJ14: 19.09 | AK14: 19.09 | AL14: 19.09 | AM14: 19.09 | AN14: 19.09 | AO14: 19.09 | AP14: 19.09
A15: FILTRO DE AIRE | B15: ='W7 DIESEL 120K'!U6 -> 0 | D15: 10.45 | F15: 10.45 | H15: 10.45 | J15: 10.45 | L15: 10.45 | N15: 10.45 | P15: 10.45 | R15: 10.45 | T15: 10.45 | V15: 10.45 | X15: 10.45 | Z15: 10.45 | AB15: 10.45 | AD15: 10.45 | AF15: 10.45 | AH15: 10.45 | AJ15: 10.45 | AL15: 10.45 | AN15: 10.45 | AP15: 10.45
A16: FILTRO DE CABINA A/C | B16: ='W7 DIESEL 120K'!U7 -> 0 | D16: 8.77 | F16: 8.77 | H16: 8.77 | J16: 8.77 | L16: 8.77 | N16: 8.77 | P16: 8.77 | R16: 8.77 | T16: 8.77 | V16: 8.77 | X16: 8.77 | Z16: 8.77 | AB16: 8.77 | AD16: 8.77 | AF16: 8.77 | AH16: 8.77 | AJ16: 8.77 | AL16: 8.77 | AN16: 8.77 | AP16: 8.77
A17: PASTILLAS DE FRENO DEL | B17: ='W7 DIESEL 120K'!U8 -> 0 | D17: 29.16 | F17: 29.16 | H17: 29.16 | J17: 29.16 | L17: 29.16 | N17: 29.16 | P17: 29.16 | R17: 29.16 | T17: 29.16 | V17: 29.16 | X17: 29.16 | Z17: 29.16 | AB17: 29.16 | AD17: 29.16 | AF17: 29.16 | AH17: 29.16 | AJ17: 29.16 | AL17: 29.16 | AN17: 29.16 | AP17: 29.16
A18: PASTILLAS DE FRENOS POST | B18: ='W7 DIESEL 120K'!U9 -> 0 | D18: 29.63 | F18: 29.63 | H18: 29.63 | J18: 29.63 | L18: 29.63 | N18: 29.63 | P18: 29.63 | R18: 29.63 | T18: 29.63 | V18: 29.63 | X18: 29.63 | Z18: 29.63 | AB18: 29.63 | AD18: 29.63 | AF18: 29.63 | AH18: 29.63 | AJ18: 29.63 | AL18: 29.63 | AN18: 29.63 | AP18: 29.63
A19: LIQUIDO INYECTORES | B19: ='W7 DIESEL 120K'!U10 -> 0 | D19: 7.01 | F19: 7.01 | H19: 7.01 | J19: 7.01 | L19: 7.01 | N19: 7.01 | P19: 7.01 | R19: 7.01 | T19: 7.01 | V19: 7.01 | X19: 7.01 | Z19: 7.01 | AB19: 7.01 | AD19: 7.01 | AF19: 7.01 | AH19: 7.01 | AJ19: 7.01 | AL19: 7.01 | AN19: 7.01 | AP19: 7.01
A20: LIMPIADOR DE FRENOS | B20: ='W7 DIESEL 120K'!U11 -> 0 | D20: 5.6 | F20: 5.6 | H20: 5.6 | J20: 5.6 | L20: 5.6 | N20: 5.6 | P20: 5.6 | R20: 5.6 | T20: 5.6 | V20: 5.6 | X20: 5.6 | Z20: 5.6 | AB20: 5.6 | AD20: 5.6 | AF20: 5.6 | AH20: 5.6 | AJ20: 5.6 | AL20: 5.6 | AN20: 5.6 | AP20: 5.6
A21: LIMPIADOR DE ADMISION | B21: ='W7 DIESEL 120K'!U12 -> 0 | D21: 6.02 | F21: 6.02 | H21: 6.02 | J21: 6.02 | L21: 6.02 | N21: 6.02 | P21: 6.02 | R21: 6.02 | T21: 6.02 | V21: 6.02 | X21: 6.02 | Z21: 6.02 | AB21: 6.02 | AD21: 6.02 | AF21: 6.02 | AH21: 6.02 | AJ21: 6.02 | AL21: 6.02 | AN21: 6.02 | AP21: 6.02
A22: REFRIGERANTE | B22: ='W7 DIESEL 120K'!U13 -> 0
A23: KIT DE DISTRIBUCIÓN | B23: ='W7 DIESEL 120K'!U14 -> 0 | V23: 172.86 | AP23: 172.86
A24: SUMINISTROS | B24: ='W7 DIESEL 120K'!U17 -> 3.5 | C24: 3.5 | D24: 3.5 | E24: 3.5 | F24: 3.5 | G24: 3.5 | H24: 3.5 | I24: 3.5 | J24: 3.5 | K24: 3.5 | L24: 3.5 | M24: 3.5 | N24: 3.5 | O24: 3.5 | P24: 3.5 | Q24: 3.5 | R24: 3.5 | S24: 3.5 | T24: 3.5 | U24: 3.5 | V24: 3.5 | W24: 3.5 | X24: 3.5 | Y24: 3.5 | Z24: 3.5 | AA24: 3.5 | AB24: 3.5 | AC24: 3.5 | AD24: 3.5 | AE24: 3.5 | AF24: 3.5 | AG24: 3.5 | AH24: 3.5 | AI24: 3.5 | AJ24: 3.5 | AK24: 3.5 | AL24: 3.5 | AM24: 3.5 | AN24: 3.5 | AO24: 3.5 | AP24: 3.5
A25: BASE TERMOSTATO Y TERMOSTATO | L25: 27.63 | V25: 27.63 | AF25: 27.63 | AP25: 27.63
A26: TAPA RADIADOR | L26: 6.25 | V26: 6.25 | AF26: 6.25 | AP26: 6.25
A27: BANDA DE SERVICIO/ACCESORIOS | P27: 29.29 | AD27: 29.29
A28: TOTAL REPUESTOS | B28: =B12+B13+B14+B15+B17+B18+B19+B20+B21+B23+B24+B16 -> 33.56 | C28: =C12+C13+C14+C15+C17+C18+C19+C20+C21+C23+C24+C16+C27 -> 36.16 | D28: =D12+D13+D14+D15+D17+D18+D19+D20+D21+D23+D24+D16+D27 -> 132.8 | E28: =E12+E13+E14+E15+E17+E18+E19+E20+E21+E23+E24+E16+E27 -> 36.16 | F28: =F12+F13+F14+F15+F17+F18+F19+F20+F21+F23+F24+F16+F27 -> 132.8 | G28: =G12+G13+G14+G15+G17+G18+G19+G20+G21+G23+G24+G16+G27 -> 36.16 | H28: =H12+H13+H14+H15+H17+H18+H19+H20+H21+H23+H24+H16+H27 -> 132.8 | I28: =I12+I13+I14+I15+I17+I18+I19+I20+I21+I23+I24+I16+I27 -> 36.16 | J28: =SUM(J12:J27) -> 132.8 | K28: =SUM(K12:K27) -> 36.16 | L28: =SUM(L12:L27) -> 166.68 | M28: =SUM(M12:M27) -> 36.16 | N28: =SUM(N12:N27) -> 132.8 | O28: =SUM(O12:O27) -> 36.16 | P28: =SUM(P12:P27) -> 162.09 | Q28: =SUM(Q12:Q27) -> 36.16 | ... Z28: =SUM(Z12:Z27) -> 132.8 | AA28: 36.16 | AB28: =SUM(AB12:AB27) -> 132.8 | AC28: 36.16 | AD28: =SUM(AD12:AD27) -> 162.09 | AE28: 36.16 | AF28: =SUM(AF12:AF27) -> 166.68 | AG28: 36.16 | AH28: =SUM(AH12:AH27) -> 132.8 | AI28: 36.16 | AJ28: =SUM(AJ12:AJ27) -> 132.8 | AK28: 36.16 | AL28: =SUM(AL12:AL27) -> 132.8 | AM28: 36.16 | AN28: =SUM(AN12:AN27) -> 132.8 | AO28: 36.16 | AP28: =SUM(AP12:AP27) -> 339.54
A29: MANO DE OBRA POR KILOMETRAJE | C29: 19.4 | D29: 107.5 | E29: 14.11 | F29: 132.19 | G29: 14.11 | H29: 125.84 | I29: 14.11 | J29: 163.94 | K29: 14.11 | L29: 119.84 | M29: 14.11 | N29: 147.01 | O29: 14.11 | P29: 98.68 | Q29: 14.11 | R29: 132.19 | S29: 14.11 | T29: 129.37 | U29: 14.11 | V29: 264.49 | W29: 19.4 | X29: 107.5 | Y29: 14.11 | Z29: 132.19 | AA29: 14.11 | AB29: 132.19 | AC29: 14.11 | AD29: 132.19 | AE29: 14.11 | AF29: 119.84 | AG29: 14.11 | AH29: 132.19 | AI29: 14.11 | AJ29: 132.19 | AK29: 14.11 | AL29: 132.19 | AM29: 14.11 | AN29: 132.19 | AO29: 14.11 | AP29: 264.49
A30: ALINEACION | B30: 0 | D30: 17.16 | F30: 17.16 | H30: 17.16 | J30: 17.16 | L30: 17.16 | N30: 17.16 | P30: 17.16 | R30: 17.16 | T30: 17.16 | V30: 17.16 | X30: 17.16 | Z30: 17.16 | AB30: 17.16 | AD30: 17.16 | AF30: 17.16 | AH30: 17.16 | AJ30: 17.16 | AL30: 17.16 | AN30: 17.16 | AP30: 17.16
A31: BALANCEO | D31: 15.84 | F31: 15.84 | H31: 15.84 | J31: 15.84 | L31: 15.84 | N31: 15.84 | P31: 15.84 | R31: 15.84 | T31: 15.84 | V31: 15.84 | X31: 15.84 | Z31: 15.84 | AB31: 15.84 | AD31: 15.84 | AF31: 15.84 | AH31: 15.84 | AJ31: 15.84 | AL31: 15.84 | AN31: 15.84 | AP31: 15.84
A32: LIMPIEZA DE INYECTORES | B32: 0 | D32: 16.5 | F32: 16.5 | H32: 16.5 | J32: 16.5 | L32: 16.5 | N32: 16.5 | P32: 16.5 | R32: 16.5 | T32: 16.5 | V32: 16.5 | X32: 16.5 | Z32: 16.5 | AB32: 16.5 | AD32: 16.5 | AF32: 16.5 | AH32: 16.5 | AJ32: 16.5 | AL32: 16.5 | AN32: 16.5 | AP32: 16.5
A33: LAVADO PREMIUM | B33: 0 | F33: 26 | J33: 26 | N33: 26 | R33: 26 | V33: 26 | Z33: 26 | AD33: 26 | AH33: 26 | AL33: 26 | AP33: 26
A34: TOTAL MANO DE OBRA | B34: ='W7 DIESEL 120K'!U21 -> 14.78 | C34: =SUM(C29:C32) -> 19.4 | D34: =SUM(D29:D32) -> 157 | E34: =SUM(E29:E32) -> 14.11 | F34: =SUM(F29:F32) -> 181.69 | G34: =SUM(G29:G32) -> 14.11 | H34: =SUM(H29:H32) -> 175.34 | I34: =SUM(I29:I32) -> 14.11 | J34: =SUM(J29:J33) -> 239.44 | K34: =SUM(K29:K32) -> 14.11 | L34: =SUM(L29:L32) -> 169.34 | M34: =SUM(M29:M32) -> 14.11 | N34: =SUM(N29:N32) -> 196.51 | O34: =SUM(O29:O32) -> 14.11 | P34: =SUM(P29:P32) -> 148.18 | Q34: =SUM(Q29:Q32) -> 14.11 | R34: =SUM(R29:R32) -> 181.69 | ... Z34: =SUM(Z29:Z32) -> 181.69 | AA34: 14.11 | AB34: =SUM(AB29:AB32) -> 181.69 | AC34: 14.11 | AD34: =SUM(AD29:AD32) -> 181.69 | AE34: 14.11 | AF34: =SUM(AF29:AF32) -> 169.34 | AG34: 14.11 | AH34: =SUM(AH29:AH32) -> 181.69 | AI34: 14.11 | AJ34: =SUM(AJ29:AJ32) -> 181.69 | AK34: 14.11 | AL34: =SUM(AL29:AL32) -> 181.69 | AM34: 14.11 | AN34: =SUM(AN29:AN32) -> 181.69 | AO34: 14.11 | AP34: =SUM(AP29:AP32) -> 313.99
A35: TOTAL COSTO MANTENIMIENTO POR KILOMETRAJE | C35: =C11+C28+C34 -> 99.54 | D35: =D11+D28+D34 -> 333.78 | E35: =E11+E28+E34 -> 94.25 | F35: =F11+F28+F34 -> 358.47 | G35: =G11+G28+G34 -> 94.25 | H35: =H11+H28+H34 -> 418.96 | I35: =I11+I28+I34 -> 94.25 | J35: =J11+J28+J34 -> 416.22 | ... Z35: =Z11+Z28+Z34 -> 425.31 | AA35: 94.25 | AB35: =AB11+AB28+AB34 -> 358.47 | AC35: 94.25 | AD35: =AD11+AD28+AD34 -> 387.76 | AE35: 94.25 | AF35: =AF11+AF28+AF34 -> 490.99 | AG35: 94.25 | AH35: =AH11+AH28+AH34 -> 358.47 | AI35: 94.25 | AJ35: =AJ11+AJ28+AJ34 -> 358.47 | AK35: 94.25 | AL35: =AL11+AL28+AL34 -> 425.31 | AM35: 94.25 | AN35: =AN11+AN28+AN34 -> 358.47 | AO35: 94.25 | AP35: =AP11+AP28+AP34 -> 741.66

Sheet DETALLADO MANT 4X2 - NO APLICA
A1: PLAN DE MANTENIMIENTO PREVENTIVO WINGLE 7 4X2
A2: WINGLE 7 DIESEL | B2: INTERMEDIOS | C2: 5000 | D2: 10000 | E2: 15000 | F2: 20000 | G2: 25000 | H2: 30000 | I2: 35000 | J2: 40000 | K2: 45000 | L2: 50000 | M2: 55000 | N2: 60000 | O2: 65000 | P2: 70000 | Q2: 75000 | R2: 80000 | S2: 85000 | T2: 90000 | U2: 95000 | V2: 100000 | W2: 105000 | X2: 110000 | Y2: 115000 | Z2: 120000
A3: ACEITE MOTOR (10W40) | B3: ='W7 DIESEL 120K'!U2 -> 40.98 | C3: 40.98 | D3: 40.98 | E3: 40.98 | F3: 40.98 | G3: 40.98 | H3: 40.98 | I3: 40.98 | J3: 40.98 | K3: 40.98 | L3: 40.98 | M3: 40.98 | N3: 40.98 | O3: 40.98 | P3: 40.98 | Q3: 40.98 | R3: 40.98 | S3: 40.98 | T3: 40.98 | U3: 40.98 | V3: 40.98 | W3: 40.98 | X3: 40.98 | Y3: 40.98 | Z3: 40.98
A4: FILTRO DE ACEITE | B4: ='W7 DIESEL 120K'!U3 -> 6.01 | C4: 6.01 | D4: 6.01 | E4: 6.01 | F4: 6.01 | G4: 6.01 | H4: 6.01 | I4: 6.01 | J4: 6.01 | K4: 6.01 | L4: 6.01 | M4: 6.01 | N4: 6.01 | O4: 6.01 | P4: 6.01 | Q4: 6.01 | R4: 6.01 | S4: 6.01 | T4: 6.01 | U4: 6.01 | V4: 6.01 | W4: 6.01 | X4: 6.01 | Y4: 6.01 | Z4: 6.01
A5: FILTROS DE COMBUSTIBLE | B5: ='W7 DIESEL 120K'!U4 -> 6.5 | C5: 6.5 | D5: 6.5 | E5: 6.5 | F5: 6.5 | G5: 6.5 | H5: 6.5 | I5: 6.5 | J5: 6.5 | K5: 6.5 | L5: 6.5 | M5: 6.5 | N5: 6.5 | O5: 6.5 | P5: 6.5 | Q5: 6.5 | R5: 6.5 | S5: 6.5 | T5: 6.5 | U5: 6.5 | V5: 6.5 | W5: 6.5 | X5: 6.5 | Y5: 6.5 | Z5: 6.5
A6: FILTRO TRAMPA DE AGUA/COMB | B6: ='W7 DIESEL 120K'!U5 -> 17.55 | C6: 17.55 | D6: 17.55 | E6: 17.55 | F6: 17.55 | G6: 17.55 | H6: 17.55 | I6: 17.55 | J6: 17.55 | K6: 17.55 | L6: 17.55 | M6: 17.55 | N6: 17.55 | O6: 17.55 | P6: 17.55 | Q6: 17.55 | R6: 17.55 | S6: 17.55 | T6: 17.55 | U6: 17.55 | V6: 17.55 | W6: 17.55 | X6: 17.55 | Y6: 17.55 | Z6: 17.55
A7: FILTRO DE AIRE | B7: ='W7 DIESEL 120K'!U6 -> 0 | D7: 10.45 | F7: 10.45 | H7: 10.45 | J7: 10.45 | L7: 10.45 | N7: 10.45 | P7: 10.45 | R7: 10.45 | T7: 10.45 | V7: 10.45 | X7: 10.45 | Z7: 10.45
A8: FILTRO DE CABINA A/C | B8: ='W7 DIESEL 120K'!U7 -> 0 | D8: 7.69 | F8: 7.69 | H8: 7.69 | J8: 7.69 | L8: 7.69 | N8: 7.69 | P8: 7.69 | R8: 7.69 | T8: 7.69 | V8: 7.69 | X8: 7.69 | Z8: 7.69
A9: PASTILLAS DE FRENO DEL | B9: ='W7 DIESEL 120K'!U8 -> 0 | D9: 26.87 | F9: 26.87 | H9: 26.87 | J9: 26.87 | L9: 26.87 | N9: 26.87 | P9: 26.87 | R9: 26.87 | T9: 26.87 | V9: 26.87 | X9: 26.87 | Z9: 26.87
A10: PASTILLAS DE FRENOS POST | B10: ='W7 DIESEL 120K'!U9 -> 0 | D10: 27 | F10: 27 | H10: 27 | J10: 27 | L10: 27 | N10: 27 | P10: 27 | R10: 27 | T10: 27 | V10: 27 | X10: 27 | Z10: 27
A11: LIQUIDO INYECTORES | B11: ='W7 DIESEL 120K'!U10 -> 0 | D11: 6.5 | F11: 6.5 | H11: 6.5 | J11: 6.5 | L11: 6.5 | N11: 6.5 | P11: 6.5 | R11: 6.5 | T11: 6.5 | V11: 6.5 | X11: 6.5 | Z11: 6.5
A12: LIMPIADOR DE FRENOS | B12: ='W7 DIESEL 120K'!U11 -> 0 | D12: 5 | F12: 5 | H12: 5 | J12: 5 | L12: 5 | N12: 5 | P12: 5 | R12: 5 | T12: 5 | V12: 5 | X12: 5 | Z12: 5
A13: LIMPIADOR DE ADMISION | B13: ='W7 DIESEL 120K'!U12 -> 0 | D13: 5.4 | F13: 5.4 | H13: 5.4 | J13: 5.4 | L13: 5.4 | N13: 5.4 | P13: 5.4 | R13: 5.4 | T13: 5.4 | V13: 5.4 | X13: 5.4 | Z13: 5.4
A14: REFRIGERANTE | B14: ='W7 DIESEL 120K'!U13 -> 0
A15: KIT DE DISTRIBUCIÓN | B15: ='W7 DIESEL 120K'!U14 -> 0 | V15: 157.97
A16: ACEITE DE CAJA (75W90) 4lt | B16: ='W7 DIESEL 120K'!U15 -> 0 | L16: 31.56 | V16: 31.56
A17: ACEITE DIFERENCIAL POSTERIOR (80W90) 3lt | L17: 22.5 | V17: 22.5
A18: SUMINISTROS | B18: ='W7 DIESEL 120K'!U17 -> 3.5 | C18: 3.5 | D18: 3.5 | E18: 3.5 | F18: 3.5 | G18: 3.5 | H18: 3.5 | I18: 3.5 | J18: 3.5 | K18: 3.5 | L18: 3.5 | M18: 3.5 | N18: 3.5 | O18: 3.5 | P18: 3.5 | Q18: 3.5 | R18: 3.5 | S18: 3.5 | T18: 3.5 | U18: 3.5 | V18: 3.5 | W18: 3.5 | X18: 3.5 | Y18: 3.5 | Z18: 3.5
A19: ACEITE DIRECCION HIDRAULICA | B19: ='W7 DIESEL 120K'!U18 -> 0 | L19: 7.33 | V19: 7.33
A20: LIQUIDO DE FRENOS | B20: ='W7 DIESEL 120K'!U19 -> 0 | H20: 12 | N20: 12 | T20: 12
A21: BANDA DE SERVICIO/ACCESORIOS | P21: 26.6
A22: TOTAL REPUESTOS | B22: =B4+B5+B6+B7+B9+B10+B11+B12+B13+B15+B18+B8 -> 33.56 | C22: =C4+C5+C6+C7+C9+C10+C11+C12+C13+C15+C18+C8+C21 -> 33.56 | D22: =D4+D5+D6+D7+D9+D10+D11+D12+D13+D15+D18+D8+D21 -> 122.47 | E22: =E4+E5+E6+E7+E9+E10+E11+E12+E13+E15+E18+E8+E21 -> 33.56 | F22: =F4+F5+F6+F7+F9+F10+F11+F12+F13+F15+F18+F8+F21 -> 122.47 | G22: =G4+G5+G6+G7+G9+G10+G11+G12+G13+G15+G18+G8+G21 -> 33.56 | H22: =H4+H5+H6+H7+H9+H10+H11+H12+H13+H15+H18+H8+H21 -> 122.47 | I22: =I4+I5+I6+I7+I9+I10+I11+I12+I13+I15+I18+I8+I21 -> 33.56 | J22: =J4+J5+J6+J7+J9+J10+J11+J12+J13+J15+J18+J8+J21 -> 122.47 | ... Z22: =Z4+Z5+Z6+Z7+Z9+Z10+Z11+Z12+Z13+Z15+Z18+Z8+Z21 -> 122.47 | AA22: =SUM(C22:Z22) -> 2056.93
A23: TOTAL MANO DE OBRA | B23: ='W7 DIESEL 120K'!U21 -> 14.78 | C23: 19.4 | D23: 157 | E23: 14.11 | F23: 181.69 | G23: 14.11 | H23: 175.34 | I23: 14.11 | J23: 213.44 | K23: 14.11 | L23: 169.34 | M23: 14.11 | N23: 196.51 | O23: 14.11 | P23: 148.18 | Q23: 14.11 | R23: 181.69 | S23: 14.11 | T23: 178.87 | U23: 14.11 | V23: 313.99 | W23: 19.4 | X23: 157 | Y23: 14.11 | Z23: 181.69 | AA23: =SUM(C23:Z23) -> 2434.64
A24: ALINEACION | B24: 0 | D24: 17.16 | F24: 17.16 | H24: 17.16 | J24: 17.16 | L24: 17.16 | N24: 17.16 | P24: 17.16 | R24: 17.16 | T24: 17.16 | V24: 17.16 | X24: 17.16 | Z24: 17.16
A25: BALANCEO | D25: 15.84 | F25: 15.84 | H25: 15.84 | J25: 15.84 | L25: 15.84 | N25: 15.84 | P25: 15.84 | R25: 15.84 | T25: 15.84 | V25: 15.84 | X25: 15.84 | Z25: 15.84
A26: LIMPIEZA DE INYECTORES | B26: 0 | D26: 16.5 | F26: 16.5 | H26: 16.5 | J26: 16.5 | L26: 16.5 | N26: 16.5 | P26: 16.5 | R26: 16.5 | T26: 16.5 | V26: 16.5 | X26: 16.5 | Z26: 16.5
A27: *LUBRICANTES | B27: =B3+B14+B16+#REF!+B19+B20 -> #REF! | C27: =C3+C14+C16+C19+C20 -> 40.98 | D27: =D3+D14+D16+D19+D20+D17 -> 40.98 | E27: =E3+E14+E16+E19+E20+E17 -> 40.98 | F27: =F3+F14+F16+F19+F20+F17 -> 40.98 | G27: =G3+G14+G16+G19+G20+G17 -> 40.98 | H27: =H3+H14+H16+H19+H20+H17 -> 52.98 | I27: =I3+I14+I16+I19+I20+I17 -> 40.98 | J27: =J3+J14+J16+J19+J20+J17 -> 40.98 | K27: =K3+K14+K16+K19+K20+K17 -> 40.98 | ... Z27: =Z3+Z14+Z16+Z19+Z20+Z17 -> 40.98 | AA27: =SUM(C27:Z27) -> 1142.3
A28: TOTAL COSTO MANTINIENTO POR KILOMETRAJE | C28: =C22+C23+C27 -> 93.94 | D28: =D22+D23+D27 -> 320.45 | E28: =E22+E23+E27 -> 88.65 | F28: =F22+F23+F27 -> 345.14 | G28: =G22+G23+G27 -> 88.65 | H28: =H22+H23+H27 -> 350.79 | I28: =I22+I23+I27 -> 88.65 | J28: =J22+J23+J27 -> 376.89 | ... Z28: =Z22+Z23+Z27 -> 345.14

Sheet DETALLADO MANT 4X2.
A1: PLAN DE MANTENIMIENTO PREVENTIVO WINGLE 7 4X2
A2: WINGLE 7 DIESEL | B2: 5000 | C2: 10000 | D2: 15000 | E2: 20000 | F2: 25000 | G2: 30000 | H2: 35000 | I2: 40000 | J2: 45000 | K2: 50000 | L2: 55000 | M2: 60000 | N2: 65000 | O2: 70000 | P2: 75000 | Q2: 80000 | R2: 85000 | S2: 90000 | T2: 95000 | U2: 100000 | V2: 105000 | W2: 110000 | X2: 115000 | Y2: 120000 | Z2: 125000 | AA2: 130000 | AB2: 135000 | AC2: 140000 | AD2: 145000 | AE2: 150000 | AF2: 155000 | AG2: 160000 | AH2: 165000 | AI2: 170000 | AJ2: 175000 | AK2: 180000 | AL2: 185000 | AM2: 190000 | AN2: 195000 | AO2: 200000 | AP2: 205000 | AQ2: 210000 | AR2: 215000 | AS2: 220000 | AT2: 225000 | AU2: 230000 | AV2: 235000 | AW2: 240000 | AX2: 245000 | AY2: 250000
A3: ACEITE MOTOR (10W40) 6lt | B3: 43.98 | C3: 43.98 | D3: 43.98 | E3: 43.98 | F3: 43.98 | G3: 43.98 | H3: 43.98 | I3: 43.98 | J3: 43.98 | K3: 43.98 | L3: 43.98 | M3: 43.98 | N3: 43.98 | O3: 43.98 | P3: 43.98 | Q3: 43.98 | R3: 43.98 | S3: 43.98 | T3: 43.98 | U3: 43.98 | V3: 43.98 | W3: 43.98 | X3: 43.98 | Y3: 43.98 | Z3: 43.98 | AA3: 43.98 | AB3: 43.98 | AC3: 43.98 | AD3: 43.98 | AE3: 43.98 | AF3: 43.98 | AG3: 43.98 | AH3: 43.98 | AI3: 43.98 | AJ3: 43.98 | AK3: 43.98 | AL3: 43.98 | AM3: 43.98 | AN3: 43.98 | AO3: 43.98 | AP3: 43.98 | AQ3: 43.98 | AR3: 43.98 | AS3: 43.98 | AT3: 43.98 | AU3: 43.98 | AV3: 43.98 | AW3: 43.98 | AX3: 43.98 | AY3: 43.98
A4: ACEITE DE CAJA (75W90) 3lt | K4: 28.23 | U4: 28.23 | AD4: 28.23 | AK4: 28.23 | AQ4: 28.23 | AW4: 28.23
A5: ACEITE DIFERENCIAL DELANTERO (80W90) 3lt | AE5: 26.61 | AK5: 26.61 | AQ5: 26.61 | AW5: 26.61 | AY5: 26.61
A6: ACEITE DIFERENCIAL POSTERIOR (80W90) 3lt | K6: 26.61 | U6: 26.61 | Z6: 8.71 | AE6: 8.71 | AO6: 8.71 | AY6: 8.71
A7: ACEITE TRANSFER (ATF3-DEXRON3) 3 lt | Z7: 35.44 | AE7: 35.44 | AJ7: 35.44 | AO7: 35.44 | AY7: 35.44
A8: ACEITE DIRECCION HIDRAULICA | K8: 8.71 | U8: 8.71
A9: REFRIGERANTE 8lt | K9: 35.44 | U9: 35.44
A10: LIQUIDO DE FRENOS | G10: 18 | M10: 18 | S10: 18 | Y10: 18 | AE10: 18 | AK10: 18 | AQ10: 18 | AW10: 18
A11: TOTAL LUBRICANTES | B11: =SUM(B3:B10) -> 43.98 | C11: =SUM(C3:C10) -> 43.98 | D11: =SUM(D3:D10) -> 43.98 | E11: =SUM(E3:E10) -> 43.98 | F11: =SUM(F3:F10) -> 43.98 | G11: =SUM(G3:G10) -> 61.98 | H11: =SUM(H3:H10) -> 43.98 | I11: =SUM(I3:I10) -> 43.98 | ... AY11: =SUM(AY3:AY10) -> 114.74 | AZ11: =SUM(B11:AY11) -> 2998.99
A12: FILTRO DE ACEITE | B12: =7.07+1.5 -> 8.57 | C12: =7.07+1.5 -> 8.57 | D12: =7.07+1.5 -> 8.57 | E12: =7.07+1.5 -> 8.57 | F12: =7.07+1.5 -> 8.57 | G12: =7.07+1.5 -> 8.57 | H12: =7.07+1.5 -> 8.57 | I12: =7.07+1.5 -> 8.57 | ... AY12: =7.07+1.5 -> 8.57
A13: FILTROS DE COMBUSTIBLE | B13: =6.5+1.5 -> 8 | C13: =6.5+1.5 -> 8 | D13: =6.5+1.5 -> 8 | E13: =6.5+1.5 -> 8 | F13: =6.5+1.5 -> 8 | G13: =6.5+1.5 -> 8 | H13: =6.5+1.5 -> 8 | I13: =6.5+1.5 -> 8 | ... AY13: =6.5+1.5 -> 8
A14: FILTRO TRAMPA DE AGUA/COMB | B14: =19.09+1.5 -> 20.59 | C14: =19.09+1.5 -> 20.59 | D14: =19.09+1.5 -> 20.59 | E14: =19.09+1.5 -> 20.59 | F14: =19.09+1.5 -> 20.59 | G14: =19.09+1.5 -> 20.59 | H14: =19.09+1.5 -> 20.59 | I14: =19.09+1.5 -> 20.59 | ... AY14: =19.09+1.5 -> 20.59
A15: FILTRO DE AIRE | C15: 10.45 | E15: 10.45 | G15: 10.45 | I15: 10.45 | K15: 10.45 | M15: 10.45 | O15: 10.45 | Q15: 10.45 | S15: 10.45 | U15: 10.45 | W15: 10.45 | Y15: 10.45 | AA15: 10.45 | AC15: 10.45 | AE15: 10.45 | AG15: 10.45 | AI15: 10.45 | AK15: 10.45 | AM15: 10.45 | AO15: 10.45 | AQ15: 10.45 | AS15: 10.45 | AU15: 10.45 | AW15: 10.45 | AY15: 10.45
A16: FILTRO DE CABINA A/C | C16: 8.77 | E16: 8.77 | G16: 8.77 | I16: 8.77 | K16: 8.77 | M16: 8.77 | O16: 8.77 | Q16: 8.77 | S16: 8.77 | U16: 8.77 | W16: 8.77 | Y16: 8.77 | AA16: 8.77 | AC16: 8.77 | AE16: 8.77 | AG16: 8.77 | AI16: 8.77 | AK16: 8.77 | AM16: 8.77 | AO16: 8.77 | AQ16: 8.77 | AS16: 8.77 | AU16: 8.77 | AW16: 8.77 | AY16: 8.77
A17: PASTILLAS DE FRENO DEL | C17: 29.16 | E17: 29.16 | G17: 29.16 | I17: 29.16 | K17: 29.16 | M17: 29.16 | O17: 29.16 | Q17: 29.16 | S17: 29.16 | U17: 29.16 | W17: 29.16 | Y17: 29.16 | AA17: 29.16 | AC17: 29.16 | AE17: 29.16 | AG17: 29.16 | AI17: 29.16 | AK17: 29.16 | AM17: 29.16 | AO17: 29.16 | AQ17: 29.16 | AS17: 29.16 | AU17: 29.16 | AW17: 29.16 | AY17: 29.16
A18: PASTILLAS DE FRENOS POST | C18: 29.63 | E18: 29.63 | G18: 29.63 | I18: 29.63 | K18: 29.63 | M18: 29.63 | O18: 29.63 | Q18: 29.63 | S18: 29.63 | U18: 29.63 | W18: 29.63 | Y18: 29.63 | AA18: 29.63 | AC18: 29.63 | AE18: 29.63 | AG18: 29.63 | AI18: 29.63 | AK18: 29.63 | AM18: 29.63 | AO18: 29.63 | AQ18: 29.63 | AS18: 29.63 | AU18: 29.63 | AW18: 29.63 | AY18: 29.63
A19: LIQUIDO INYECTORES | C19: 7.01 | E19: 7.01 | G19: 7.01 | I19: 7.01 | K19: 7.01 | M19: 7.01 | O19: 7.01 | Q19: 7.01 | S19: 7.01 | U19: 7.01 | W19: 7.01 | Y19: 7.01 | AA19: 7.01 | AC19: 7.01 | AE19: 7.01 | AG19: 7.01 | AI19: 7.01 | AK19: 7.01 | AM19: 7.01 | AO19: 7.01 | AQ19: 7.01 | AS19: 7.01 | AU19: 7.01 | AW19: 7.01 | AY19: 7.01
A20: LIMPIADOR DE FRENOS | C20: 5.6 | E20: 5.6 | G20: 5.6 | I20: 5.6 | K20: 5.6 | M20: 5.6 | O20: 5.6 | Q20: 5.6 | S20: 5.6 | U20: 5.6 | W20: 5.6 | Y20: 5.6 | AA20: 5.6 | AC20: 5.6 | AE20: 5.6 | AG20: 5.6 | AI20: 5.6 | AK20: 5.6 | AM20: 5.6 | AO20: 5.6 | AQ20: 5.6 | AS20: 5.6 | AU20: 5.6 | AW20: 5.6 | AY20: 5.6
A21: LIMPIADOR DE ADMISION | C21: 6.02 | E21: 6.02 | G21: 6.02 | I21: 6.02 | K21: 6.02 | M21: 6.02 | O21: 6.02 | Q21: 6.02 | S21: 6.02 | U21: 6.02 | W21: 6.02 | Y21: 6.02 | AA21: 6.02 | AC21: 6.02 | AE21: 6.02 | AG21: 6.02 | AI21: 6.02 | AK21: 6.02 | AM21: 6.02 | AO21: 6.02 | AQ21: 6.02 | AS21: 6.02 | AU21: 6.02 | AW21: 6.02 | AY21: 6.02
A22: REFRIGERANTE
A23: KIT DE DISTRIBUCIÓN | U23: 172.86 | AO23: 172.86
A24: BASE TERMOSTATO | K24: 11.47 | U24: 11.47 | AE24: 11.47 | AO24: 11.47 | AY24: 11.47
A25: TERMOSTATO | K25: 12.23 | U25: 12.23 | AE25: 12.23 | AO25: 12.23 | AY25: 12.23
A26: BANDA DE SERVICIO/ACCESORIOS | O26: 32 | AC26: 32 | AQ26: 32
A27: BOMBA DE AGUA WINGLE 7 | Z27: 178.2 | AY27: 178.2
A28: MANGUERA SALIDA RADIADOR | Z28: 25.12 | AY28: 25.12
A29: MANGUERA ENTRADA RADIADOR | Z29: 28.17 | AY29: 28.17
A30: COBERTOR TERMOSTATO MOTOR | Z30: 16 | AY30: 16
A31: TUBERIA ENTRADA AGUA A EGR | Z31: 4 | AY31: 4
A32: MANGUERA SALIDA REFRIGERANTE | Z32: 7.25 | AY32: 7.25
A33: MANGUERA DE CALEFACCION 1 | Z33: 20 | AY33: 20
A34: MANGUERA DE CALEFACCION 2 | Z34: 25 | AY34: 25
A35: KIT CAÑERIAS D/H WINGLE 7 | AE35: 100.75
A36: RETENEDOR DELT BOMBA DE ACEITE | Z36: 7.74 | AY36: 7.74
A37: RETENEDOR ARBOL DE LEVAS | Z37: 6.65 | AJ37: 6.65 | AY37: 6.65
A38: DUCTO METALICO SALIDA AGUA | Z38: 16 | AY38: 16
A39: MANGUERA AGUA CABEZOTE | Z39: 23.83 | AY39: 23.83
A40: SINCRONIZADO 5TA/6TA (2) | AD40: 56.5
...

Sheet CONSOLIDADO
B2: COSTOS MANTENIMIENTO WINGLE 7 4X4 | G2: CANTIDAD VEHICULOS
B3: 1 | C3: Total lubricantes | D3: Mantenimiento preventivo | E3: =+'DETALLADO MANT 4X4'!AZ11*G3 -> 3368.17 | G3: 1
B4: 2 | C4: Total repuestos | E4: =+'DETALLADO MANT 4X4'!AZ62*G3 -> 6767.78
B5: 3 | C5: Total mano de obra | E5: =+'DETALLADO MANT 4X4'!AZ74*G3 -> 8829.97
B6: 4 | C6: Mantenimiento correctivo | D6: Se considera un valor aproximado del 30% del costo total de mantenimientos preventivos | E6: =(E3+E4+E5)*0.3 -> 5689.776
B7: Total 1 + 2 + 3 + 4 | E7: =SUM(E3:E6) -> 24655.696
B8: Costos no incluyen IVA
B10: COSTOS MANTENIMIENTO WINGLE 7 4X2 | G10: CANTIDAD VEHICULOS
B11: 1 | C11: Total lubricantes | D11: Mantenimiento preventivo | E11: ='DETALLADO MANT 4X2.'!AZ11*G11 -> 2998.99 | G11: 1
B12: 2 | C12: Total repuestos | E12: ='DETALLADO MANT 4X2.'!AZ62*G11 -> 6768.15
B13: 3 | C13: Total mano de obra | E13: ='DETALLADO MANT 4X2.'!AZ74*G11 -> 8829.97
B14: 4 | C14: Mantenimiento correctivo | D14: Se considera un valor aproximado del 30% del costo total de mantenimientos preventivos | E14: =(E11+E12+E13)*0.3 -> 5579.133
B15: Total 1 + 2 + 3 + 4 | E15: =SUM(E11:E14) -> 24176.243
B16: Costos no incluyen IVA

Sheet PLAN MANTENIMIENTO
A1: PLAN DE MANTENIMIENTO PREVENTIVO WINGLE 7 (4X4 Y 4X2)
A2: WINGLE 7 DIESEL | B2: 5000 | C2: 10000 | D2: 15000 | E2: 20000 | F2: 25000 | G2: 30000 | H2: 35000 | I2: 40000 | J2: 45000 | K2: 50000 | L2: 55000 | M2: 60000 | N2: 65000 | O2: 70000 | P2: 75000 | Q2: 80000 | R2: 85000 | S2: 90000 | T2: 95000 | U2: 100000 | V2: 105000 | W2: 110000 | X2: 115000 | Y2: 120000
A3: ACEITE MOTOR | B3: X | C3: X | D3: X | E3: X | F3: X | G3: X | H3: X | I3: X | J3: X | K3: X | L3: X | M3: X | N3: X | O3: X | P3: X | Q3: X | R3: X | S3: X | T3: X | U3: X | V3: X | W3: X | X3: X | Y3: X
A4: FILTRO DE ACEITE | B4: X | C4: X | D4: X | E4: X | F4: X | G4: X | H4: X | I4: X | J4: X | K4: X | L4: X | M4: X | N4: X | O4: X | P4: X | Q4: X | R4: X | S4: X | T4: X | U4: X | V4: X | W4: X | X4: X | Y4: X
A5: FILTROS DE COMBUSTIBLE | B5: X | C5: X | D5: X | E5: X | F5: X | G5: X | H5: X | I5: X | J5: X | K5: X | L5: X | M5: X | N5: X | O5: X | P5: X | Q5: X | R5: X | S5: X | T5: X | U5: X | V5: X | W5: X | X5: X | Y5: X
A6: FILTRO TRAMPA DE AGUA/COMB | B6: X | C6: X | D6: X | E6: X | F6: X | G6: X | H6: X | I6: X | J6: X | K6: X | L6: X | M6: X | N6: X | O6: X | P6: X | Q6: X | R6: X | S6: X | T6: X | U6: X | V6: X | W6: X | X6: X | Y6: X
A7: FILTRO DE AIRE | C7: X | E7: X | G7: X | I7: X | K7: X | M7: X | O7: X | Q7: X | S7: X | U7: X | W7: X | Y7: X
A8: FILTRO DE CABINA A/C | C8: X | E8: X | G8: X | I8: X | K8: X | M8: X | O8: X | Q8: X | S8: X | U8: X | W8: X | Y8: X
A9: PASTILLAS DE FRENO DEL | C9: X | E9: X | G9: X | I9: X | K9: X | M9: X | O9: X | Q9: X | S9: X | U9: X | W9: X | Y9: X
A10: PASTILLAS DE FRENOS POST | C10: X | E10: X | G10: X | I10: X | K10: X | M10: X | O10: X | Q10: X | S10: X | U10: X | W10: X | Y10: X
A11: LIQUIDO INYECTORES | C11: X | E11: X | G11: X | I11: X | K11: X | M11: X | O11: X | Q11: X | S11: X | U11: X | W11: X | Y11: X
A12: LIMPIADOR DE FRENOS | C12: X | E12: X | G12: X | I12: X | K12: X | M12: X | O12: X | Q12: X | S12: X | U12: X | W12: X | Y12: X
A13: LIMPIADOR DE ADMISION | C13: X | E13: X | G13: X | I13: X | K13: X | M13: X | O13: X | Q13: X | S13: X | U13: X | W13: X | Y13: X
A14: REFRIGERANTE
A15: KIT DE DISTRIBUCIÓN | U15: X
A16: ACEITE DE CAJA (4X2 Y 4X4) | K16: X | U16: X
A17: ACEITE DIFERENCIAL DELANTERO (SOLO 4X4) | K17: X | U17: X
A18: ACEITE DIFERENCIAL POSTERIOR (4X2 Y 4X4) | K18: X | U18: X
A19: ACEITE TRANSFER (SOLO 4X4) | K19: X | U19: X
A20: SUMINISTROS | B20: X | C20: X | D20: X | E20: X | F20: X | G20: X | H20: X | I20: X | J20: X | K20: X | L20: X | M20: X | N20: X | O20: X | P20: X | Q20: X | R20: X | S20: X | T20: X | U20: X | V20: X | W20: X | X20: X | Y20: X
A21: ACEITE DIRECCION HIDRAULICA | K21: X | U21: X
A22: LIQUIDO DE FRENOS | G22: X | M22: X | S22: X
A23: BANDA DE SERVICIO/ACCESORIOS | O23: X
A24: MANO DE OBRA | B24: X | C24: X | D24: X | E24: X | F24: X | G24: X | H24: X | I24: X | J24: X | K24: X | L24: X | M24: X | N24: X | O24: X | P24: X | Q24: X | R24: X | S24: X | T24: X | U24: X | V24: X | W24: X | X24: X | Y24: X
A25: ALINEACION | C25: X | E25: X | G25: X | I25: X | K25: X | M25: X | O25: X | Q25: X | S25: X | U25: X | W25: X | Y25: X
A26: BALANCEO | C26: X | E26: X | G26: X | I26: X | K26: X | M26: X | O26: X | Q26: X | S26: X | U26: X | W26: X | Y26: X
A27: LIMPIEZA DE INYECTORES | C27: X | E27: X | G27: X | I27: X | K27: X | M27: X | O27: X | Q27: X | S27: X | U27: X | W27: X | Y27: X

Sheet REF. MANT. CORRECTIVO
A1: MARCA | B1: GWM
A2: MODELO | B2: WINGLE 7 DIESEL | C2: MANTENIMIENTOS CORRECTIVOS | G2: VALORES
A3: ITEM | B3: DESCRIPCION | C3: TOTAL REPUESTOS | D3: Total M/O | E3: TOTAL LUBRICANTES | F3: SUBTOTAL | G3: IVA | H3: TOTAL
A4: 1 | B4: BOMBA DE COMBUSTIBLE ALTA PRESION | C4: 1170 | D4: 147.6 | F4: =SUM(C4:E4) -> 1317.6 | G4: =F4*0.12 -> 158.112 | H4: =SUM(F4:G4) -> 1475.712
A5: 2 | B5: BOMBA AGUA | C5: 99.09 | D5: 132.75 | F5: =SUM(C5:E5) -> 231.84 | G5: =F5*0.12 -> 27.8208 | H5: =SUM(F5:G5) -> 259.6608
A6: 3 | B6: BOMBA DIRECCION HIDRAULICA | C6: 187.49 | D6: 82.5 | E6: 15 | F6: =SUM(C6:E6) -> 284.99 | G6: =F6*0.12 -> 34.1988 | H6: =SUM(F6:G6) -> 319.1888
A7: 4 | B7: AMORTIGUADORES DELANTEROS | C7: 157.52 | D7: 28.5 | F7: =SUM(C7:E7) -> 186.02 | G7: =F7*0.12 -> 22.3224 | H7: =SUM(F7:G7) -> 208.3424
A8: 5 | B8: AMORTIGUADORES POSTERIORES | C8: 116 | D8: 28.5 | F8: =SUM(C8:E8) -> 144.5 | G8: =F8*0.12 -> 17.34 | H8: =SUM(F8:G8) -> 161.84
A9: 6 | B9: KIT EMBRAGUE COMPLETO | C9: 204.44 | D9: 123.75 | F9: =SUM(C9:E9) -> 328.19 | G9: =F9*0.12 -> 39.3828 | H9: =SUM(F9:G9) -> 367.5728
A10: 7 | B10: RODAMIENTOS PUNTAS DE EJE DELANTEROS (4) | C10: 48.88 | D10: 61.05 | F10: =SUM(C10:E10) -> 109.93 | G10: =F10*0.12 -> 13.1916 | H10: =SUM(F10:G10) -> 123.1216
A11: 8 | B11: RETENEDORES EJE DELANTEROS (2) | C11: 7.76 | D11: 82 | F11: =SUM(C11:E11) -> 89.76 | G11: =F11*0.12 -> 10.7712 | H11: =SUM(F11:G11) -> 100.5312
A12: 9 | B12: DISCOS DE FRENO DELANTEROS | C12: 119.18 | D12: 30 | F12: =SUM(C12:E12) -> 149.18 | G12: =F12*0.12 -> 17.9016 | H12: =SUM(F12:G12) -> 167.0816
A13: 10 | B13: DISCOS DE FRENO POSTERIORES | C13: 141.48 | D13: 30 | F13: =SUM(C13:E13) -> 171.48 | G13: =F13*0.12 -> 20.5776 | H13: =SUM(F13:G13) -> 192.0576
A14: 11 | B14: BUJES DE PAQUETES DE RESORTES | C14: 40 | D14: 82.5 | F14: =SUM(C14:E14) -> 122.5 | G14: =F14*0.12 -> 14.7 | H14: =SUM(F14:G14) -> 137.2
A15: 12 | B15: CRUCETAS DE CARDAN | C15: 12.96 | D15: 82.5 | F15: =SUM(C15:E15) -> 95.46 | G15: =F15*0.12 -> 11.4552 | H15: =SUM(F15:G15) -> 106.9152
A16: 13 | B16: BOMBA DE FRENO | C16: 201.37 | D16: 86.05 | F16: =SUM(C16:E16) -> 287.42 | G16: =F16*0.12 -> 34.4904 | H16: =SUM(F16:G16) -> 321.9104
A17: 14 | B17: BOMBA DE EMBRAGUE | C17: 30.44 | D17: 50.05 | F17: =SUM(C17:E17) -> 80.49 | G17: =F17*0.12 -> 9.6588 | H17: =SUM(F17:G17) -> 90.1488
A18: 15 | B18: INYECTORES | C18: 1557.56 | D18: 41.25 | F18: =SUM(C18:E18) -> 1598.81 | G18: =F18*0.12 -> 191.8572 | H18: =SUM(F18:G18) -> 1790.6672
A19: 16 | B19: TURBO GEOMETRIA VARIABLE | C19: 1340.14 | D19: 99.5 | F19: =SUM(C19:E19) -> 1439.64 | G19: =F19*0.12 -> 172.7568 | H19: =SUM(F19:G19) -> 1612.3968
A20: 17 | B20: CREMALLERA DE DIRECCION | C20: 500 | D20: 82.5 | E20: 15 | F20: =SUM(C20:E20) -> 597.5 | G20: =F20*0.12 -> 71.7 | H20: =SUM(F20:G20) -> 669.2
A21: 18 | B21: ROTULAS SUPERIORES | C21: 71.36 | D21: 51 | F21: =SUM(C21:E21) -> 122.36 | G21: =F21*0.12 -> 14.6832 | H21: =SUM(F21:G21) -> 137.0432
A22: 19 | B22: ROTULAS INFERIORES | C22: 71.08 | D22: 51 | F22: =SUM(C22:E22) -> 122.08 | G22: =F22*0.12 -> 14.6496 | H22: =SUM(F22:G22) -> 136.7296
A23: 20 | B23: COMPRESOR A/C | C23: 390.18 | D23: 109.5 | F23: =SUM(C23:E23) -> 499.68 | G23: =F23*0.12 -> 59.9616 | H23: =SUM(F23:G23) -> 559.6416
A24: 21 | B24: BANDA DE SERVICIO | C24: 48.27 | D24: 14.85 | F24: =SUM(C24:E24) -> 63.12 | G24: =F24*0.12 -> 7.5744 | H24: =SUM(F24:G24) -> 70.6944
A25: 22 | B25: RODAMIENTAS DE CAJA DE CAMBIOS | C25: 177.84 | D25: 240 | E25: 48 | F25: =SUM(C25:E25) -> 465.84 | G25: =F25*0.12 -> 55.9008 | H25: =SUM(F25:G25) -> 521.7408
A26: 23 | B26: SINCRONIZADOS DE CAJA DE CAMBIOS | C26: 192.32 | D26: 240 | E26: 48 | F26: =SUM(C26:E26) -> 480.32 | G26: =F26*0.12 -> 57.6384 | H26: =SUM(F26:G26) -> 537.9584
A27: 24 | B27: PAQUETES DE RESORTES POSTERIORES | C27: 329.28 | D27: 66 | F27: =SUM(C27:E27) -> 395.28 | G27: =F27*0.12 -> 47.4336 | H27: =SUM(F27:G27) -> 442.7136
B28: SUBTOTAL | C28: =SUM(C4:C27) -> 7214.64 | D28: =SUM(D4:D27) -> 2043.35 | E28: =SUM(E4:E27) -> 126 | F28: =SUM(F4:F27) -> 9383.99 | G28: =SUM(G4:G27) -> 1126.0788 | H28: =SUM(H4:H27) -> 10510.069
B29: IVA | C29: =C28*0.12 -> 865.7568 | D29: =D28*0.12 -> 245.202 | E29: =E28*0.12 -> 15.12 | F29: =F28*0.12 -> 1126.0788
B30: TOTAL | C30: =SUM(C28:C29) -> 8080.3968 | D30: =SUM(D28:D29) -> 2288.552 | E30: =SUM(E28:E29) -> 141.12 | F30: =SUM(F28:F29) -> 10510.069

Sheet REF. MANT. CORRECTIVO COMPLETO
A1: MARCA | B1: GWM
A2: MODELO | B2: WINGLE 7 DIESEL | C2: MANTENIMIENTOS CORRECTIVOS
A3: ITEM | B3: DESCRIPCION | C3: TOTAL REPUESTOS | D3: Total M/O | E3: TOTAL LUBRICANTES | F3: SUBTOTAL
A4: 1 | B4: BOMBA DE COMBUSTIBLE ALTA PRESION | C4: 1322 | D4: 160 | F4: =SUM(C4:E4) -> 1482
A5: 2 | B5: BOMBA AGUA | C5: 154.95 | D5: 160 | E5: 35.44 | F5: =SUM(C5:E5) -> 350.39
A6: 3 | B6: BOMBA DIRECCION HIDRAULICA | C6: 187.49 | D6: 82.5 | E6: =8.71*2 -> 17.42 | F6: =SUM(C6:E6) -> 287.41
A7: 4 | B7: AMORTIGUADORES DELANTEROS (2) | C7: 157.52 | D7: 40 | F7: =SUM(C7:E7) -> 197.52
A8: 5 | B8: AMORTIGUADORES POSTERIORES (2) | C8: 124 | D8: 40 | F8: =SUM(C8:E8) -> 164
A9: 6 | B9: KIT EMBRAGUE COMPLETO | C9: 250 | D9: 150 | F9: =C9+C10+D9 -> 410
A10: 7 | B10: RODAMIENTO VOLANTE | C10: 10
A11: 8 | B11: RODAMIENTOS PUNTAS DE EJE DELANTEROS (4) | C11: 90 | D11: 61.05 | F11: =SUM(C11:E11) -> 151.05
