Workbook

Sheet Hoja1
A1: GWM POER GASOLINA | B1: A/F | C1: 5000 | D1: 10000 | E1: 20000 | F1: 30000 | G1: 40000 | H1: 50000 | I1: 60000 | J1: 70000 | K1: 80000 | L1: 90000 | M1: 100000 | N1: 110000 | O1: 120000
A2: ACEITE MOTOR | B2: 30.9 | C2: 30.9 | D2: 30.9 | E2: 30.9 | F2: 30.9 | G2: 30.9 | H2: 30.9 | I2: 30.9 | J2: 30.9 | K2: 30.9 | L2: 30.9 | M2: 30.9 | N2: 30.9 | O2: 30.9
A3: FILTRO DE ACEITE | B3: 17.6 | C3: 17.6 | D3: 17.6 | E3: 17.6 | F3: 17.6 | G3: 17.6 | H3: 17.6 | I3: 17.6 | J3: 17.6 | K3: 17.6 | L3: 17.6 | M3: 17.6 | N3: 17.6 | O3: 17.6
A4: FILTRO DE GASOLINA | D4: 16.64 | E4: 16.64 | F4: 16.64 | G4: 16.64 | H4: 16.64 | I4: 16.64 | J4: 16.64 | K4: 16.64 | L4: 16.64 | M4: 16.64 | N4: 16.64 | O4: 16.64
A5: FILTRO DE AIRE | D5: 29 | E5: 29 | F5: 29 | G5: 29 | H5: 29 | I5: 29 | J5: 29 | K5: 29 | L5: 29 | M5: 29 | N5: 29 | O5: 29
A6: PASTILLAS DE FRENO DEL | E6: 69.17 | F6: 69.17 | G6: 69.17 | H6: 69.17 | I6: 69.17 | J6: 69.17 | K6: 69.17 | L6: 69.17 | M6: 69.17 | O6: 69.17
A7: PASTILLAS DE FRENO POST | D7: 0 | E7: 50.77 | G7: 50.77 | I7: 50.77 | K7: 50.77 | M7: 50.77 | N7: 0 | O7: 50.77
A8: LIQUIDO INYECTORES | E8: 6.5 | G8: 6.5 | I8: 6.5 | K8: 6.5 | M8: 6.5 | O8: 6.5
A9: LIMPIADOR DE FRENOS | D9: 5 | E9: 5 | F9: 5 | G9: 5 | H9: 5 | I9: 5 | J9: 5 | K9: 5 | L9: 5 | M9: 5 | N9: 5 | O9: 5
A10: LIMPIADOR DE ADMISION | D10: 5.4 | E10: 5.4 | F10: 5.4 | G10: 5.4 | H10: 5.4 | J10: 5.4 | K10: 5.4 | L10: 5.4 | M10: 5.4 | N10: 5.4
A11: REFRIGERANTE | H11: 14 | M11: 14
A12: ACEITE DE CAJA Y TRANS | C12: 40.6 | H12: 40.6 | M12: 40.6
A13: BUJIAS | E13: 70.04 | G13: 70.04 | I13: 70.04 | J13: 0 | K13: 70.04 | L13: 0 | M13: 70.04 | O13: 70.04
A14: SUMINISTROS | B14: 3 | C14: 3 | D14: 3.5 | E14: 3.5 | F14: 3.5 | G14: 3.5 | H14: 3.5 | I14: 3.5 | J14: 3.5 | K14: 3.5 | L14: 3.5 | M14: 3.5 | N14: 3.5 | O14: 3.5
A15: LIMPIA TANQUES BG | E15: 0 | F15: 0 | G15: 0 | H15: 0 | I15: 0 | J15: 0 | K15: 0 | L15: 0 | M15: 0 | O15: 0
A16: LIQUIDO DE FRENOS | E16: 3 | G16: 3 | I16: 3 | K16: 3 | M16: 3 | O16: 3
A17: TOTAL REPUESTOS | B17: 51.5 | C17: 92.1 | D17: 108.04 | E17: 307.52 | F17: 177.21 | G17: 307.52 | H17: 231.81 | I17: 302.12 | J17: 177.21 | K17: 307.52 | L17: 177.21 | M17: 362.12 | N17: 108.04 | O17: 302.12
A18: MANO DE OBRA | B18: 6.6 | C18: 13.2 | D18: 110.55 | E18: 117.15 | F18: 105.6 | G18: 132 | H18: 125.4 | I18: 132 | J18: 105.6 | K18: 128.7 | L18: 132 | M18: 138.6 | N18: 110.55 | O18: 132
A19: ALINEACION Y BALANCEO | B19: 0 | C19: 0 | D19: 33 | E19: 33 | F19: 33 | G19: 33 | H19: 33 | I19: 33 | J19: 33 | K19: 33 | L19: 33 | M19: 33 | N19: 33 | O19: 33
A20: LIMPIEZA DE INYECTORES | B20: 0 | C20: 0 | D20: 0 | E20: 16.5 | F20: 0 | G20: 16.5 | H20: 0 | I20: 16.5 | J20: 0 | K20: 16.5 | L20: 0 | M20: 16.5 | N20: 0 | O20: 16.5
A21: TOTAL M/O | B21: 6.6 | C21: 13.2 | D21: 143.55 | E21: 166.65 | F21: 138.6 | G21: 181.5 | H21: 158.4 | I21: 181.5 | J21: 138.6 | K21: 178.2 | L21: 165 | M21: 188.1 | N21: 143.55 | O21: 181.5
A22: TOTAL | B22: 58.1 | C22: 105.3 | D22: 251.59 | E22: 474.17 | F22: 315.81 | G22: 489.02 | H22: 390.21 | I22: 483.62 | J22: 315.81 | K22: 485.72 | L22: 342.21 | M22: 550.22 | N22: 251.59 | O22: 483.62
A24: GWM POER DIESEL | B24: A/F | C24: 5000 | D24: 10000 | E24: 20000 | F24: 30000 | G24: 40000 | H24: 50000 | I24: 60000 | J24: 70000 | K24: 80000 | L24: 90000 | M24: 100000 | N24: 110000 | O24: 120000
A25: FILTRO DE ACEITE | B25: 11.84 | C25: 11.84 | D25: 11.84 | E25: 11.84 | F25: 11.84 | G25: 11.84 | H25: 11.84 | I25: 11.84 | J25: 11.84 | K25: 11.84 | L25: 11.84 | M25: 11.84 | N25: 11.84 | O25: 11.84
A26: FILTRO DE COMBUSTIBLE | B26: 32.76 | C26: 32.76 | D26: 32.76 | E26: 32.76 | F26: 32.76 | G26: 32.76 | H26: 32.76 | I26: 32.76 | J26: 32.76 | K26: 32.76 | L26: 32.76 | M26: 32.76 | N26: 32.76 | O26: 32.76
A27: FILTRO DE AIRE | D27: 20.99 | E27: 20.99 | F27: 20.99 | G27: 20.99 | H27: 20.99 | I27: 20.99 | J27: 20.99 | K27: 20.99 | L27: 20.99 | M27: 20.99 | N27: 20.99 | O27: 20.99
A28: PASTILLAS DE FRENO DEL | E28: 76.09 | F28: 76.09 | G28: 76.09 | H28: 76.09 | I28: 76.09 | J28: 76.09 | K28: 76.09 | L28: 76.09 | M28: 76.09 | O28: 76.09
A29: PASTILLAS DE FRENO POST | D29: 0 | E29: 55.85 | G29: 55.85 | I29: 55.85 | K29: 55.85 | M29: 55.85 | N29: 0 | O29: 55.85
A30: TOTAL REPUESTOS | B30: =SUM(B25:B29) -> 44.6 | C30: =SUM(C25:C29) -> 44.6 | D30: =SUM(D25:D29) -> 65.59 | E30: =SUM(E25:E29) -> 197.53 | F30: =SUM(F25:F29) -> 141.68 | G30: =SUM(G25:G29) -> 197.53 | H30: =SUM(H25:H29) -> 141.68 | I30: =SUM(I25:I29) -> 197.53 | ... O30: =SUM(O25:O29) -> 197.53
A31: ACEITE MOTOR | B31: 40.32 | C31: 40.32 | D31: 40.32 | E31: 40.32 | F31: 40.32 | G31: 40.32 | H31: 40.32 | I31: 40.32 | J31: 40.32 | K31: 40.32 | L31: 40.32 | M31: 40.32 | N31: 40.32 | O31: 40.32
A32: LIQUIDO INYECTORES | E32: 7.71 | G32: 7.71 | I32: 7.71 | K32: 7.71 | M32: 7.71 | O32: 7.71
A33: LIMPIADOR DE FRENOS | D33: 6.16 | E33: 6.16 | F33: 6.16 | G33: 6.16 | H33: 6.16 | I33: 6.16 | J33: 6.16 | K33: 6.16 | L33: 6.16 | M33: 6.16 | N33: 6.16 | O33: 6.16
A34: LIMPIADOR DE ADMISION | D34: 6.62 | E34: 6.62 | F34: 6.62 | G34: 6.62 | H34: 6.62 | I34: 6.62 | J34: 6.62 | K34: 6.62 | L34: 6.62 | M34: 6.62 | N34: 6.62 | O34: 6.62
A35: REFRIGERANTE | H35: 17.73 | M35: 17.73
A36: ACEITE DE CAJA Y TRANS | C36: 54.81 | H36: 54.81 | M36: 54.81
A37: SUMINISTROS | B37: 3.5 | C37: 3.5 | D37: 3.5 | E37: 3.5 | F37: 3.5 | G37: 3.5 | H37: 3.5 | I37: 3.5 | J37: 3.5 | K37: 3.5 | L37: 3.5 | M37: 3.5 | N37: 3.5 | O37: 3.5
A38: LIQUIDO DE FRENOS | E38: 3.59 | G38: 3.59 | I38: 3.59 | K38: 3.59 | M38: 3.59 | O38: 3.59
A39: TOTAL LUBRICANTES E INSUMOS | B39: =SUM(B31:B38) -> 43.82 | C39: =SUM(C31:C38) -> 98.63 | D39: =SUM(D31:D38) -> 56.6 | E39: =SUM(E31:E38) -> 67.9 | F39: =SUM(F31:F38) -> 56.6 | G39: =SUM(G31:G38) -> 67.9 | H39: =SUM(H31:H38) -> 129.14 | I39: =SUM(I31:I38) -> 67.9 | ... O39: =SUM(O31:O38) -> 67.9
A40: MANO DE OBRA | B40: 13.2 | C40: 18.15 | D40: 113.85 | E40: 120.45 | F40: 131.01 | G40: 150.15 | H40: 125.4 | I40: 134.31 | J40: 105.6 | K40: 120.45 | L40: 134.31 | M40: 244.2 | N40: 113.85 | O40: 134.31
A41: ALINEACION Y BALANCEO | B41: 0 | C41: 0 | D41: 33 | E41: 33 | F41: 33 | G41: 33 | H41: 33 | I41: 33 | J41: 33 | K41: 33 | L41: 33 | M41: 33 | N41: 33 | O41: 33
...

Sheet CRONOGRAMA MANT POER 4X4
A1: CRONOGRAMA DE MANTENIMIENTO POER AC 2.0 CD 4X4 TM DIESEL
A2: GWM POER DIESEL | B2: A/F | C2: 5.000 KM | D2: 10.000 KM | E2: 15.000 KM | F2: 20.000 KM | G2: 25.000 KM | H2: 30.000 KM | I2: 35.000 KM | J2: 40.000 KM | K2: 45.000 KM | L2: 50.000 KM | M2: 55.000 KM | N2: 60.000 KM | O2: 65.000 KM | P2: 70.000 KM | Q2: 75.000 KM | R2: 80.000 KM | S2: 85.000 KM | T2: 90.000 KM | U2: 95.000 KM | V2: 100.000 KM | W2: 105.000 KM | X2: 110.000 KM | Y2: 115.000 KM | Z2: 120.000 KM
A3: FILTRO DE ACEITE | B3: X | C3: 11.84 | D3: 11.84 | E3: 11.84 | F3: 11.84 | G3: 11.84 | H3: 11.84 | I3: 11.84 | J3: 11.84 | K3: 11.84 | L3: 11.84 | M3: 11.84 | N3: 11.84 | O3: 11.84 | P3: 11.84 | Q3: 11.84 | R3: 11.84 | S3: 11.84 | T3: 11.84 | U3: 11.84 | V3: 11.84 | W3: 11.84 | X3: 11.84 | Y3: 11.84 | Z3: 11.84
A4: FILTRO DE COMBUSTIBLE | B4: 32.76 | C4: 32.76 | D4: 32.76 | E4: 32.76 | F4: 32.76 | G4: 32.76 | H4: 32.76 | I4: 32.76 | J4: 32.76 | K4: 32.76 | L4: 32.76 | M4: 32.76 | N4: 32.76 | O4: 32.76 | P4: 32.76 | Q4: 32.76 | R4: 32.76 | S4: 32.76 | T4: 32.76 | U4: 32.76 | V4: 32.76 | W4: 32.76 | X4: 32.76 | Y4: 32.76 | Z4: 32.76
A5: FILTRO DE AIRE | D5: 20.99 | F5: 20.99 | H5: 20.99 | J5: 20.99 | L5: 20.99 | N5: 20.99 | P5: 20.99 | R5: 20.99 | T5: 20.99 | V5: 20.99 | X5: 20.99 | Z5: 20.99
A6: PASTILLAS DE FRENO DEL | F6: 76.09 | H6: 76.09 | J6: 76.09 | L6: 76.09 | N6: 76.09 | P6: 76.09 | R6: 76.09 | T6: 76.09 | V6: 76.09 | Z6: 76.09
A7: PASTILLAS DE FRENO POST | D7: 0 | F7: 55.85 | J7: 55.85 | N7: 55.85 | R7: 55.85 | V7: 55.85 | X7: 0 | Z7: 55.85
A8: TOTAL REPUESTOS | B8: =SUM(B3:B7) -> 32.76 | C8: =SUM(C3:C7) -> 44.6 | D8: =SUM(D3:D7) -> 65.59 | E8: =SUM(E3:E7) -> 44.6 | F8: =SUM(F3:F7) -> 197.53 | G8: =SUM(G3:G7) -> 44.6 | H8: =SUM(H3:H7) -> 141.68 | I8: =SUM(I3:I7) -> 44.6 | ... Z8: =SUM(Z3:Z7) -> 197.53
A9: ACEITE MOTOR | B9: 40.32 | C9: 40.32 | D9: 40.32 | E9: 40.32 | F9: 40.32 | G9: 40.32 | H9: 40.32 | I9: 40.32 | J9: 40.32 | K9: 40.32 | L9: 40.32 | M9: 40.32 | N9: 40.32 | O9: 40.32 | P9: 40.32 | Q9: 40.32 | R9: 40.32 | S9: 40.32 | T9: 40.32 | U9: 40.32 | V9: 40.32 | W9: 40.32 | X9: 40.32 | Y9: 40.32 | Z9: 40.32
A10: LIQUIDO INYECTORES | F10: 7.71 | J10: 7.71 | N10: 7.71 | R10: 7.71 | V10: 7.71 | Z10: 7.71
A11: LIMPIADOR DE FRENOS | D11: 6.16 | F11: 6.16 | H11: 6.16 | J11: 6.16 | L11: 6.16 | N11: 6.16 | P11: 6.16 | R11: 6.16 | T11: 6.16 | V11: 6.16 | X11: 6.16 | Z11: 6.16
A12: LIMPIADOR DE ADMISION | D12: 6.62 | F12: 6.62 | H12: 6.62 | J12: 6.62 | L12: 6.62 | N12: 6.62 | P12: 6.62 | R12: 6.62 | T12: 6.62 | V12: 6.62 | X12: 6.62 | Z12: 6.62
A13: REFRIGERANTE | L13: 17.73 | V13: 17.73
A14: ACEITE DE CAJA Y TRANS | C14: 54.81 | L14: 54.81 | V14: 54.81
A15: SUMINISTROS | B15: 3.5 | C15: 3.5 | D15: 3.5 | E15: 3.5 | F15: 3.5 | G15: 3.5 | H15: 3.5 | I15: 3.5 | J15: 3.5 | K15: 3.5 | L15: 3.5 | M15: 3.5 | N15: 3.5 | O15: 3.5 | P15: 3.5 | Q15: 3.5 | R15: 3.5 | S15: 3.5 | T15: 3.5 | U15: 3.5 | V15: 3.5 | W15: 3.5 | X15: 3.5 | Y15: 3.5 | Z15: 3.5
A16: LIQUIDO DE FRENOS | F16: 3.59 | J16: 3.59 | N16: 3.59 | R16: 3.59 | V16: 3.59 | Z16: 3.59
A17: TOTAL LUBRICANTES | B17: =SUM(B9:B16) -> 43.82 | C17: =SUM(C9:C16) -> 98.63 | D17: =SUM(D9:D16) -> 56.6 | E17: =SUM(E9:E16) -> 43.82 | F17: =SUM(F9:F16) -> 67.9 | G17: =SUM(G9:G16) -> 43.82 | H17: =SUM(H9:H16) -> 56.6 | I17: =SUM(I9:I16) -> 43.82 | ... Z17: =SUM(Z9:Z16) -> 67.9
A18: MANO DE OBRA | B18: 15.18 | C18: 20.79 | D18: 137.28 | E18: 15.18 | F18: 146.19 | G18: 15.18 | H18: 157.08 | I18: 15.18 | J18: 181.5 | K18: 15.18 | L18: 150.81 | M18: 15.18 | N18: 163.35 | O18: 15.18 | P18: 128.04 | Q18: 15.18 | R18: 147.51 | S18: 15.18 | T18: 161.04 | U18: 15.18 | V18: 289.74 | W18: 15.18 | X18: 137.28 | Y18: 15.18 | Z18: 163.35
A19: ALINEACION Y BALANCEO | B19: 0 | C19: 0 | D19: 17.16 | E19: 0 | F19: 17.16 | G19: 0 | H19: 17.16 | I19: 0 | J19: 17.16 | K19: 0 | L19: 17.16 | M19: 0 | N19: 17.16 | O19: 0 | P19: 17.16 | Q19: 0 | R19: 17.16 | S19: 0 | T19: 17.16 | U19: 0 | V19: 17.16 | W19: 0 | X19: 17.16 | Y19: 0 | Z19: 17.16
A20: BALANCEO | D20: 15.84 | F20: 15.84 | H20: 15.84 | J20: 15.84 | L20: 15.84 | N20: 15.84 | P20: 15.84 | R20: 15.84 | T20: 15.84 | V20: 15.84 | X20: 15.84 | Z20: 15.84
A21: LIMPIEZA DE INYECTORES | B21: 0 | C21: 0 | D21: 0 | E21: 0 | F21: 16.5 | G21: 0 | H21: 0 | I21: 0 | J21: 16.5 | K21: 0 | L21: 0 | M21: 0 | N21: 16.5 | O21: 0 | P21: 0 | Q21: 0 | R21: 16.5 | S21: 0 | T21: 0 | U21: 0 | V21: 16.5 | W21: 0 | X21: 0 | Y21: 0 | Z21: 16.5
A22: LAVADO | D22: 9.9 | F22: 9.9 | H22: 9.9 | J22: 9.9 | L22: 9.9 | N22: 9.9 | P22: 9.9 | R22: 9.9 | T22: 9.9 | V22: 9.9 | X22: 9.9 | Z22: 9.9
A23: TOTAL M/O | B23: =SUM(B18:B22) -> 15.18 | C23: =SUM(C18:C22) -> 20.79 | D23: =SUM(D18:D22) -> 180.18 | E23: =SUM(E18:E22) -> 15.18 | F23: =SUM(F18:F22) -> 205.59 | G23: =SUM(G18:G22) -> 15.18 | H23: =SUM(H18:H22) -> 199.98 | I23: =SUM(I18:I22) -> 15.18 | ... Z23: =SUM(Z18:Z22) -> 222.75
A24: TOTAL MANTENIMIENTO X KM | B24: =+B8+B17+B23 -> 91.76 | C24: =+C8+C17+C23 -> 164.02 | D24: =+D8+D17+D23 -> 302.37 | E24: =+E8+E17+E23 -> 103.6 | F24: =+F8+F17+F23 -> 471.02 | G24: =+G8+G17+G23 -> 103.6 | H24: =+H8+H17+H23 -> 398.26 | I24: =+I8+I17+I23 -> 103.6 | ... Z24: =+Z8+Z17+Z23 -> 488.18

Sheet POER AC 2.0 CD 4X2 TM DIESEL
A1: PLAN DE MANTENIMIENTO POER AC 2.0 CD 4X2 TM DIESEL
A2: GWM POER DIESEL | B2: A/F | C2: 5.000 KM | D2: 10.000 KM | E2: 15.000 KM | F2: 20.000 KM | G2: 25.000 KM | H2: 30.000 KM | I2: 35.000 KM | J2: 40.000 KM | K2: 45.000 KM | L2: 50.000 KM | M2: 55.000 KM | N2: 60.000 KM | O2: 65.000 KM | P2: 70.000 KM | Q2: 75.000 KM | R2: 80.000 KM | S2: 85.000 KM | T2: 90.000 KM | U2: 95.000 KM | V2: 100.000 KM | W2: 105.000 KM | X2: 110.000 KM | Y2: 115.000 KM | Z2: 120.000 KM
A3: FILTRO DE ACEITE | B3: 11.84 | C3: 11.84 | D3: 11.84 | E3: 11.84 | F3: 11.84 | G3: 11.84 | H3: 11.84 | I3: 11.84 | J3: 11.84 | K3: 11.84 | L3: 11.84 | M3: 11.84 | N3: 11.84 | O3: 11.84 | P3: 11.84 | Q3: 11.84 | R3: 11.84 | S3: 11.84 | T3: 11.84 | U3: 11.84 | V3: 11.84 | W3: 11.84 | X3: 11.84 | Y3: 11.84 | Z3: 11.84
A4: FILTRO DE COMBUSTIBLE | B4: 32.76 | C4: 32.76 | D4: 32.76 | E4: 32.76 | F4: 32.76 | G4: 32.76 | H4: 32.76 | I4: 32.76 | J4: 32.76 | K4: 32.76 | L4: 32.76 | M4: 32.76 | N4: 32.76 | O4: 32.76 | P4: 32.76 | Q4: 32.76 | R4: 32.76 | S4: 32.76 | T4: 32.76 | U4: 32.76 | V4: 32.76 | W4: 32.76 | X4: 32.76 | Y4: 32.76 | Z4: 32.76
A5: FILTRO DE AIRE | D5: 20.99 | F5: 20.99 | H5: 20.99 | J5: 20.99 | L5: 20.99 | N5: 20.99 | P5: 20.99 | R5: 20.99 | T5: 20.99 | V5: 20.99 | X5: 20.99 | Z5: 20.99
A6: PASTILLAS DE FRENO DEL | D6: 76.09 | F6: 76.09 | H6: 76.09 | J6: 76.09 | L6: 76.09 | N6: 76.09 | P6: 76.09 | R6: 76.09 | T6: 76.09 | V6: 76.09 | X6: 76.09 | Z6: 76.09
A7: PASTILLAS DE FRENO POST | F7: 55.85 | J7: 55.85 | N7: 55.85 | R7: 55.85 | V7: 55.85 | Z7: 55.85
A8: KIT BANDA DE ACCESORIOS | R8: 79.87
A9: FILTRO DE CABINA A/C | D9: 21.25 | F9: 21.25 | H9: 21.25 | J9: 21.25 | L9: 21.25 | N9: 21.25 | P9: 21.25 | R9: 21.25 | T9: 21.25 | V9: 21.25 | X9: 21.25 | Z9: 21.25
A10: BASE TERMOSTATO Y TERMOSTATO | L10: 23.71 | V10: 23.71
A11: TEMPLADOR BANDA DISTRIBUCION | V11: 163.9
A12: BANDA DE DISTRIBUCION | V12: 88.84
A13: RODAMIENTO BANDA DISTRIBUCION | V13: 71.41
A14: ARANDELA DE TAPON DE CARTER | C14: 7.5 | D14: 7.5 | E14: 7.5 | F14: 7.5 | G14: 7.5 | H14: 7.5 | I14: 7.5 | J14: 7.5 | K14: 7.5 | L14: 7.5 | M14: 7.5 | N14: 7.5 | O14: 7.5 | P14: 7.5 | Q14: 7.5 | R14: 7.5 | S14: 7.5 | T14: 7.5 | U14: 7.5 | V14: 7.5 | W14: 7.5 | X14: 7.5 | Y14: 7.5 | Z14: 7.5
A15: TOTAL REPUESTOS | B15: =SUM(B3:B7) -> 44.6 | C15: =SUM(C3:C14) -> 52.1 | D15: =SUM(D3:D14) -> 170.43 | E15: =SUM(E3:E14) -> 52.1 | F15: =SUM(F3:F14) -> 226.28 | G15: =SUM(G3:G14) -> 52.1 | H15: =SUM(H3:H14) -> 170.43 | I15: =SUM(I3:I14) -> 52.1 | J15: =SUM(J3:J14) -> 226.28 | ... Z15: =SUM(Z3:Z14) -> 226.28 | AA15: =SUM(C15:Z15) -> 3456.9
A16: ACEITE MOTOR(6l) | B16: 40.32 | C16: 46.2 | D16: 46.2 | E16: 46.2 | F16: 46.2 | G16: 46.2 | H16: 46.2 | I16: 46.2 | J16: 46.2 | K16: 46.2 | L16: 46.2 | M16: 46.2 | N16: 46.2 | O16: 46.2 | P16: 46.2 | Q16: 46.2 | R16: 46.2 | S16: 46.2 | T16: 46.2 | U16: 46.2 | V16: 46.2 | W16: 46.2 | X16: 46.2 | Y16: 46.2 | Z16: 46.2
A17: LIQUIDO INYECTORES | F17: 7.71 | J17: 7.71 | N17: 7.71 | R17: 7.71 | V17: 7.71 | Z17: 7.71
A18: LIMPIADOR DE FRENOS | D18: 6.16 | F18: 6.16 | H18: 6.16 | J18: 6.16 | L18: 6.16 | N18: 6.16 | P18: 6.16 | R18: 6.16 | T18: 6.16 | V18: 6.16 | X18: 6.16 | Z18: 6.16
A19: LIMPIADOR DE ADMISION | D19: 6.62 | F19: 6.62 | H19: 6.62 | J19: 6.62 | L19: 6.62 | N19: 6.62 | P19: 6.62 | R19: 6.62 | T19: 6.62 | V19: 6.62 | X19: 6.62 | Z19: 6.62
A20: REFRIGERANTE(8l) | L20: 35.44 | V20: 35.44
A21: ACEITE DE CAJA 75W80(3l) | C21: 28.23 | L21: 28.23 | V21: 28.23
A22: ACEITE DE TRANSMISION 80W90 POST(3l) | C22: 26.61 | L22: 26.61 | V22: 26.61
A23: ACEITE DIRECCION HIDRAULICA(1L) | L23: 8.71 | V23: 8.71
A24: SUMINISTROS | B24: 3.5 | C24: 5 | D24: 5 | E24: 5 | F24: 5 | G24: 5 | H24: 5 | I24: 5 | J24: 5 | K24: 5 | L24: 5 | M24: 5 | N24: 5 | O24: 5 | P24: 5 | Q24: 5 | R24: 5 | S24: 5 | T24: 5 | U24: 5 | V24: 5 | W24: 5 | X24: 5 | Y24: 5 | Z24: 5
A25: LIQUIDO DE FRENOS(2) | F25: 15 | J25: 15 | N25: 15 | R25: 15 | V25: 15 | Z25: 15
A26: ACEITE PARA TRANSFER | AA26: =SUM(C26:Z26) -> 0
A27: TOTAL LUBRICANTES | B27: =SUM(B16:B25) -> 43.82 | C27: =SUM(C16:C26) -> 106.04 | D27: =SUM(D16:D26) -> 63.98 | E27: =SUM(E16:E26) -> 51.2 | F27: =SUM(F16:F26) -> 86.69 | G27: =SUM(G16:G26) -> 51.2 | H27: =SUM(H16:H26) -> 63.98 | I27: =SUM(I16:I26) -> 51.2 | J27: =SUM(J16:J26) -> 86.69 | ... Z27: =SUM(Z16:Z26) -> 86.69 | AA27: =SUM(C27:Z27) -> 1771.24
A28: MANO DE OBRA | B28: 15.18 | C28: 20.79 | D28: 137.28 | E28: 15.18 | F28: 146.19 | G28: 15.18 | H28: 157.08 | I28: 15.18 | J28: 181.5 | K28: 15.18 | L28: 150.81 | M28: 15.18 | N28: 163.35 | O28: 15.18 | P28: 128.04 | Q28: 15.18 | R28: 147.51 | S28: 15.18 | T28: 161.04 | U28: 15.18 | V28: 289.74 | W28: 15.18 | X28: 137.28 | Y28: 15.18 | Z28: 163.35
A29: ALINEACION | B29: 0 | D29: 17.16 | F29: 17.16 | H29: 17.16 | J29: 17.16 | L29: 17.16 | N29: 17.16 | P29: 17.16 | R29: 17.16 | T29: 17.16 | V29: 17.16 | X29: 17.16 | Z29: 17.16
A30: BALANCEO | D30: 15.84 | F30: 15.84 | H30: 15.84 | J30: 15.84 | L30: 15.84 | N30: 15.84 | P30: 15.84 | R30: 15.84 | T30: 15.84 | V30: 15.84 | X30: 15.84 | Z30: 15.84
A31: LIMPIEZA DE INYECTORES | B31: 0 | F31: 16.5 | J31: 16.5 | N31: 16.5 | R31: 16.5 | V31: 16.5 | Z31: 16.5
A32: REAJUSTE DEFENSAS METALICAS | F32: 33 | J32: 33 | N32: 33 | R32: 33 | V32: 33 | Z32: 33
A33: CALIBRACIÓN SISTEMA DE VIGILANCIA | F33: 66 | J33: 66 | N33: 66 | R33: 66 | V33: 66 | Z33: 66
A34: LAVADO | D34: 9.9 | F34: 9.9 | H34: 9.9 | J34: 9.9 | L34: 9.9 | N34: 9.9 | P34: 9.9 | R34: 9.9 | T34: 9.9 | V34: 9.9 | X34: 9.9 | Z34: 9.9
AA35: =SUM(C35:Z35) -> 0
A36: TOTAL M/O | B36: =SUM(B28:B34) -> 15.18 | C36: =SUM(C28:C35) -> 20.79 | D36: =SUM(D28:D35) -> 180.18 | E36: =SUM(E28:E35) -> 15.18 | F36: =SUM(F28:F35) -> 304.59 | G36: =SUM(G28:G35) -> 15.18 | H36: =SUM(H28:H35) -> 199.98 | I36: =SUM(I28:I35) -> 15.18 | J36: =SUM(J28:J35) -> 339.9 | ... Z36: =SUM(Z28:Z35) -> 321.75 | AA36: =SUM(C36:Z36) -> 3358.74
A37: TOTAL MANTENIMIENTO X KM | B37: =+B15+B27+B36 -> 103.6 | C37: =+C15+C27+C36 -> 178.93 | D37: =+D15+D27+D36 -> 414.59 | E37: =+E15+E27+E36 -> 118.48 | F37: =+F15+F27+F36 -> 617.56 | G37: =+G15+G27+G36 -> 118.48 | H37: =+H15+H27+H36 -> 434.39 | I37: =+I15+I27+I36 -> 118.48 | ... Z37: =+Z15+Z27+Z36 -> 634.72 | AA37: =SUM(C37:Z37) -> 8586.88

Sheet POER AC 2.0 CD 4X4 TM DIESEL
A1: PLAN DE MANTENIMIENTO PATRULLEROS
A2: GWM POER DIESEL | B2: 5.000 KM | C2: 10.000 KM | D2: 15.000 KM | E2: 20.000 KM | F2: 25.000 KM | G2: 30.000 KM | H2: 35.000 KM | I2: 40.000 KM | J2: 45.000 KM | K2: 50.000 KM | L2: 55.000 KM | M2: 60.000 KM | N2: 65.000 KM | O2: 70.000 KM | P2: 75.000 KM | Q2: 80.000 KM | R2: 85.000 KM | S2: 90.000 KM | T2: 95.000 KM | U2: 100.000 KM | V2: 105.000 KM | W2: 110.000 KM | X2: 115.000 KM | Y2: 120.000 KM
A3: FILTRO DE ACEITE | B3: 14.34 | C3: 14.34 | D3: 14.34 | E3: 14.34 | F3: 14.34 | G3: 14.34 | H3: 14.34 | I3: 14.34 | J3: 14.34 | K3: 14.34 | L3: 14.34 | M3: 14.34 | N3: 14.34 | O3: 14.34 | P3: 14.34 | Q3: 14.34 | R3: 14.34 | S3: 14.34 | T3: 14.34 | U3: 14.34 | V3: 14.34 | W3: 14.34 | X3: 14.34 | Y3: 14.34
A4: FILTRO DE COMBUSTIBLE | B4: 35.26 | C4: 35.26 | D4: 35.26 | E4: 35.26 | F4: 35.26 | G4: 35.26 | H4: 35.26 | I4: 35.26 | J4: 35.26 | K4: 35.26 | L4: 35.26 | M4: 35.26 | N4: 35.26 | O4: 35.26 | P4: 35.26 | Q4: 35.26 | R4: 35.26 | S4: 35.26 | T4: 35.26 | U4: 35.26 | V4: 35.26 | W4: 35.26 | X4: 35.26 | Y4: 35.26
A5: FILTRO DE AIRE | C5: 20.99 | E5: 20.99 | G5: 20.99 | I5: 20.99 | K5: 20.99 | M5: 20.99 | O5: 20.99 | Q5: 20.99 | S5: 20.99 | U5: 20.99 | W5: 20.99 | Y5: 20.99
A6: PASTILLAS DE FRENO DEL | C6: 76.09 | E6: 76.09 | G6: 76.09 | I6: 76.09 | K6: 76.09 | M6: 76.09 | O6: 76.09 | Q6: 76.09 | S6: 76.09 | U6: 76.09 | W6: 76.09 | Y6: 76.09
A7: PASTILLAS DE FRENO POST | E7: 55.85 | I7: 55.85 | M7: 55.85 | Q7: 55.85 | U7: 55.85 | Y7: 55.85
A8: BANDA DE ACCESORIOS | Q8: 79.87
A9: FILTRO DE CABINA A/C | C9: 21.25 | E9: 21.25 | G9: 21.25 | I9: 21.25 | K9: 21.25 | M9: 21.25 | O9: 21.25 | Q9: 21.25 | S9: 21.25 | U9: 21.25 | W9: 21.25 | Y9: 21.25
A10: TERMOSTATO | K10: 12.71 | U10: 12.71
A11: BASE TERMOSTATO | K11: 11 | U11: 11
A12: TEMPLADOR BANDA DISTRIBUCION 4D20M | U12: 125.9
A13: RODAMIENTO BANDA DISTRIBUCION 4D20M | U13: 38
A14: BANDA DE DISTRIBUCION | U14: 88.84
A15: RODAMIENTO BANDA DISTRIBUCION | U15: 71.41
A16: ARANDELA DE TAPON DE CARTER | B16: 7.5 | C16: 7.5 | D16: 7.5 | E16: 7.5 | F16: 7.5 | G16: 7.5 | H16: 7.5 | I16: 7.5 | J16: 7.5 | K16: 7.5 | L16: 7.5 | M16: 7.5 | N16: 7.5 | O16: 7.5 | P16: 7.5 | Q16: 7.5 | R16: 7.5 | S16: 7.5 | T16: 7.5 | U16: 7.5 | V16: 7.5 | W16: 7.5 | X16: 7.5 | Y16: 7.5
A17: TOTAL REPUESTOS | B17: =SUM(B3:B16) -> 57.1 | C17: =SUM(C3:C16) -> 175.43 | D17: =SUM(D3:D16) -> 57.1 | E17: =SUM(E3:E16) -> 231.28 | F17: =SUM(F3:F16) -> 57.1 | G17: =SUM(G3:G16) -> 175.43 | H17: =SUM(H3:H16) -> 57.1 | I17: =SUM(I3:I16) -> 231.28 | ... Y17: =SUM(Y3:Y16) -> 231.28 | Z17: =SUM(B17:Y17) -> 3576.9
A18: ACEITE MOTOR(6l) | B18: 46.2 | C18: 46.2 | D18: 46.2 | E18: 46.2 | F18: 46.2 | G18: 46.2 | H18: 46.2 | I18: 46.2 | J18: 46.2 | K18: 46.2 | L18: 46.2 | M18: 46.2 | N18: 46.2 | O18: 46.2 | P18: 46.2 | Q18: 46.2 | R18: 46.2 | S18: 46.2 | T18: 46.2 | U18: 46.2 | V18: 46.2 | W18: 46.2 | X18: 46.2 | Y18: 46.2
A19: LIQUIDO INYECTORES | E19: 7.71 | I19: 7.71 | M19: 7.71 | Q19: 7.71 | U19: 7.71 | Y19: 7.71
A20: LIMPIADOR DE FRENOS | C20: 6.16 | E20: 6.16 | G20: 6.16 | I20: 6.16 | K20: 6.16 | M20: 6.16 | O20: 6.16 | Q20: 6.16 | S20: 6.16 | U20: 6.16 | W20: 6.16 | Y20: 6.16
A21: LIMPIADOR DE ADMISION | C21: 6.62 | E21: 6.62 | G21: 6.62 | I21: 6.62 | K21: 6.62 | M21: 6.62 | O21: 6.62 | Q21: 6.62 | S21: 6.62 | U21: 6.62 | W21: 6.62 | Y21: 6.62
A22: REFRIGERANTE(8l) | K22: 35.44 | U22: 35.44
A23: ACEITE DE CAJA 75W80(3l) | B23: 28.23 | K23: 28.23 | U23: 28.23
A24: ACEITE DE TRANSMISION 80W90 DEL (3l) | B24: 26.61 | K24: 26.61 | U24: 26.61
A25: ACEITE DE TRANSMISION 80W90 POST(3l) | B25: 26.61 | K25: 26.61 | U25: 26.61
A26: ACEITE CAJA DE TRANSFERENCIA(2l) | K26: 17.42 | U26: 17.42
A27: ACEITE DIRECCION HIDRAULICA(1L) | K27: 8.71 | U27: 8.71
A28: LIQUIDO DE FRENOS(2) | E28: 15 | I28: 15 | M28: 15 | Q28: 15 | U28: 15 | Y28: 15
A29: ACEITE PARA TRANSFER | Z29: =SUM(B30:Y30) -> 1765.91
A30: TOTAL LUBRICANTES | B30: =SUM(B18:B29) -> 127.65 | C30: =SUM(C18:C29) -> 58.98 | D30: =SUM(D18:D29) -> 46.2 | E30: =SUM(E18:E29) -> 81.69 | F30: =SUM(F18:F29) -> 46.2 | G30: =SUM(G18:G29) -> 58.98 | H30: =SUM(H18:H29) -> 46.2 | I30: =SUM(I18:I29) -> 81.69 | ... Y30: =SUM(Y18:Y29) -> 81.69 | Z30: =SUM(B30:Y30) -> 1765.91
A31: MANO DE OBRA | B31: 20.79 | C31: 137.28 | D31: 15.18 | E31: 146.19 | F31: 15.18 | G31: 157.08 | H31: 15.18 | I31: 181.5 | J31: 15.18 | K31: 150.81 | L31: 15.18 | M31: 163.35 | N31: 15.18 | O31: 128.04 | P31: 15.18 | Q31: 147.51 | R31: 15.18 | S31: 161.04 | T31: 15.18 | U31: 289.74 | V31: 15.18 | W31: 137.28 | X31: 15.18 | Y31: 163.35
A32: ALINEACION | C32: 17.16 | E32: 17.16 | G32: 17.16 | I32: 17.16 | K32: 17.16 | M32: 17.16 | O32: 17.16 | Q32: 17.16 | S32: 17.16 | U32: 17.16 | W32: 17.16 | Y32: 17.16
A33: BALANCEO | C33: 15.84 | E33: 15.84 | G33: 15.84 | I33: 15.84 | K33: 15.84 | M33: 15.84 | O33: 15.84 | Q33: 15.84 | S33: 15.84 | U33: 15.84 | W33: 15.84 | Y33: 15.84
A34: LIMPIEZA DE INYECTORES | E34: 16.5 | I34: 16.5 | M34: 16.5 | Q34: 16.5 | U34: 16.5 | Y34: 16.5
A35: REAJUSTE DEFENSAS METALICAS | E35: 33 | I35: 33 | M35: 33 | Q35: 33 | U35: 33 | Y35: 33
A36: CALIBRACIÓN SISTEMA DE VIGILANCIA | E36: 66 | I36: 66 | M36: 66 | Q36: 66 | U36: 66 | Y36: 66
A37: LAVADO | C37: 9.9 | E37: 9.9 | G37: 9.9 | I37: 9.9 | K37: 9.9 | M37: 9.9 | O37: 9.9 | Q37: 9.9 | S37: 9.9 | U37: 9.9 | W37: 9.9 | Y37: 9.9
Z38: =SUM(B39:Y39) -> 3358.74
A39: TOTAL M/O | B39: =SUM(B31:B38) -> 20.79 | C39: =SUM(C31:C38) -> 180.18 | D39: =SUM(D31:D38) -> 15.18 | E39: =SUM(E31:E38) -> 304.59 | F39: =SUM(F31:F38) -> 15.18 | G39: =SUM(G31:G38) -> 199.98 | H39: =SUM(H31:H38) -> 15.18 | I39: =SUM(I31:I38) -> 339.9 | ... Y39: =SUM(Y31:Y38) -> 321.75 | Z39: =SUM(B39:Y39) -> 3358.74
A40: TOTAL MANTENIMIENTO X KM | B40: =+B17+B30+B39 -> 205.54 | C40: =+C17+C30+C39 -> 414.59 | D40: =+D17+D30+D39 -> 118.48 | E40: =+E17+E30+E39 -> 617.56 | F40: =+F17+F30+F39 -> 118.48 | G40: =+G17+G30+G39 -> 434.39 | H40: =+H17+H30+H39 -> 118.48 | I40: =+I17+I30+I39 -> 652.87 | ... Y40: =+Y17+Y30+Y39 -> 634.72

Sheet CONSOLIDADO DE VALORES
B2: COSTOS MANTENIMIENTO POER 4X4 | G2: CANTIDAD DE VEHICULOS
B3: 1 | C3: Total Repuestos | D3: Mantenimiento preventivo | E3: ='POER AC 2.0 CD 4X4 TM DIESEL'!Z17 -> 3576.9 | G3: 1
B4: 2 | C4: Total Lubricantes | E4: ='POER AC 2.0 CD 4X4 TM DIESEL'!Z30 -> 1765.91
B5: 3 | C5: Total Mano de Obra | E5: ='POER AC 2.0 CD 4X4 TM DIESEL'!Z39 -> 3358.74
B6: 4 | C6: Mantenimiento correctivo | D6: Se considera un valor aproximado del 30% del costo total de mantenimientos preventivos | E6: =(E3+E4+E5)*0.3 -> 2610.465
B7: Total 1 + 2 + 3 + 4 | E7: =SUM(E3:E6) -> 11312.015
B8: Costos no incluyen IVA
B11: COSTOS MANTENIMIENTO POER 7 4X2 | G11: CANTIDAD DE VEHICULOS
B12: 1 | C12: Total Repuestos | D12: Mantenimiento preventivo | E12: ='POER AC 2.0 CD 4X2 TM DIESEL'!AA15*G12 -> 3456.9 | G12: 1
B13: 2 | C13: Total Lubricantes | E13: ='POER AC 2.0 CD 4X2 TM DIESEL'!AA27*G12 -> 1771.24
B14: 3 | C14: Total Mano de Obra | E14: ='POER AC 2.0 CD 4X2 TM DIESEL'!AA36*G12 -> 3358.74
B15: 4 | C15: Mantenimiento correctivo | D15: Se considera un valor aproximado del 30% del costo total de mantenimientos preventivos | E15: =(E12+E13+E14)*0.3 -> 2576.064
B16: Total 1 + 2 + 3 + 4 | E16: =SUM(E12:E15) -> 11162.944
B17: Costos no incluyen IVA

Sheet REF MANT CORRECTIVO
A1: MARCA | B1: GWM
A2: MODELO | B2: POER 2.0 AC 4X4 | C2: MANTENIMIENTOS CORRECTIVOS
A3: ITEM | B3: DESCRIPCION | C3: TOTAL REPUESTOS | D3: Total M/O | E3: TOTAL LUBRICANTES | F3: SUBTOTAL
A4: 1 | B4: BOMBA DE COMBUSTIBLE ALTA PRESION | C4: =G4*1.1 -> 1172.952 | D4: 264 | F4: =C4+D4+E4 -> 1436.952 | G4: 1066.32 | H4: 72.6 | J4: 0.15
A5: 2 | B5: BOMBA AGUA | C5: =G5*1.1 -> 237.765 | D5: 165 | E5: 35.44 | F5: =C5+D5+E5 -> 438.205 | G5: 216.15 | H5: 57.75
A6: 3 | B6: BOMBA DIRECCION HIDRAULICA | C6: =G6*1.1 -> 300.465 | D6: 132 | E6: 17.42 | F6: =C6+D6+E6 -> 449.885 | G6: 273.15 | H6: 67.65
A7: 4 | B7: AMORTIGUADORES DELANTEROS | C7: =G7*1.1 -> 187.396 | D7: 49.5 | F7: =C7+D7+E7 -> 236.896 | G7: 170.36 | H7: 79.2
A8: 5 | B8: AMORTIGUADORES POSTERIORES | C8: =G8*1.1 -> 125.411 | D8: 49.5 | F8: =C8+D8+E8 -> 174.911 | G8: 114.01 | H8: 56.1
A9: 6 | B9: DISCO Y PLATO EMBRAGUE | C9: 350 | D9: 165 | F9: =C10+C9+D9+C11 -> 575
A10: 7 | B10: RODAMIENTO EMBRAGUE | C10: 50
A11: 8 | B11: RODAMIENTO VOLANTE | C11: 10
A12: 9 | B12: RODAMIENTOS PUNTAS DE EJE DELANTEROS (4) | C12: =G12*1.1 -> 89.617 | D12: 99 | F12: =C12+D12+E12 -> 188.617 | G12: 81.47 | H12: 61.05
A13: 10 | B13: DISCOS DE FRENO DELANTEROS | C13: =G13*1.1 -> 141.669 | D13: 49.5 | F13: =C13+D13+E13 -> 191.169 | G13: 128.79 | H13: 16.5
A14: 11 | B14: DISCOS DE FRENO POSTERIORES | C14: =G14*1.1 -> 103.532 | D14: 49.5 | F14: =C14+D14+E14 -> 153.032 | G14: 94.12 | H14: 16.5
A15: 12 | B15: BUJES DEL COLGANTE DEL PAQUETE POSTERIOR (8) | C15: 30 | D15: 82.5 | F15: =C15+D15+E15 -> 112.5 | G15: 189.85 | H15: 41.25
A16: 13 | B16: PAQUETE POSTERIOR | C16: 230.24 | D16: 115.5 | F16: =C16+D16+E16 -> 345.74
A17: 14 | B17: EJE CARDAN COMPLETO | C17: 385.5 | D17: 66 | F17: =C17+D17+E17 -> 451.5 | G17: 35 | H17: 66
A18: 15 | B18: BOMBA DE FRENO | C18: =G18*1.1 -> 199.496 | D18: 165 | E18: 15 | F18: =C18+D18+E18 -> 379.496 | G18: 181.36 | H18: 41.25
A19: 16 | B19: BOMBA DE EMBRAGUE (PRINCIPAL) | C19: 75 | D19: 66 | E19: 15 | F19: =C19+D19+E19 -> 156 | G19: 58.05 | H19: 61.05
A20: 17 | B20: INYECTORES | C20: =G20*1.1 -> 352.781 | D20: 49.5 | F20: =C20+D20+E20 -> 402.281 | G20: 320.71 | H20: 41.25
A21: 18 | B21: CREMALLERA DE DIRECCION | C21: =G21*1.1 -> 599.126 | D21: 132 | E21: 17.42 | F21: =C21+D21+E21 -> 748.546 | G21: 544.66 | H21: 74.25 | I21: 14.85
A22: 19 | B22: TERMINJAL DE LA DIRECCIÓN RH | C22: 70 | D22: 66 | F22: =+C22+D22 -> 136
A23: 20 | B23: TERMINJAL DE LA DIRECCIÓN LH | C23: 70 | D23: 66 | F23: =+C23+D23 -> 136
A24: 21 | B24: MESAS SUPERIORES | C24: 190.41 | D24: 66 | F24: 256.41
A25: 22 | B25: MESAS INFERIORES | C25: 394.61 | D25: 66 | F25: 460.61
A26: 23 | B26: COMPRESOR A/C | C26: =G26*1.1 -> 454.564 | D26: 99 | F26: =C26+D26+E26 -> 553.564 | G26: 413.24 | H26: 49.5
A27: 24 | B27: BANDA DE SERVICIO | C27: =G27*1.1 -> 37.686 | D27: 16.5 | F27: =C27+D27+E27 -> 54.186 | G27: 34.26 | H27: 14.85
A28: 25 | B28: PAQUETES DE RESORTES POSTERIORES | C28: =G28*1.1 -> 208.835 | D28: 132 | F28: =C28+D28+E28 -> 340.835 | G28: 189.85 | H28: 33
A29: 26 | B29: SENSOR TPMS | C29: 62 | D29: 33 | F29: =C29+D29+E29 -> 95 | G29: 52.84 | H29: 26.4
A30: 27 | B30: PLUMAS LH(LIMPIAPRABRISAS) | C30: 81.99 | D30: 7.26 | F30: 89.25
A31: 28 | B31: PLUMAS RH(LIMPIAPRABRISAS)
A32: 29 | B32: PASTILLAS DE FRENO DEL | C32: 76.09 | D32: 42.5 | F32: =+D32+C32 -> 118.59
A33: 30 | B33: PASTILLAS DE FRENO POST. | C33: 55.85 | D33: 42.5 | F33: =+C33+D33 -> 98.35
A34: 31 | B34: FOCOS 1 CONTACTO | C34: 1.25 | D34: 6.6 | F34: =SUM(C34:E34) -> 7.85 | G34: 12 | H34: 6.6
A35: 32 | B35: FOCOS 2 CONTACTOS | C35: 1.3 | D35: 6.6 | F35: =SUM(C35:E35) -> 7.9
A36: 33 | B36: FOCOS HALÓGENO | C36: 12 | D36: 6.6 | F36: =SUM(C36:E36) -> 18.6
A37: 34 | B37: BATERIA | C37: 180 | D37: 10 | F37: =C37+D37+E37 -> 190
A38: 35 | B38: ENLLANTAJE C/U | D38: 6.5 | F38: =C38+D38+E38 -> 6.5
A39: 36 | B39: PARCHE NEUMÁTICO C/U | D39: 15 | F39: =C39+D39+E39 -> 15
A40: 37 | B40: VIVOTEK GRABADOR MOBILE | C40: =1944.75*1.4 -> 2722.65 | D40: 33 | F40: =C40+D40+E40 -> 2755.65
...
