Workbook

Sheet W7 DIESEL 120K
A1: WINGLE 7 DIESEL | B1: INTERMEDIOS | C1: 5000 | D1: 10000 | E1: 20000 | F1: 30000 | G1: 40000 | H1: 50000 | I1: 60000 | J1: 70000 | K1: 80000 | L1: 90000 | M1: 100000 | N1: 110000 | O1: 120000 | R1: CANTIDAD MANT. INTERMEDIOS | U1: INTERMEDIOS
A2: ACEITE MOTOR | B2: =$R$2*U2 -> 245.88 | C2: 40.98 | D2: 40.98 | E2: 40.98 | F2: 40.98 | G2: 40.98 | H2: 40.98 | I2: 40.98 | J2: 40.98 | R2: 6 | U2: =40.98 -> 40.98
A3: FILTRO DE ACEITE | B3: =$R$2*U3 -> 36.06 | C3: 6.01 | D3: 6.01 | E3: 6.01 | F3: 6.01 | G3: 6.01 | H3: 6.01 | I3: 6.01 | J3: 6.01 | U3: =6.01 -> 6.01
A4: FILTROS DE COMBUSTIBLE | B4: =$R$2*U4 -> 39 | C4: 6.5 | D4: 6.5 | E4: 6.5 | F4: 6.5 | G4: 6.5 | H4: 6.5 | I4: 6.5 | J4: 6.5 | U4: =6.5 -> 6.5
A5: FILTRO TRAMPA DE AGUA/COMB | B5: =$R$2*U5 -> 105.3 | C5: 17.55 | D5: 17.55 | E5: 17.55 | F5: 17.55 | G5: 17.55 | H5: 17.55 | I5: 17.55 | J5: 17.55 | U5: =17.55 -> 17.55
A6: FILTRO DE AIRE | B6: =$R$2*U6 -> 0 | D6: 10.45 | E6: 10.45 | F6: 10.45 | G6: 10.45 | H6: 10.45 | I6: 10.45 | J6: 10.45
A7: FILTRO DE CABINA A/C | B7: =$R$2*U7 -> 0 | D7: 7.69 | E7: 7.69 | F7: 7.69 | G7: 7.69 | H7: 7.69 | I7: 7.69 | J7: 7.69
A8: PASTILLAS DE FRENO DEL | B8: =$R$2*U8 -> 0 | D8: 26.87 | F8: 26.87 | H8: 26.87 | J8: 26.87
A9: PASTILLAS DE FRENOS POST | B9: =$R$2*U9 -> 0 | D9: 27 | F9: 27 | H9: 27 | J9: 27
A10: LIQUIDO INYECTORES | B10: =$R$2*U10 -> 0 | E10: 6.5 | G10: 6.5 | I10: 6.5
A11: LIMPIADOR DE FRENOS | B11: =$R$2*U11 -> 0 | D11: 5 | E11: 5 | F11: 5 | G11: 5 | H11: 5 | I11: 5 | J11: 5
A12: LIMPIADOR DE ADMISION | B12: =$R$2*U12 -> 0 | D12: 5.4 | E12: 5.4 | F12: 5.4 | G12: 5.4 | H12: 5.4 | I12: 5.4 | J12: 5.4
A13: REFRIGERANTE | B13: =$R$2*U13 -> 0 | G13: 15
A14: DISTRIBUCION | B14: =$R$2*U14 -> 0
A15: ACEITE DE CAJA | B15: =$R$2*U15 -> 0 | C15: 31.56 | H15: 31.56
A16: ACEITE DIFERENCIAL/TRANSFER | B16: =$R$2*U16 -> 0 | C16: 22.5 | H16: 22.5
A17: SUMINISTROS | B17: =$R$2*U17 -> 21 | C17: 3.5 | D17: 3.5 | E17: 3.5 | F17: 3.5 | G17: 3.5 | H17: 3.5 | I17: 3.5 | J17: 3.5 | U17: =3.5 -> 3.5
A18: ACEITE DIRECCION HIDRAULICA | B18: =$R$2*U18 -> 0 | F18: 7.33 | I18: 7.33
A19: LIQUIDO DE FRENOS | B19: =R19*U19 -> 0 | C19: 0 | D19: 0 | E19: 12 | F19: 0 | G19: 12 | H19: 0 | I19: 12 | J19: 0 | U19: 0
A20: TOTAL REPUESTOS | B20: =B3+B4+B5+B6+B8+B9+B10+B11+B12+B14+B17+B7 -> 201.36 | C20: =C3+C4+C5+C6+C8+C9+C10+C11+C12+C14+C17+C7 -> 33.56 | D20: =D3+D4+D5+D6+D8+D9+D10+D11+D12+D14+D17+D7 -> 115.97 | E20: =E3+E4+E5+E6+E8+E9+E10+E11+E12+E14+E17+E7 -> 68.6 | F20: =F3+F4+F5+F6+F8+F9+F10+F11+F12+F14+F17+F7 -> 115.97 | G20: =G3+G4+G5+G6+G8+G9+G10+G11+G12+G14+G17+G7 -> 68.6 | H20: =H3+H4+H5+H6+H8+H9+H10+H11+H12+H14+H17+H7 -> 115.97 | I20: =I3+I4+I5+I6+I8+I9+I10+I11+I12+I14+I17+I7 -> 68.6 | J20: =J3+J4+J5+J6+J8+J9+J10+J11+J12+J14+J17+J7 -> 115.97 | P20: =SUM(B20:O20) -> 904.6 | U20: =U3+U4+U5+U6+U8+U9+U10+U11+U12+U14+U17+U7 -> 33.56
A21: TOTAL MANO DE OBRA | B21: =R2*U21 -> 88.68 | C21: 19.4 | D21: 157 | E21: 181.69 | F21: 175.34 | G21: 213.44 | H21: 169.34 | I21: 196.51 | J21: 148.18 | P21: =SUM(B21:O21) -> 1349.58 | U21: =14.78 -> 14.78
A22: ALINEACION | B22: 0 | C22: 0 | D22: 17.16 | E22: 17.16 | F22: 17.16 | G22: 17.16 | H22: 17.16 | I22: 17.16 | J22: 17.16 | U22: 0
A23: BALANCEO | D23: 15.84 | E23: 15.84 | F23: 15.84 | G23: 15.84 | H23: 15.84 | I23: 15.84 | J23: 15.84
A24: LIMPIEZA DE INYECTORES | B24: 0 | C24: 0 | D24: 0 | E24: 16.5 | F24: 0 | G24: 16.5 | H24: 0 | I24: 16.5 | J24: 0 | U24: 0
A25: TOTAL M/O | B25: =SUM(B21:B24) -> 88.68 | F25: =SUM(F21:F24) -> 208.34 | G25: =SUM(G21:G24) -> 262.94 | H25: =SUM(H21:H24) -> 202.34 | I25: =SUM(I21:I24) -> 246.01 | J25: =SUM(J21:J24) -> 181.18 | U25: =SUM(U21:U24) -> 14.78
A26: TOTAL | B26: =+B20+B25 -> 290.04 | F26: =+F20+F25 -> 324.31 | G26: =+G20+G25 -> 331.54 | H26: =+H20+H25 -> 318.31 | I26: =+I20+I25 -> 314.61 | J26: =+J20+J25 -> 297.15 | U26: =+U20+U25 -> 48.34
A27: *LUBRICANTES | B27: =B2+B13+B15+B16+B18+B19 -> 245.88 | C27: =C2+C13+C15+C16+C18+C19 -> 95.04 | D27: =D2+D13+D15+D16+D18+D19 -> 40.98 | E27: =E2+E13+E15+E16+E18+E19 -> 52.98 | F27: =F2+F13+F15+F16+F18+F19 -> 48.31 | G27: =G2+G13+G15+G16+G18+G19 -> 67.98 | H27: =H2+H13+H15+H16+H18+H19 -> 95.04 | I27: =I2+I13+I15+I16+I18+I19 -> 60.31 | J27: =J2+J13+J15+J16+J18+J19 -> 40.98 | P27: =SUM(B27:O27) -> 747.5 | Q27: 30% MANT. PREV. | U27: =U2+U13+U15+U16+U18+U19 -> 40.98
B28: =B20+B21+B27 -> 535.92 | C28: =C20+C21+C27 -> 148 | D28: =D20+D21+D27 -> 313.95 | E28: =E20+E21+E27 -> 303.27 | F28: =F20+F21+F27 -> 339.62 | G28: =G20+G21+G27 -> 350.02 | H28: =H20+H21+H27 -> 380.35 | I28: =I20+I21+I27 -> 325.42 | ... O28: =O20+O21+O27 -> 0 | P28: =SUM(P20:P27) -> 3001.68 | Q28: =P28*0.3 -> 900.504
J29: =SUM(B28:J28) -> 3001.68 | O29: =SUM(B28:O28) -> 3001.68 | P29: TOTAL
A30: WINGLE 7 PLAN DE MANTENIMIENTO | P30: =SUM(P28:Q28) -> 3902.184
A31: MOTORES DIESEL | B31: INTERMEDIO | C31: 5000 | D31: 10000 | E31: 20000 | F31: 30000 | G31: 40000 | H31: 50000 | I31: 60000 | J31: 70000 | K31: 80000 | L31: 90000 | M31: 100000 | N31: 110000 | O31: 120000
A32: ACEITE MOTOR | B32: X | C32: X | D32: X | E32: X | F32: X | G32: X | H32: X | I32: X | J32: X | K32: X | L32: X | M32: X | N32: X | O32: X
A33: FILTRO DE ACEITE | B33: X | C33: X | D33: X | E33: X | F33: X | G33: X | H33: X | I33: X | J33: X | K33: X | L33: X | M33: X | N33: X | O33: X
A34: FILTROS DE COMBUSTIBLE | B34: X | C34: X | D34: X | E34: X | F34: X | G34: X | H34: X | I34: X | J34: X | K34: X | L34: X | M34: X | N34: X | O34: X
A35: FILTRO DE AIRE | D35: X | E35: X | F35: X | G35: X | H35: X | I35: X | J35: X | K35: X | L35: X | M35: X | N35: X | O35: X
A36: PASTILLAS DE FRENO | D36: X | F36: X | H36: X | J36: X | L36: X | N36: X
A37: LIQUIDO INYECTORES | E37: X | G37: X | I37: X | K37: X | M37: X | O37: X
A38: LIMPIADOR DE FRENOS | D38: X | E38: X | F38: X | G38: X | H38: X | I38: X | J38: X | K38: X | L38: X | M38: X | N38: X | O38: X
A39: LIMPIADOR DE ADMISION | D39: X | E39: X | F39: X | G39: X | H39: X | I39: X | J39: X | K39: X | L39: X | M39: X | N39: X | O39: X
A40: REFRIGERANTE | G40: X | K40: X | O40: X
...

Sheet DETALLADO MANT 4X4
A1: PLAN DE MANTENIMIENTO PREVENTIVO KYC F3 4X4
A2: KYC F3 | B2: INTERMEDIOS | C2: 5000 | D2: 10000 | E2: 15000 | F2: 20000 | G2: 25000 | H2: 30000 | I2: 35000 | J2: 40000 | K2: 45000 | L2: 50000 | M2: 55000 | N2: 60000 | O2: 65000 | P2: 70000 | Q2: 75000 | R2: 80000 | S2: 85000 | T2: 90000 | U2: 95000 | V2: 100000 | W2: 105000 | X2: 110000 | Y2: 115000 | Z2: 120000
A3: ACEITE MOTOR (10W40) 6lt | B3: ='W7 DIESEL 120K'!U2 -> 40.98 | C3: 43.8 | D3: 43.8 | E3: 43.8 | F3: 43.8 | G3: 43.8 | H3: 43.8 | I3: 43.8 | J3: 43.8 | K3: 43.8 | L3: 43.8 | M3: 43.8 | N3: 43.8 | O3: 43.8 | P3: 43.8 | Q3: 43.8 | R3: 43.8 | S3: 43.8 | T3: 43.8 | U3: 43.8 | V3: 43.8 | W3: 43.8 | X3: 43.8 | Y3: 43.8 | Z3: 43.8
A4: ACEITE DE CAJA (75W90) 3lt | B4: ='W7 DIESEL 120K'!#REF! -> #REF! | C4: 25.65 | L4: 25.65 | V4: 25.65
A5: ACEITE DIFERENCIAL DELANTERO (80W90) 3lt | B5: ='W7 DIESEL 120K'!#REF! -> #REF! | C5: 24.18 | L5: 24.18 | V5: 24.18
A6: ACEITE DIFERENCIAL POSTERIOR (80W90) 3lt | C6: 24.18 | L6: 24.18 | V6: 24.18
A7: ACEITE TRANSFER (ATF3-DEXRON3) 3 lt | L7: 23.76 | V7: 23.76
A8: REFRIGERANTE 8lt | L8: 35.44 | V8: 35.44
A9: LIQUIDO DE FRENOS | B9: ='W7 DIESEL 120K'!U3 -> 6.01 | H9: 17.22 | N9: 17.22 | T9: 17.22 | Z9: 17.22
A10: TOTAL LUBRICANTES | C10: =SUM(C3:C9) -> 117.81 | D10: =SUM(D3:D9) -> 43.8 | E10: =SUM(E3:E9) -> 43.8 | F10: =SUM(F3:F9) -> 43.8 | G10: =SUM(G3:G9) -> 43.8 | H10: =SUM(H3:H9) -> 61.02 | I10: =SUM(I3:I9) -> 43.8 | J10: =SUM(J3:J9) -> 43.8 | ... Z10: =SUM(Z3:Z9) -> 61.02 | AA10: =SUM(C10:Z10) -> 1460.51
A11: FILTRO DE ACEITE | B11: ='W7 DIESEL 120K'!U3 -> 6.01 | C11: 8.31 | D11: 8.31 | E11: 8.31 | F11: 8.31 | G11: 8.31 | H11: 8.31 | I11: 8.31 | J11: 8.31 | K11: 8.31 | L11: 8.31 | M11: 8.31 | N11: 8.31 | O11: 8.31 | P11: 8.31 | Q11: 8.31 | R11: 8.31 | S11: 8.31 | T11: 8.31 | U11: 8.31 | V11: 8.31 | W11: 8.31 | X11: 8.31 | Y11: 8.31 | Z11: 8.31
A12: FILTROS DE COMBUSTIBLE | B12: ='W7 DIESEL 120K'!U4 -> 6.5 | C12: 13.39 | D12: 13.39 | E12: 13.39 | F12: 13.39 | G12: 13.39 | H12: 13.39 | I12: 13.39 | J12: 13.39 | K12: 13.39 | L12: 13.39 | M12: 13.39 | N12: 13.39 | O12: 13.39 | P12: 13.39 | Q12: 13.39 | R12: 13.39 | S12: 13.39 | T12: 13.39 | U12: 13.39 | V12: 13.39 | W12: 13.39 | X12: 13.39 | Y12: 13.39 | Z12: 13.39
A13: FILTRO DE AIRE | B13: ='W7 DIESEL 120K'!U6 -> 0 | D13: 15.75 | F13: 15.75 | H13: 15.75 | J13: 15.75 | L13: 15.75 | N13: 15.75 | P13: 15.75 | R13: 15.75 | T13: 15.75 | V13: 15.75 | X13: 15.75 | Z13: 15.75
A14: PASTILLAS DE FRENO DEL | B14: ='W7 DIESEL 120K'!U8 -> 0 | D14: 30.79 | F14: 30.79 | H14: 30.79 | J14: 30.79 | L14: 30.79 | N14: 30.79 | P14: 30.79 | R14: 30.79 | T14: 30.79 | V14: 30.79 | X14: 30.79 | Z14: 30.79
A15: LIQUIDO INYECTORES | B15: ='W7 DIESEL 120K'!U10 -> 0 | D15: 8.18 | F15: 8.18 | H15: 8.18 | J15: 8.18 | L15: 8.18 | N15: 8.18 | P15: 8.18 | R15: 8.18 | T15: 8.18 | V15: 8.18 | X15: 8.18 | Z15: 8.18
A16: LIMPIADOR DE FRENOS | B16: ='W7 DIESEL 120K'!U11 -> 0 | D16: 5.6 | F16: 5.6 | H16: 5.6 | J16: 5.6 | L16: 5.6 | N16: 5.6 | P16: 5.6 | R16: 5.6 | T16: 5.6 | V16: 5.6 | X16: 5.6 | Z16: 5.6
A17: LIMPIADOR DE ADMISION | B17: ='W7 DIESEL 120K'!U12 -> 0 | D17: 6.02 | F17: 6.02 | H17: 6.02 | J17: 6.02 | L17: 6.02 | N17: 6.02 | P17: 6.02 | R17: 6.02 | T17: 6.02 | V17: 6.02 | X17: 6.02 | Z17: 6.02
A18: REFRIGERANTE | B18: ='W7 DIESEL 120K'!U13 -> 0
A19: BOMBA DE AGUA | B19: ='W7 DIESEL 120K'!U14 -> 0 | V19: 151.24
A20: SUMINISTROS | B20: ='W7 DIESEL 120K'!U17 -> 3.5 | C20: 5 | D20: 5 | E20: 5 | F20: 5 | G20: 5 | H20: 5 | I20: 5 | J20: 5 | K20: 5 | L20: 5 | M20: 5 | N20: 5 | O20: 5 | P20: 5 | Q20: 5 | R20: 5 | S20: 5 | T20: 5 | U20: 5 | V20: 5 | W20: 5 | X20: 5 | Y20: 5 | Z20: 5
A21: TERMOSTATO | L21: 10 | V21: 10
A22: BANDA DE SERVICIO/ACCESORIOS | P22: 33.5
A23: TOTAL REPUESTOS | B23: =B11+B12+#REF!+B13+B14+#REF!+B15+B16+B17+B19+B20+#REF! -> #REF! | C23: =SUM(C11:C22) -> 26.7 | D23: =SUM(D11:D22) -> 93.04 | E23: =SUM(E11:E22) -> 26.7 | F23: =SUM(F11:F22) -> 93.04 | G23: =SUM(G11:G22) -> 26.7 | H23: =SUM(H11:H22) -> 93.04 | I23: =SUM(I11:I22) -> 26.7 | J23: =SUM(J11:J22) -> 93.04 | ... Z23: =SUM(Z11:Z22) -> 93.04 | AA23: =SUM(C23:Z23) -> 1641.62
A24: MANO DE OBRA POR KILOMETRAJE | C24: 19.4 | D24: 107.5 | E24: 14.11 | F24: 132.19 | G24: 14.11 | H24: 125.84 | I24: 14.11 | J24: 163.94 | K24: 14.11 | L24: 119.84 | M24: 14.11 | N24: 147.01 | O24: 14.11 | P24: 98.68 | Q24: 14.11 | R24: 132.19 | S24: 14.11 | T24: 129.37 | U24: 14.11 | V24: 264.49 | W24: 14.11 | X24: 107.5 | Y24: 14.11 | Z24: 132.19
A25: ALINEACION | B25: 0 | D25: 17.16 | F25: 17.16 | H25: 17.16 | J25: 17.16 | L25: 17.16 | N25: 17.16 | P25: 17.16 | R25: 17.16 | T25: 17.16 | V25: 17.16 | X25: 17.16 | Z25: 17.16
A26: BALANCEO | D26: 15.84 | F26: 15.84 | H26: 15.84 | J26: 15.84 | L26: 15.84 | N26: 15.84 | P26: 15.84 | R26: 15.84 | T26: 15.84 | V26: 15.84 | X26: 15.84 | Z26: 15.84
A27: EMPACAR ZAPATAS | J27: 30 | R27: 30 | Z27: 30
A28: MANTENIMIENTO Y CALIBRACIÓN DE INYECTORES | O28: 850
A29: LIMPIEZA DE INYECTORES | B29: 0 | D29: 16.5 | F29: 16.5 | H29: 16.5 | J29: 16.5 | L29: 16.5 | N29: 16.5 | P29: 16.5 | R29: 16.5 | T29: 16.5 | V29: 16.5 | X29: 16.5 | Z29: 16.5
A30: TOTAL MANO DE OBRA | B30: ='W7 DIESEL 120K'!U21 -> 14.78 | C30: =SUM(C24:C29) -> 19.4 | D30: =SUM(D24:D29) -> 157 | E30: =SUM(E24:E29) -> 14.11 | F30: =SUM(F24:F29) -> 181.69 | G30: =SUM(G24:G29) -> 14.11 | H30: =SUM(H24:H29) -> 175.34 | I30: =SUM(I24:I29) -> 14.11 | J30: =SUM(J24:J29) -> 243.44 | ... Z30: =SUM(Z24:Z29) -> 211.69 | AA30: =SUM(C30:Z30) -> 3369.35
A31: TOTAL COSTO MANTENIMIENTO POR KILOMETRAJE | C31: =C10+C23+C30 -> 163.91 | D31: =D10+D23+D30 -> 293.84 | E31: =E10+E23+E30 -> 84.61 | F31: =F10+F23+F30 -> 318.53 | G31: =G10+G23+G30 -> 84.61 | H31: =H10+H23+H30 -> 329.4 | I31: =I10+I23+I30 -> 84.61 | J31: =J10+J23+J30 -> 380.28 | ... Z31: =Z10+Z23+Z30 -> 365.75

Sheet CORRECTIVO
A1: MARCA | B1: GWM
A2: MODELO | B2: WINGLE 7 DIESEL | C2: MANTENIMIENTOS CORRECTIVOS
A3: ITEM | B3: DESCRIPCION | C3: CANTIDAD | D3: VALOR UNI | E3: TOTAL REPUESTOS | F3: MANO DE OBRA | H3: OBSERVACION DE TRABAJOS ADICIONALES | I3: Total M/O | J3: TOTAL LUBRICANTES | K3: SUBTOTAL | L3: IVA | M3: TOTAL
A4: 1 | B4: BOMBA DE COMBUSTIBLE ALTA PRESION | C4: 1 | D4: 1170 | E4: =D4*C4 -> 1170 | F4: Cambio bomba de combustible | G4: 72.6 | H4: contemplar desmontaje de banda de distribución mas 75.00 | I4: 147.6 | K4: =+E4+I4+J4 -> 1317.6 | L4: =+K4*0.12 -> 158.112 | M4: =+K4+L4 -> 1475.712
A5: 2 | B5: BOMBA AGUA | C5: 1 | D5: 99.09 | E5: 126.34 | F5: Cambio bomba de agua | G5: 57.75 | H5: contemplar desmontaje de banda de distribución mas 75.00 | I5: 132.75 | K5: =+E5+I5+J5 -> 259.09 | L5: =+K5*0.12 -> 31.0908 | M5: =+K5+L5 -> 290.1808
A6: 3 | B6: BOMBA DIRECCION HIDRAULICA | C6: 1 | D6: 187.49 | E6: =D6*C6 -> 187.49 | F6: Cambio bomba de dirección Hidráulica | G6: 49.5 | H6: mas dranado del sistema 33.00 | I6: 82.5 | J6: 15 | K6: =+E6+I6+J6 -> 284.99 | L6: =+K6*0.12 -> 34.1988 | M6: =+K6+L6 -> 319.1888
A7: 4 | B7: AMORTIGUADORES DELANTEROS | C7: 2 | D7: 78.76 | E7: =D7*C7 -> 157.52 | F7: Cambio amortiguadores delanteros | G7: 28.5 | I7: 28.5 | K7: =+E7+I7+J7 -> 186.02 | L7: =+K7*0.12 -> 22.3224 | M7: =+K7+L7 -> 208.3424
A8: 5 | B8: AMORTIGUADORES POSTERIORES | C8: 2 | D8: 58 | E8: 81.42 | F8: Cambio amortiguadores posteriores | G8: 28.5 | I8: 28.5 | K8: =+E8+I8+J8 -> 109.92 | L8: =+K8*0.12 -> 13.1904 | M8: =+K8+L8 -> 123.1104
A9: 6 | B9: KIT EMBRAGUE COMPLETO | C9: 1 | D9: =23.31+68+113.13 -> 204.44 | E9: 271.51 | F9: Cambio Kit de embrague | G9: 123.75 | I9: 123.75 | K9: =+E9+I9+J9 -> 395.26 | L9: =+K9*0.12 -> 47.4312 | M9: =+K9+L9 -> 442.6912
A10: 7 | B10: RODAMIENTOS PUNTAS DE EJE DELANTEROS (4) | C10: 4 | D10: 12.22 | E10: 50.66 | F10: Cambio y engrase de rodamientos de puntas de eje delanteras | G10: 61.05 | I10: 61.05 | K10: =+E10+I10+J10 -> 111.71 | L10: =+K10*0.12 -> 13.4052 | M10: =+K10+L10 -> 125.1152
A11: 8 | B11: RETENEDORES EJE DELANTEROS (2) | C11: 2 | D11: 3.88 | E11: =D11*C11 -> 7.76 | F11: Cambio retenedores puntas de eje delanteras | G11: 82 | I11: 82 | K11: =+E11+I11+J11 -> 89.76 | L11: =+K11*0.12 -> 10.7712 | M11: =+K11+L11 -> 100.5312
A12: 9 | B12: DISCOS DE FRENO DELANTEROS | C12: 2 | D12: 59.59 | E12: =D12*C12 -> 119.18 | F12: Cambio discos de freno delanteros | G12: 30 | I12: 30 | K12: =+E12+I12+J12 -> 149.18 | L12: =+K12*0.12 -> 17.9016 | M12: =+K12+L12 -> 167.0816
A13: 10 | B13: DISCOS DE FRENO POSTERIORES | C13: 2 | D13: 70.74 | E13: =D13*C13 -> 141.48 | F13: Cambio de discos de freno | G13: 30 | I13: 30 | K13: =+E13+I13+J13 -> 171.48 | L13: =+K13*0.12 -> 20.5776 | M13: =+K13+L13 -> 192.0576
A14: 11 | B14: BUJES DE PAQUETES DE RESORTES | C14: 4 | D14: 10 | E14: 38.96 | F14: Cambio bujes de paquetes | G14: 82.5 | I14: 82.5 | K14: =+E14+I14+J14 -> 121.46 | L14: =+K14*0.12 -> 14.5752 | M14: =+K14+L14 -> 136.0352
A15: 12 | B15: CRUCETAS DE CARDAN | C15: 1 | D15: 12.96 | E15: =D15*C15 -> 12.96 | F15: Cambio crucetas | G15: 49.5 | H15: mas desmontaje de cardan 33 | I15: 82.5 | K15: =+E15+I15+J15 -> 95.46 | L15: =+K15*0.12 -> 11.4552 | M15: =+K15+L15 -> 106.9152
A16: 13 | B16: BOMBA DE FRENO | C16: 1 | D16: 201.37 | E16: 188.24 | F16: Cambio bomba de freno | G16: 61.05 | H16: mas purgado de liquido 25 | I16: 86.05 | K16: =+E16+I16+J16 -> 274.29 | L16: =+K16*0.12 -> 32.9148 | M16: =+K16+L16 -> 307.2048
A17: 14 | B17: BOMBA DE EMBRAGUE | C17: 1 | D17: 30.44 | E17: =D17*C17 -> 30.44 | F17: Cambio bomba de embrague | G17: 25.05 | H17: mas purgado de liquido 25 | I17: 50.05 | K17: =+E17+I17+J17 -> 80.49 | L17: =+K17*0.12 -> 9.6588 | M17: =+K17+L17 -> 90.1488
A18: 15 | B18: INYECTORES | C18: 4 | D18: 389.39 | E18: =D18*C18 -> 1557.56 | F18: Cambio y diagnóstico de inyectores | G18: 41.25 | I18: 41.25 | K18: =+E18+I18+J18 -> 1598.81 | L18: =+K18*0.12 -> 191.8572 | M18: =+K18+L18 -> 1790.6672
A19: 16 | B19: TURBO GEOMETRIA VARIABLE | C19: 1 | D19: 1340.14 | E19: =D19*C19 -> 1340.14 | F19: Cambio turbo | G19: 49.5 | H19: mas limpieza de sistema intercooler 50.00 | I19: 99.5 | K19: =+E19+I19+J19 -> 1439.64 | L19: =+K19*0.12 -> 172.7568 | M19: =+K19+L19 -> 1612.3968
A20: 17 | B20: CREMALLERA DE DIRECCION | C20: 1 | D20: 500 | E20: 642.3 | F20: Cambio cremallera de dirección y sangrado sistema | G20: 82.5 | I20: 82.5 | J20: 15 | K20: =+E20+I20+J20 -> 739.8 | L20: =+K20*0.12 -> 88.776 | M20: =+K20+L20 -> 828.576
A21: 18 | B21: ROTULAS SUPERIORES | C21: 2 | D21: 35.68 | E21: =D21*C21 -> 71.36 | F21: Cambio rotulas de suspensión | G21: 33 | H21: mas alineación 18.00 | I21: 51 | K21: =+E21+I21+J21 -> 122.36 | L21: =+K21*0.12 -> 14.6832 | M21: =+K21+L21 -> 137.0432
A22: 19 | B22: ROTULAS INFERIORES | C22: 2 | D22: 35.54 | E22: =D22*C22 -> 71.08 | F22: Cambio rotulas de suspensión | G22: 33 | H22: mas alineación 18.00 | I22: 51 | K22: =+E22+I22+J22 -> 122.08 | L22: =+K22*0.12 -> 14.6496 | M22: =+K22+L22 -> 136.7296
A23: 20 | B23: COMPRESOR A/C | C23: 1 | D23: 390.18 | E23: 352.87 | F23: Cambio compresor de A/C | G23: 49.5 | H23: mas carga de aire 60 | I23: 109.5 | K23: =+E23+I23+J23 -> 462.37 | L23: =+K23*0.12 -> 55.4844 | M23: =+K23+L23 -> 517.8544
A24: 21 | B24: BANDA DE SERVICIO | C24: 1 | D24: 48.27 | E24: 26.6 | F24: Cambio banda de servicio | G24: 14.85 | I24: 14.85 | K24: =+E24+I24+J24 -> 41.45 | L24: =+K24*0.12 -> 4.974 | M24: =+K24+L24 -> 46.424
A25: 22 | B25: RODAMIENTAS DE CAJA DE CAMBIOS | C25: 1 | D25: =35.53+28.1+21.75+4.84+16.97+10.45+16.55+14.43+10.45+18.77 -> 177.84 | E25: 172.6 | F25: Cambio rodamientas de caja | G25: 165 | H25: mas DM caja 75.00 mas lubricantes 48 | I25: 240 | J25: 48 | K25: =+E25+I25+J25 -> 460.6 | L25: =+K25*0.12 -> 55.272 | M25: =+K25+L25 -> 515.872
A26: 23 | B26: SINCRONIZADOS DE CAJA DE CAMBIOS | C26: 1 | D26: =42.99+66.16+26.91+28.13*2 -> 192.32 | E26: 161.59 | F26: Cambio sincronizados de caja | G26: 165 | H26: mas DM caja 75.00 mas lubricantes 48 | I26: 240 | J26: 48 | K26: =+E26+I26+J26 -> 449.59 | L26: =+K26*0.12 -> 53.9508 | M26: =+K26+L26 -> 503.5408
A27: 24 | B27: PAQUETES DE RESORTES POSTERIORES | C27: 2 | D27: 164.59 | E27: 184.34 | F27: Cambio paquetes de resortes posteriores | G27: 66 | I27: 66 | K27: =+E27+I27+J27 -> 250.34 | L27: =+K27*0.12 -> 30.0408 | M27: =+K27+L27 -> 280.3808
B28: SUBTOTAL | E28: =SUM(E4:E27) -> 7164.4 | I28: =SUM(I4:I27) -> 2043.35 | J28: =SUM(J4:J27) -> 126 | K28: =SUM(K4:K27) -> 9333.75 | L28: =SUM(L4:L27) -> 1120.05 | M28: =SUM(M4:M27) -> 10453.8
B29: IVA | E29: =+E28*0.12 -> 859.728 | I29: =+I28*0.12 -> 245.202 | J29: =+J28*0.12 -> 15.12 | K29: =+K28*0.12 -> 1120.05 | L29: =+L28*0.12 -> 134.406 | M29: =+M28*0.12 -> 1254.456
B30: TOTAL | E30: =+E28+E29 -> 8024.128 | I30: =+I28+I29 -> 2288.552 | J30: =+J28+J29 -> 141.12 | K30: =+K28+K29 -> 10453.8 | L30: =+L28+L29 -> 1254.456 | M30: =+M28+M29 -> 11708.256

Sheet TABLA GRAL MO-REP
A1: TABLA COSTOS MANTENIMIENTO PREVENTIVO CAMIONETA WINGLE 7, SEGÚN PLAN MANTENIMIENTO FABRICANTE
A2: CANTIDAD TOTAL DE VEHICULOS | F2: 21
A3: KILOMETRAJE (km) | C3: TOTAL LUBRICANTES | D3: TOTAL REPUESTOS | E3: TOTAL MANO DE OBRA | F3: SUBTOTAL/CAMIONETA
B4: 5000 | C4: ='W7 DIESEL 120K'!C27 -> 95.04 | D4: ='W7 DIESEL 120K'!C20 -> 33.56 | E4: ='W7 DIESEL 120K'!C21 -> 19.4 | F4: =SUM(C4:E4) -> 148
B5: 10000 | C5: ='W7 DIESEL 120K'!D27 -> 40.98 | D5: ='W7 DIESEL 120K'!D20 -> 115.97 | E5: ='W7 DIESEL 120K'!D21 -> 157 | F5: =SUM(C5:E5) -> 313.95
B6: 15000 | C6: 40.98 | D6: 33.56 | E6: 14.11 | F6: =SUM(C6:E6) -> 88.65
B7: 20000 | C7: ='W7 DIESEL 120K'!E27 -> 52.98 | D7: ='W7 DIESEL 120K'!E20 -> 68.6 | E7: ='W7 DIESEL 120K'!E21 -> 181.69 | F7: =SUM(C7:E7) -> 303.27
B8: 25000 | C8: 40.98 | D8: 33.56 | E8: 14.11 | F8: =SUM(C8:E8) -> 88.65
B9: 30000 | C9: ='W7 DIESEL 120K'!F27 -> 48.31 | D9: ='W7 DIESEL 120K'!F20 -> 115.97 | E9: ='W7 DIESEL 120K'!F21 -> 175.34 | F9: =SUM(C9:E9) -> 339.62
B10: 35000 | C10: 40.98 | D10: 33.56 | E10: 14.11 | F10: =SUM(C10:E10) -> 88.65
B11: 40000 | C11: ='W7 DIESEL 120K'!G27 -> 67.98 | D11: ='W7 DIESEL 120K'!G20 -> 68.6 | E11: ='W7 DIESEL 120K'!G21 -> 213.44 | F11: =SUM(C11:E11) -> 350.02
B12: 45000 | C12: 40.98 | D12: 33.56 | E12: 14.11 | F12: =SUM(C12:E12) -> 88.65
B13: 50000 | C13: ='W7 DIESEL 120K'!H27 -> 95.04 | D13: ='W7 DIESEL 120K'!H20 -> 115.97 | E13: ='W7 DIESEL 120K'!H21 -> 169.34 | F13: =SUM(C13:E13) -> 380.35
B14: 55000 | C14: 40.98 | D14: 33.56 | E14: 14.11 | F14: =SUM(C14:E14) -> 88.65
B15: 60000 | C15: ='W7 DIESEL 120K'!I27 -> 60.31 | D15: ='W7 DIESEL 120K'!I20 -> 68.6 | E15: ='W7 DIESEL 120K'!I21 -> 196.51 | F15: =SUM(C15:E15) -> 325.42
B16: 65000 | C16: 40.98 | D16: 33.56 | E16: 14.11 | F16: =SUM(C16:E16) -> 88.65
B17: 70000 | C17: ='W7 DIESEL 120K'!J27 -> 40.98 | D17: ='W7 DIESEL 120K'!J20 -> 115.97 | E17: ='W7 DIESEL 120K'!J21 -> 148.18 | F17: =SUM(C17:E17) -> 305.13
B18: 75000 | C18: 40.98 | D18: 33.56 | E18: 14.11 | F18: =SUM(C18:E18) -> 88.65
B19: 80000 | C19: ='W7 DIESEL 120K'!K27 -> 0 | D19: ='W7 DIESEL 120K'!K20 -> 0 | E19: ='W7 DIESEL 120K'!K21 -> 0 | F19: =SUM(C19:E19) -> 0
B20: 85000 | C20: 40.98 | D20: 33.56 | E20: 14.11 | F20: =SUM(C20:E20) -> 88.65
B21: 90000 | C21: ='W7 DIESEL 120K'!L27 -> 0 | D21: ='W7 DIESEL 120K'!L20 -> 0 | E21: ='W7 DIESEL 120K'!L21 -> 0 | F21: =SUM(C21:E21) -> 0
B22: 95000 | C22: 40.98 | D22: 33.56 | E22: 14.11 | F22: =SUM(C22:E22) -> 88.65
B23: 100000 | C23: ='W7 DIESEL 120K'!M27 -> 0 | D23: ='W7 DIESEL 120K'!M20 -> 0 | E23: ='W7 DIESEL 120K'!M21 -> 0 | F23: =SUM(C23:E23) -> 0
B24: 105000 | C24: 40.98 | D24: 33.56 | E24: 14.11 | F24: =SUM(C24:E24) -> 88.65
B25: 110000 | C25: ='W7 DIESEL 120K'!N27 -> 0 | D25: ='W7 DIESEL 120K'!N20 -> 0 | E25: ='W7 DIESEL 120K'!N21 -> 0 | F25: =SUM(C25:E25) -> 0
B26: 115000 | C26: 40.98 | D26: 33.56 | E26: 14.11 | F26: =SUM(C26:E26) -> 88.65
B27: 120000 | C27: ='W7 DIESEL 120K'!O27 -> 0 | D27: ='W7 DIESEL 120K'!O20 -> 0 | E27: ='W7 DIESEL 120K'!O21 -> 0 | F27: =SUM(C27:E27) -> 0
B28: SUBTOTAL UNITARIO | C28: =SUM(C4:C27) -> 952.4 | D28: =SUM(D4:D27) -> 1072.4 | E28: =SUM(E4:E27) -> 1416.11 | F28: =SUM(F4:F27) -> 3440.91
B29: SUBTOTAL (21 VEHICULOS) | C29: =C28*$F$2 -> 20000.4 | D29: =D28*$F$2 -> 22520.4 | E29: =E28*$F$2 -> 29738.31 | F29: =SUM(C29:E29) -> 72259.11
A30: MANTENIMIENTO CORRECTIVO (30% MANTENIMIENTO PREVENTIVO) | C30: =C29*0.3 -> 6000.12 | D30: =D29*0.3 -> 6756.12 | E30: =E29*0.3 -> 8921.493 | F30: =SUM(C30:E30) -> 21677.733
A31: TOTAL | C31: =C29+C30 -> 26000.52 | D31: =D29+D30 -> 29276.52 | E31: =E29+E30 -> 38659.803 | F31: =SUM(C31:E31) -> 93936.843
B32: IVA | C32: =C31*0.12 -> 3120.0624 | D32: =D31*0.12 -> 3513.1824 | E32: =E31*0.12 -> 4639.1764 | F32: =SUM(C32:E32) -> 11272.421
B33: TOTAL | C33: =SUM(C31:C32) -> 29120.582 | D33: =SUM(D31:D32) -> 32789.702 | E33: =SUM(E31:E32) -> 43298.979 | F33: =SUM(C33:E33) -> 105209.26

Sheet MANT. CORRECTIVOS SOLICITADOS
B1: MANTENIMIENTOS CORRECTIVOS ESTIMADOS
B2: ITEM | C2: CÓDIGO CPC | D2: DESCRIPCIÓN | E2: CANTIDAD | F2: UNIDAD | G2: COSTO | H2: SUBTOTAL (SIN IVA)
B3: 1 | D3: DISCO DE FRENO DELANTERO | E3: 18 | F3: UNIDAD | G3: 59.59 | H3: =E3*G3 -> 1072.62
B4: 2 | D4: DISCOS DE FRENOS POSTERIORES | E4: 18 | F4: UNIDAD | G4: 70.74 | H4: =E4*G4 -> 1273.32
B5: 3 | D5: PLATO DE EMBRAGUE | E5: 9 | F5: UNIDAD | G5: 95 | H5: =E5*G5 -> 855
B6: 4 | D6: DISCO DE EMBRAGUE | E6: 9 | F6: UNIDAD | G6: 135 | H6: =E6*G6 -> 1215
B7: 5 | D7: RODAMIENTO DE EMBRAGUE | E7: 9 | F7: UNIDAD | G7: 27.63 | H7: =E7*G7 -> 248.67
B8: 6 | D8: BANDA DE ACCESORIOS | E8: 9 | F8: UNIDAD | G8: 26.6 | H8: =E8*G8 -> 239.4
B9: 7 | D9: TEMPLADOR DE BANDA | E9: 9 | F9: UNIDAD | G9: 123.23 | H9: =E9*G9 -> 1109.07
B10: 8 | D10: CAMBIO DE BANDA Y TEMPLADOR | E10: 9 | F10: UNIDAD | G10: 72.6 | H10: =E10*G10 -> 653.4
B11: 9 | D11: MANTENIMIENTO DE AIRE ACONDICIONADO (CADA 40000 KILOMETROS) | E11: 27 | F11: UNIDAD | G11: 55 | H11: =E11*G11 -> 1485
B12: 10 | D12: CAMBIO DE DISCOS DE FRENOS DELANTEROS | E12: 9 | F12: UNIDAD | G12: 16.5 | H12: =E12*G12 -> 148.5
B13: 11 | D13: CAMBIO DE DISCOS DE FRENOS POSTERIORES | E13: 9 | F13: UNIDAD | G13: 16.5 | H13: =E13*G13 -> 148.5
B14: 12 | D14: CAMBIO DE KIT DE EMBRAGUE | E14: 9 | F14: UNIDAD | G14: 123.75 | H14: =E14*G14 -> 1113.75
B15: 13 | D15: RECTIFICADA DE DISCOS | E15: 9 | F15: UNIDAD | G15: 17.82 | H15: =E15*G15 -> 160.38
B16: TOTAL (SIN IVA) | H16: =SUM(H3:H15) -> 9722.61

Sheet DETALLADO MANT 4X2
A1: PLAN DE MANTENIMIENTO PREVENTIVO KYC F3 4X2
A2: KYC F3 | B2: INTERMEDIOS | C2: 5000 | D2: 10000 | E2: 15000 | F2: 20000 | G2: 25000 | H2: 30000 | I2: 35000 | J2: 40000 | K2: 45000 | L2: 50000 | M2: 55000 | N2: 60000 | O2: 65000 | P2: 70000 | Q2: 75000 | R2: 80000 | S2: 85000 | T2: 90000 | U2: 95000 | V2: 100000 | W2: 105000 | X2: 110000 | Y2: 115000 | Z2: 120000
A3: ACEITE MOTOR (10W40) 6lt | B3: ='W7 DIESEL 120K'!U2 -> 40.98 | C3: 43.8 | D3: 43.8 | E3: 43.8 | F3: 43.8 | G3: 43.8 | H3: 43.8 | I3: 43.8 | J3: 43.8 | K3: 43.8 | L3: 43.8 | M3: 43.8 | N3: 43.8 | O3: 43.8 | P3: 43.8 | Q3: 43.8 | R3: 43.8 | S3: 43.8 | T3: 43.8 | U3: 43.8 | V3: 43.8 | W3: 43.8 | X3: 43.8 | Y3: 43.8 | Z3: 43.8
A4: ACEITE DE CAJA (75W90) 3lt | B4: ='W7 DIESEL 120K'!#REF! -> #REF! | C4: 25.65 | L4: 25.65 | V4: 25.65
A5: ACEITE DIFERENCIAL DELANTERO (80W90) 3lt | B5: ='W7 DIESEL 120K'!#REF! -> #REF!
A6: ACEITE DIFERENCIAL POSTERIOR (80W90) 3lt | C6: 24.18 | L6: 24.18 | V6: 24.18
A7: ACEITE TRANSFER (ATF3-DEXRON3) 3 lt
A8: REFRIGERANTE 8lt | L8: 35.44 | V8: 35.44
A9: LIQUIDO DE FRENOS | B9: ='W7 DIESEL 120K'!U3 -> 6.01 | H9: 17.22 | N9: 17.22 | T9: 17.22 | Z9: 17.22
A10: TOTAL LUBRICANTES | C10: =SUM(C3:C9) -> 93.63 | D10: =SUM(D3:D9) -> 43.8 | E10: =SUM(E3:E9) -> 43.8 | F10: =SUM(F3:F9) -> 43.8 | G10: =SUM(G3:G9) -> 43.8 | H10: =SUM(H3:H9) -> 61.02 | I10: =SUM(I3:I9) -> 43.8 | J10: =SUM(J3:J9) -> 43.8 | ... Z10: =SUM(Z3:Z9) -> 61.02 | AA10: =SUM(C10:Z10) -> 1340.45
A11: FILTRO DE ACEITE | B11: ='W7 DIESEL 120K'!U3 -> 6.01 | C11: 10.81 | D11: 10.81 | E11: 10.81 | F11: 10.81 | G11: 10.81 | H11: 10.81 | I11: 10.81 | J11: 10.81 | K11: 10.81 | L11: 10.81 | M11: 10.81 | N11: 10.81 | O11: 10.81 | P11: 10.81 | Q11: 10.81 | R11: 10.81 | S11: 10.81 | T11: 10.81 | U11: 10.81 | V11: 10.81 | W11: 10.81 | X11: 10.81 | Y11: 10.81 | Z11: 10.81
A12: FILTRO DE COMBUSTIBLE | B12: ='W7 DIESEL 120K'!U4 -> 6.5 | C12: 15.89 | D12: 15.89 | E12: 15.89 | F12: 15.89 | G12: 15.89 | H12: 15.89 | I12: 15.89 | J12: 15.89 | K12: 15.89 | L12: 15.89 | M12: 15.89 | N12: 15.89 | O12: 15.89 | P12: 15.89 | Q12: 15.89 | R12: 15.89 | S12: 15.89 | T12: 15.89 | U12: 15.89 | V12: 15.89 | W12: 15.89 | X12: 15.89 | Y12: 15.89 | Z12: 15.89
A13: FILTRO DE AIRE | B13: ='W7 DIESEL 120K'!U6 -> 0 | D13: 15.75 | F13: 15.75 | H13: 15.75 | J13: 15.75 | L13: 15.75 | N13: 15.75 | P13: 15.75 | R13: 15.75 | T13: 15.75 | V13: 15.75 | X13: 15.75 | Z13: 15.75
A14: PASTILLAS DE FRENO DEL | B14: ='W7 DIESEL 120K'!U8 -> 0 | D14: 30.79 | F14: 30.79 | H14: 30.79 | J14: 30.79 | L14: 30.79 | N14: 30.79 | P14: 30.79 | R14: 30.79 | T14: 30.79 | V14: 30.79 | X14: 30.79 | Z14: 30.79
A15: LIQUIDO INYECTORES | B15: ='W7 DIESEL 120K'!U10 -> 0 | D15: 8.18 | F15: 8.18 | H15: 8.18 | J15: 8.18 | L15: 8.18 | N15: 8.18 | P15: 8.18 | R15: 8.18 | T15: 8.18 | V15: 8.18 | X15: 8.18 | Z15: 8.18
A16: LIMPIADOR DE FRENOS | B16: ='W7 DIESEL 120K'!U11 -> 0 | D16: 5.6 | F16: 5.6 | H16: 5.6 | J16: 5.6 | L16: 5.6 | N16: 5.6 | P16: 5.6 | R16: 5.6 | T16: 5.6 | V16: 5.6 | X16: 5.6 | Z16: 5.6
A17: LIMPIADOR DE ADMISION | B17: ='W7 DIESEL 120K'!U12 -> 0 | D17: 6.02 | F17: 6.02 | H17: 6.02 | J17: 6.02 | L17: 6.02 | N17: 6.02 | P17: 6.02 | R17: 6.02 | T17: 6.02 | V17: 6.02 | X17: 6.02 | Z17: 6.02
A18: REFRIGERANTE | B18: ='W7 DIESEL 120K'!U13 -> 0
A19: BOMBA DE AGUA | B19: ='W7 DIESEL 120K'!U14 -> 0 | V19: 151.24
A20: TERMOSTATO | L20: 10 | V20: 10
A21: BANDA DE SERVICIO/ACCESORIOS | P21: 33.5
A22: TOTAL REPUESTOS | B22: =B11+B12+#REF!+B13+B14+#REF!+B15+B16+B17+B19+#REF!+#REF! -> #REF! | C22: =SUM(C11:C21) -> 26.7 | D22: =SUM(D11:D21) -> 93.04 | E22: =SUM(E11:E21) -> 26.7 | F22: =SUM(F11:F21) -> 93.04 | G22: =SUM(G11:G21) -> 26.7 | H22: =SUM(H11:H21) -> 93.04 | I22: =SUM(I11:I21) -> 26.7 | J22: =SUM(J11:J21) -> 93.04 | ... Z22: =SUM(Z11:Z21) -> 93.04 | AA22: =SUM(C22:Z22) -> 1641.62
A23: MANO DE OBRA POR KILOMETRAJE | C23: 19.4 | D23: 107.5 | E23: 14.11 | F23: 132.19 | G23: 14.11 | H23: 125.84 | I23: 14.11 | J23: 163.94 | K23: 14.11 | L23: 119.84 | M23: 14.11 | N23: 147.01 | O23: 14.11 | P23: 98.68 | Q23: 14.11 | R23: 132.19 | S23: 14.11 | T23: 129.37 | U23: 14.11 | V23: 264.49 | W23: 14.11 | X23: 107.5 | Y23: 14.11 | Z23: 132.19
A24: ALINEACION | B24: 0 | D24: 17.16 | F24: 17.16 | H24: 17.16 | J24: 17.16 | L24: 17.16 | N24: 17.16 | P24: 17.16 | R24: 17.16 | T24: 17.16 | V24: 17.16 | X24: 17.16 | Z24: 17.16
A25: BALANCEO | D25: 15.84 | F25: 15.84 | H25: 15.84 | J25: 15.84 | L25: 15.84 | N25: 15.84 | P25: 15.84 | R25: 15.84 | T25: 15.84 | V25: 15.84 | X25: 15.84 | Z25: 15.84
A26: EMPACAR ZAPATAS | J26: 30 | R26: 30 | Z26: 30
A27: MANTENIMIENTO Y CALIBRACIÓN DE INYECTORES | O27: 850
A28: LIMPIEZA DE INYECTORES | B28: 0 | D28: 16.5 | F28: 16.5 | H28: 16.5 | J28: 16.5 | L28: 16.5 | N28: 16.5 | P28: 16.5 | R28: 16.5 | T28: 16.5 | V28: 16.5 | X28: 16.5 | Z28: 16.5
A29: TOTAL MANO DE OBRA | B29: ='W7 DIESEL 120K'!U21 -> 14.78 | C29: =SUM(C23:C28) -> 19.4 | D29: =SUM(D23:D28) -> 157 | E29: =SUM(E23:E28) -> 14.11 | F29: =SUM(F23:F28) -> 181.69 | G29: =SUM(G23:G28) -> 14.11 | H29: =SUM(H23:H28) -> 175.34 | I29: =SUM(I23:I28) -> 14.11 | J29: =SUM(J23:J28) -> 243.44 | ... Z29: =SUM(Z23:Z28) -> 211.69 | AA29: =SUM(C29:Z29) -> 3369.35
A30: TOTAL COSTO MANTENIMIENTO POR KILOMETRAJE | C30: =C10+C22+C29 -> 139.73 | D30: =D10+D22+D29 -> 293.84 | E30: =E10+E22+E29 -> 84.61 | F30: =F10+F22+F29 -> 318.53 | G30: =G10+G22+G29 -> 84.61 | H30: =H10+H22+H29 -> 329.4 | I30: =I10+I22+I29 -> 84.61 | J30: =J10+J22+J29 -> 380.28 | ... Z30: =Z10+Z22+Z29 -> 365.75 | AA30: =SUM(C30:Z30) -> 6351.42

Sheet DETALLADO MANT 4X2 - NO APLICA
A1: PLAN DE MANTENIMIENTO PREVENTIVO WINGLE 7 4X2
A2: WINGLE 7 DIESEL | B2: INTERMEDIOS | C2: 5000 | D2: 10000 | E2: 15000 | F2: 20000 | G2: 25000 | H2: 30000 | I2: 35000 | J2: 40000 | K2: 45000 | L2: 50000 | M2: 55000 | N2: 60000 | O2: 65000 | P2: 70000 | Q2: 75000 | R2: 80000 | S2: 85000 | T2: 90000 | U2: 95000 | V2: 100000 | W2: 105000 | X2: 110000 | Y2: 115000 | Z2: 120000
A3: ACEITE MOTOR (10W40) | B3: ='W7 DIESEL 120K'!U2 -> 40.98 | C3: 40.98 | D3: 40.98 | E3: 40.98 | F3: 40.98 | G3: 40.98 | H3: 40.98 | I3: 40.98 | J3: 40.98 | K3: 40.98 | L3: 40.98 | M3: 40.98 | N3: 40.98 | O3: 40.98 | P3: 40.98 | Q3: 40.98 | R3: 40.98 | S3: 40.98 | T3: 40.98 | U3: 40.98 | V3: 40.98 | W3: 40.98 | X3: 40.98 | Y3: 40.98 | Z3: 40.98
A4: FILTRO DE ACEITE | B4: ='W7 DIESEL 120K'!U3 -> 6.01 | C4: 6.01 | D4: 6.01 | E4: 6.01 | F4: 6.01 | G4: 6.01 | H4: 6.01 | I4: 6.01 | J4: 6.01 | K4: 6.01 | L4: 6.01 | M4: 6.01 | N4: 6.01 | O4: 6.01 | P4: 6.01 | Q4: 6.01 | R4: 6.01 | S4: 6.01 | T4: 6.01 | U4: 6.01 | V4: 6.01 | W4: 6.01 | X4: 6.01 | Y4: 6.01 | Z4: 6.01
A5: FILTROS DE COMBUSTIBLE | B5: ='W7 DIESEL 120K'!U4 -> 6.5 | C5: 6.5 | D5: 6.5 | E5: 6.5 | F5: 6.5 | G5: 6.5 | H5: 6.5 | I5: 6.5 | J5: 6.5 | K5: 6.5 | L5: 6.5 | M5: 6.5 | N5: 6.5 | O5: 6.5 | P5: 6.5 | Q5: 6.5 | R5: 6.5 | S5: 6.5 | T5: 6.5 | U5: 6.5 | V5: 6.5 | W5: 6.5 | X5: 6.5 | Y5: 6.5 | Z5: 6.5
A6: FILTRO TRAMPA DE AGUA/COMB | B6: ='W7 DIESEL 120K'!U5 -> 17.55 | C6: 17.55 | D6: 17.55 | E6: 17.55 | F6: 17.55 | G6: 17.55 | H6: 17.55 | I6: 17.55 | J6: 17.55 | K6: 17.55 | L6: 17.55 | M6: 17.55 | N6: 17.55 | O6: 17.55 | P6: 17.55 | Q6: 17.55 | R6: 17.55 | S6: 17.55 | T6: 17.55 | U6: 17.55 | V6: 17.55 | W6: 17.55 | X6: 17.55 | Y6: 17.55 | Z6: 17.55
A7: FILTRO DE AIRE | B7: ='W7 DIESEL 120K'!U6 -> 0 | D7: 10.45 | F7: 10.45 | H7: 10.45 | J7: 10.45 | L7: 10.45 | N7: 10.45 | P7: 10.45 | R7: 10.45 | T7: 10.45 | V7: 10.45 | X7: 10.45 | Z7: 10.45
A8: FILTRO DE CABINA A/C | B8: ='W7 DIESEL 120K'!U7 -> 0 | D8: 7.69 | F8: 7.69 | H8: 7.69 | J8: 7.69 | L8: 7.69 | N8: 7.69 | P8: 7.69 | R8: 7.69 | T8: 7.69 | V8: 7.69 | X8: 7.69 | Z8: 7.69
A9: PASTILLAS DE FRENO DEL | B9: ='W7 DIESEL 120K'!U8 -> 0 | D9: 26.87 | F9: 26.87 | H9: 26.87 | J9: 26.87 | L9: 26.87 | N9: 26.87 | P9: 26.87 | R9: 26.87 | T9: 26.87 | V9: 26.87 | X9: 26.87 | Z9: 26.87
A10: PASTILLAS DE FRENOS POST | B10: ='W7 DIESEL 120K'!U9 -> 0 | D10: 27 | F10: 27 | H10: 27 | J10: 27 | L10: 27 | N10: 27 | P10: 27 | R10: 27 | T10: 27 | V10: 27 | X10: 27 | Z10: 27
A11: LIQUIDO INYECTORES | B11: ='W7 DIESEL 120K'!U10 -> 0 | D11: 6.5 | F11: 6.5 | H11: 6.5 | J11: 6.5 | L11: 6.5 | N11: 6.5 | P11: 6.5 | R11: 6.5 | T11: 6.5 | V11: 6.5 | X11: 6.5 | Z11: 6.5
A12: LIMPIADOR DE FRENOS | B12: ='W7 DIESEL 120K'!U11 -> 0 | D12: 5 | F12: 5 | H12: 5 | J12: 5 | L12: 5 | N12: 5 | P12: 5 | R12: 5 | T12: 5 | V12: 5 | X12: 5 | Z12: 5
A13: LIMPIADOR DE ADMISION | B13: ='W7 DIESEL 120K'!U12 -> 0 | D13: 5.4 | F13: 5.4 | H13: 5.4 | J13: 5.4 | L13: 5.4 | N13: 5.4 | P13: 5.4 | R13: 5.4 | T13: 5.4 | V13: 5.4 | X13: 5.4 | Z13: 5.4
A14: REFRIGERANTE | B14: ='W7 DIESEL 120K'!U13 -> 0
A15: KIT DE DISTRIBUCIÓN | B15: ='W7 DIESEL 120K'!U14 -> 0 | V15: 157.97
A16: ACEITE DE CAJA (75W90) 4lt | B16: ='W7 DIESEL 120K'!U15 -> 0 | L16: 31.56 | V16: 31.56
A17: ACEITE DIFERENCIAL POSTERIOR (80W90) 3lt | L17: 22.5 | V17: 22.5
A18: SUMINISTROS | B18: ='W7 DIESEL 120K'!U17 -> 3.5 | C18: 3.5 | D18: 3.5 | E18: 3.5 | F18: 3.5 | G18: 3.5 | H18: 3.5 | I18: 3.5 | J18: 3.5 | K18: 3.5 | L18: 3.5 | M18: 3.5 | N18: 3.5 | O18: 3.5 | P18: 3.5 | Q18: 3.5 | R18: 3.5 | S18: 3.5 | T18: 3.5 | U18: 3.5 | V18: 3.5 | W18: 3.5 | X18: 3.5 | Y18: 3.5 | Z18: 3.5
A19: ACEITE DIRECCION HIDRAULICA | B19: ='W7 DIESEL 120K'!U18 -> 0 | L19: 7.33 | V19: 7.33
A20: LIQUIDO DE FRENOS | B20: ='W7 DIESEL 120K'!U19 -> 0 | H20: 12 | N20: 12 | T20: 12
A21: BANDA DE SERVICIO/ACCESORIOS | P21: 26.6
A22: TOTAL REPUESTOS | B22: =B4+B5+B6+B7+B9+B10+B11+B12+B13+B15+B18+B8 -> 33.56 | C22: =C4+C5+C6+C7+C9+C10+C11+C12+C13+C15+C18+C8+C21 -> 33.56 | D22: =D4+D5+D6+D7+D9+D10+D11+D12+D13+D15+D18+D8+D21 -> 122.47 | E22: =E4+E5+E6+E7+E9+E10+E11+E12+E13+E15+E18+E8+E21 -> 33.56 | F22: =F4+F5+F6+F7+F9+F10+F11+F12+F13+F15+F18+F8+F21 -> 122.47 | G22: =G4+G5+G6+G7+G9+G10+G11+G12+G13+G15+G18+G8+G21 -> 33.56 | H22: =H4+H5+H6+H7+H9+H10+H11+H12+H13+H15+H18+H8+H21 -> 122.47 | I22: =I4+I5+I6+I7+I9+I10+I11+I12+I13+I15+I18+I8+I21 -> 33.56 | J22: =J4+J5+J6+J7+J9+J10+J11+J12+J13+J15+J18+J8+J21 -> 122.47 | ... Z22: =Z4+Z5+Z6+Z7+Z9+Z10+Z11+Z12+Z13+Z15+Z18+Z8+Z21 -> 122.47 | AA22: =SUM(C22:Z22) -> 2056.93
A23: TOTAL MANO DE OBRA | B23: ='W7 DIESEL 120K'!U21 -> 14.78 | C23: 19.4 | D23: 157 | E23: 14.11 | F23: 181.69 | G23: 14.11 | H23: 175.34 | I23: 14.11 | J23: 213.44 | K23: 14.11 | L23: 169.34 | M23: 14.11 | N23: 196.51 | O23: 14.11 | P23: 148.18 | Q23: 14.11 | R23: 181.69 | S23: 14.11 | T23: 178.87 | U23: 14.11 | V23: 313.99 | W23: 19.4 | X23: 157 | Y23: 14.11 | Z23: 181.69 | AA23: =SUM(C23:Z23) -> 2434.64
A24: ALINEACION | B24: 0 | D24: 17.16 | F24: 17.16 | H24: 17.16 | J24: 17.16 | L24: 17.16 | N24: 17.16 | P24: 17.16 | R24: 17.16 | T24: 17.16 | V24: 17.16 | X24: 17.16 | Z24: 17.16
A25: BALANCEO | D25: 15.84 | F25: 15.84 | H25: 15.84 | J25: 15.84 | L25: 15.84 | N25: 15.84 | P25: 15.84 | R25: 15.84 | T25: 15.84 | V25: 15.84 | X25: 15.84 | Z25: 15.84
A26: LIMPIEZA DE INYECTORES | B26: 0 | D26: 16.5 | F26: 16.5 | H26: 16.5 | J26: 16.5 | L26: 16.5 | N26: 16.5 | P26: 16.5 | R26: 16.5 | T26: 16.5 | V26: 16.5 | X26: 16.5 | Z26: 16.5
A27: *LUBRICANTES | B27: =B3+B14+B16+#REF!+B19+B20 -> #REF! | C27: =C3+C14+C16+C19+C20 -> 40.98 | D27: =D3+D14+D16+D19+D20+D17 -> 40.98 | E27: =E3+E14+E16+E19+E20+E17 -> 40.98 | F27: =F3+F14+F16+F19+F20+F17 -> 40.98 | G27: =G3+G14+G16+G19+G20+G17 -> 40.98 | H27: =H3+H14+H16+H19+H20+H17 -> 52.98 | I27: =I3+I14+I16+I19+I20+I17 -> 40.98 | J27: =J3+J14+J16+J19+J20+J17 -> 40.98 | K27: =K3+K14+K16+K19+K20+K17 -> 40.98 | ... Z27: =Z3+Z14+Z16+Z19+Z20+Z17 -> 40.98 | AA27: =SUM(C27:Z27) -> 1142.3
A28: TOTAL COSTO MANTINIENTO POR KILOMETRAJE | C28: =C22+C23+C27 -> 93.94 | D28: =D22+D23+D27 -> 320.45 | E28: =E22+E23+E27 -> 88.65 | F28: =F22+F23+F27 -> 345.14 | G28: =G22+G23+G27 -> 88.65 | H28: =H22+H23+H27 -> 350.79 | I28: =I22+I23+I27 -> 88.65 | J28: =J22+J23+J27 -> 376.89 | ... Z28: =Z22+Z23+Z27 -> 345.14

Sheet CONSOLIDADO
B2: COSTOS MANTENIMIENTO KYC F3 4X4 | G2: CANTIDAD VEHICULOS
B3: 1 | C3: Total lubricantes | D3: Mantenimiento preventivo | E3: ='DETALLADO MANT 4X4'!AA10*G3 -> 1460.51 | G3: 1
B4: 2 | C4: Total repuestos | E4: ='DETALLADO MANT 4X4'!AA23*G3 -> 1641.62
B5: 3 | C5: Total mano de obra | E5: ='DETALLADO MANT 4X4'!AA30*G3 -> 3369.35
B6: 4 | C6: Mantenimiento correctivo | D6: Se considera un valor aproximado del 30% del costo total de mantenimientos preventivos | E6: =(E3+E4+E5)*0.3 -> 1941.444
B7: Total 1 + 2 + 3 + 4 | E7: =SUM(E3:E6) -> 8412.924
B8: Costos no incluyen IVA
B10: COSTOS MANTENIMIENTO KYC F3 4X2 | G10: CANTIDAD VEHICULOS
B11: 1 | C11: Total lubricantes | D11: Mantenimiento preventivo | E11: ='DETALLADO MANT 4X2'!AA10*G11 -> 1340.45 | G11: 1
B12: 2 | C12: Total repuestos | E12: ='DETALLADO MANT 4X2'!AA22*G11 -> 1641.62
B13: 3 | C13: Total mano de obra | E13: ='DETALLADO MANT 4X2'!AA29*G11 -> 3369.35
B14: 4 | C14: Mantenimiento correctivo | D14: Se considera un valor aproximado del 30% del costo total de mantenimientos preventivos | E14: =(E11+E12+E13)*0.3 -> 1905.426
B15: Total 1 + 2 + 3 + 4 | E15: =SUM(E11:E14) -> 8256.846
B16: Costos no incluyen IVA

Sheet PLAN MANTENIMIENTO
A1: PLAN DE MANTENIMIENTO PREVENTIVO WINGLE 7 (4X4 Y 4X2)
A2: WINGLE 7 DIESEL | B2: 5000 | C2: 10000 | D2: 15000 | E2: 20000 | F2: 25000 | G2: 30000 | H2: 35000 | I2: 40000 | J2: 45000 | K2: 50000 | L2: 55000 | M2: 60000 | N2: 65000 | O2: 70000 | P2: 75000 | Q2: 80000 | R2: 85000 | S2: 90000 | T2: 95000 | U2: 100000 | V2: 105000 | W2: 110000 | X2: 115000 | Y2: 120000
A3: ACEITE MOTOR | B3: X | C3: X | D3: X | E3: X | F3: X | G3: X | H3: X | I3: X | J3: X | K3: X | L3: X | M3: X | N3: X | O3: X | P3: X | Q3: X | R3: X | S3: X | T3: X | U3: X | V3: X | W3: X | X3: X | Y3: X
A4: FILTRO DE ACEITE | B4: X | C4: X | D4: X | E4: X | F4: X | G4: X | H4: X | I4: X | J4: X | K4: X | L4: X | M4: X | N4: X | O4: X | P4: X | Q4: X | R4: X | S4: X | T4: X | U4: X | V4: X | W4: X | X4: X | Y4: X
A5: FILTROS DE COMBUSTIBLE | B5: X | C5: X | D5: X | E5: X | F5: X | G5: X | H5: X | I5: X | J5: X | K5: X | L5: X | M5: X | N5: X | O5: X | P5: X | Q5: X | R5: X | S5: X | T5: X | U5: X | V5: X | W5: X | X5: X | Y5: X
A6: FILTRO TRAMPA DE AGUA/COMB | B6: X | C6: X | D6: X | E6: X | F6: X | G6: X | H6: X | I6: X | J6: X | K6: X | L6: X | M6: X | N6: X | O6: X | P6: X | Q6: X | R6: X | S6: X | T6: X | U6: X | V6: X | W6: X | X6: X | Y6: X
A7: FILTRO DE AIRE | C7: X | E7: X | G7: X | I7: X | K7: X | M7: X | O7: X | Q7: X | S7: X | U7: X | W7: X | Y7: X
A8: FILTRO DE CABINA A/C | C8: X | E8: X | G8: X | I8: X | K8: X | M8: X | O8: X | Q8: X | S8: X | U8: X | W8: X | Y8: X
A9: PASTILLAS DE FRENO DEL | C9: X | E9: X | G9: X | I9: X | K9: X | M9: X | O9: X | Q9: X | S9: X | U9: X | W9: X | Y9: X
A10: PASTILLAS DE FRENOS POST | C10: X | E10: X | G10: X | I10: X | K10: X | M10: X | O10: X | Q10: X | S10: X | U10: X | W10: X | Y10: X
A11: LIQUIDO INYECTORES | C11: X | E11: X | G11: X | I11: X | K11: X | M11: X | O11: X | Q11: X | S11: X | U11: X | W11: X | Y11: X
A12: LIMPIADOR DE FRENOS | C12: X | E12: X | G12: X | I12: X | K12: X | M12: X | O12: X | Q12: X | S12: X | U12: X | W12: X | Y12: X
A13: LIMPIADOR DE ADMISION | C13: X | E13: X | G13: X | I13: X | K13: X | M13: X | O13: X | Q13: X | S13: X | U13: X | W13: X | Y13: X
A14: REFRIGERANTE
A15: KIT DE DISTRIBUCIÓN | U15: X
A16: ACEITE DE CAJA (4X2 Y 4X4) | K16: X | U16: X
A17: ACEITE DIFERENCIAL DELANTERO (SOLO 4X4) | K17: X | U17: X
A18: ACEITE DIFERENCIAL POSTERIOR (4X2 Y 4X4) | K18: X | U18: X
A19: ACEITE TRANSFER (SOLO 4X4) | K19: X | U19: X
A20: SUMINISTROS | B20: X | C20: X | D20: X | E20: X | F20: X | G20: X | H20: X | I20: X | J20: X | K20: X | L20: X | M20: X | N20: X | O20: X | P20: X | Q20: X | R20: X | S20: X | T20: X | U20: X | V20: X | W20: X | X20: X | Y20: X
A21: ACEITE DIRECCION HIDRAULICA | K21: X | U21: X
A22: LIQUIDO DE FRENOS | G22: X | M22: X | S22: X
A23: BANDA DE SERVICIO/ACCESORIOS | O23: X
A24: MANO DE OBRA | B24: X | C24: X | D24: X | E24: X | F24: X | G24: X | H24: X | I24: X | J24: X | K24: X | L24: X | M24: X | N24: X | O24: X | P24: X | Q24: X | R24: X | S24: X | T24: X | U24: X | V24: X | W24: X | X24: X | Y24: X
A25: ALINEACION | C25: X | E25: X | G25: X | I25: X | K25: X | M25: X | O25: X | Q25: X | S25: X | U25: X | W25: X | Y25: X
A26: BALANCEO | C26: X | E26: X | G26: X | I26: X | K26: X | M26: X | O26: X | Q26: X | S26: X | U26: X | W26: X | Y26: X
A27: LIMPIEZA DE INYECTORES | C27: X | E27: X | G27: X | I27: X | K27: X | M27: X | O27: X | Q27: X | S27: X | U27: X | W27: X | Y27: X

Sheet REF. MANT. CORRECTIVO
A1: MARCA | B1: GWM
A2: MODELO | B2: WINGLE 7 DIESEL | C2: MANTENIMIENTOS CORRECTIVOS | G2: VALORES
A3: ITEM | B3: DESCRIPCION | C3: TOTAL REPUESTOS | D3: Total M/O | E3: TOTAL LUBRICANTES | F3: SUBTOTAL | G3: IVA | H3: TOTAL
A4: 1 | B4: BOMBA DE COMBUSTIBLE ALTA PRESION | C4: 1170 | D4: 147.6 | F4: =SUM(C4:E4) -> 1317.6 | G4: =F4*0.12 -> 158.112 | H4: =SUM(F4:G4) -> 1475.712
A5: 2 | B5: BOMBA AGUA | C5: 99.09 | D5: 132.75 | F5: =SUM(C5:E5) -> 231.84 | G5: =F5*0.12 -> 27.8208 | H5: =SUM(F5:G5) -> 259.6608
A6: 3 | B6: BOMBA DIRECCION HIDRAULICA | C6: 187.49 | D6: 82.5 | E6: 15 | F6: =SUM(C6:E6) -> 284.99 | G6: =F6*0.12 -> 34.1988 | H6: =SUM(F6:G6) -> 319.1888
A7: 4 | B7: AMORTIGUADORES DELANTEROS | C7: 157.52 | D7: 28.5 | F7: =SUM(C7:E7) -> 186.02 | G7: =F7*0.12 -> 22.3224 | H7: =SUM(F7:G7) -> 208.3424
A8: 5 | B8: AMORTIGUADORES POSTERIORES | C8: 116 | D8: 28.5 | F8: =SUM(C8:E8) -> 144.5 | G8: =F8*0.12 -> 17.34 | H8: =SUM(F8:G8) -> 161.84
A9: 6 | B9: KIT EMBRAGUE COMPLETO | C9: 204.44 | D9: 123.75 | F9: =SUM(C9:E9) -> 328.19 | G9: =F9*0.12 -> 39.3828 | H9: =SUM(F9:G9) -> 367.5728
A10: 7 | B10: RODAMIENTOS PUNTAS DE EJE DELANTEROS (4) | C10: 48.88 | D10: 61.05 | F10: =SUM(C10:E10) -> 109.93 | G10: =F10*0.12 -> 13.1916 | H10: =SUM(F10:G10) -> 123.1216
A11: 8 | B11: RETENEDORES EJE DELANTEROS (2) | C11: 7.76 | D11: 82 | F11: =SUM(C11:E11) -> 89.76 | G11: =F11*0.12 -> 10.7712 | H11: =SUM(F11:G11) -> 100.5312
A12: 9 | B12: DISCOS DE FRENO DELANTEROS | C12: 119.18 | D12: 30 | F12: =SUM(C12:E12) -> 149.18 | G12: =F12*0.12 -> 17.9016 | H12: =SUM(F12:G12) -> 167.0816
A13: 10 | B13: DISCOS DE FRENO POSTERIORES | C13: 141.48 | D13: 30 | F13: =SUM(C13:E13) -> 171.48 | G13: =F13*0.12 -> 20.5776 | H13: =SUM(F13:G13) -> 192.0576
A14: 11 | B14: BUJES DE PAQUETES DE RESORTES | C14: 40 | D14: 82.5 | F14: =SUM(C14:E14) -> 122.5 | G14: =F14*0.12 -> 14.7 | H14: =SUM(F14:G14) -> 137.2
A15: 12 | B15: CRUCETAS DE CARDAN | C15: 12.96 | D15: 82.5 | F15: =SUM(C15:E15) -> 95.46 | G15: =F15*0.12 -> 11.4552 | H15: =SUM(F15:G15) -> 106.9152
A16: 13 | B16: BOMBA DE FRENO | C16: 201.37 | D16: 86.05 | F16: =SUM(C16:E16) -> 287.42 | G16: =F16*0.12 -> 34.4904 | H16: =SUM(F16:G16) -> 321.9104
A17: 14 | B17: BOMBA DE EMBRAGUE | C17: 30.44 | D17: 50.05 | F17: =SUM(C17:E17) -> 80.49 | G17: =F17*0.12 -> 9.6588 | H17: =SUM(F17:G17) -> 90.1488
A18: 15 | B18: INYECTORES | C18: 1557.56 | D18: 41.25 | F18: =SUM(C18:E18) -> 1598.81 | G18: =F18*0.12 -> 191.8572 | H18: =SUM(F18:G18) -> 1790.6672
A19: 16 | B19: TURBO GEOMETRIA VARIABLE | C19: 1340.14 | D19: 99.5 | F19: =SUM(C19:E19) -> 1439.64 | G19: =F19*0.12 -> 172.7568 | H19: =SUM(F19:G19) -> 1612.3968
A20: 17 | B20: CREMALLERA DE DIRECCION | C20: 500 | D20: 82.5 | E20: 15 | F20: =SUM(C20:E20) -> 597.5 | G20: =F20*0.12 -> 71.7 | H20: =SUM(F20:G20) -> 669.2
A21: 18 | B21: ROTULAS SUPERIORES | C21: 71.36 | D21: 51 | F21: =SUM(C21:E21) -> 122.36 | G21: =F21*0.12 -> 14.6832 | H21: =SUM(F21:G21) -> 137.0432
A22: 19 | B22: ROTULAS INFERIORES | C22: 71.08 | D22: 51 | F22: =SUM(C22:E22) -> 122.08 | G22: =F22*0.12 -> 14.6496 | H22: =SUM(F22:G22) -> 136.7296
A23: 20 | B23: COMPRESOR A/C | C23: 390.18 | D23: 109.5 | F23: =SUM(C23:E23) -> 499.68 | G23: =F23*0.12 -> 59.9616 | H23: =SUM(F23:G23) -> 559.6416
A24: 21 | B24: BANDA DE SERVICIO | C24: 48.27 | D24: 14.85 | F24: =SUM(C24:E24) -> 63.12 | G24: =F24*0.12 -> 7.5744 | H24: =SUM(F24:G24) -> 70.6944
A25: 22 | B25: RODAMIENTAS DE CAJA DE CAMBIOS | C25: 177.84 | D25: 240 | E25: 48 | F25: =SUM(C25:E25) -> 465.84 | G25: =F25*0.12 -> 55.9008 | H25: =SUM(F25:G25) -> 521.7408
A26: 23 | B26: SINCRONIZADOS DE CAJA DE CAMBIOS | C26: 192.32 | D26: 240 | E26: 48 | F26: =SUM(C26:E26) -> 480.32 | G26: =F26*0.12 -> 57.6384 | H26: =SUM(F26:G26) -> 537.9584
A27: 24 | B27: PAQUETES DE RESORTES POSTERIORES | C27: 329.28 | D27: 66 | F27: =SUM(C27:E27) -> 395.28 | G27: =F27*0.12 -> 47.4336 | H27: =SUM(F27:G27) -> 442.7136
B28: SUBTOTAL | C28: =SUM(C4:C27) -> 7214.64 | D28: =SUM(D4:D27) -> 2043.35 | E28: =SUM(E4:E27) -> 126 | F28: =SUM(F4:F27) -> 9383.99 | G28: =SUM(G4:G27) -> 1126.0788 | H28: =SUM(H4:H27) -> 10510.069
B29: IVA | C29: =C28*0.12 -> 865.7568 | D29: =D28*0.12 -> 245.202 | E29: =E28*0.12 -> 15.12 | F29: =F28*0.12 -> 1126.0788
B30: TOTAL | C30: =SUM(C28:C29) -> 8080.3968 | D30: =SUM(D28:D29) -> 2288.552 | E30: =SUM(E28:E29) -> 141.12 | F30: =SUM(F28:F29) -> 10510.069

Sheet REF. MANT. CORRECTIVO COMPLETO
A1: MARCA | B1: GWM
A2: MODELO | B2: KYC F3 | C2: MANTENIMIENTOS CORRECTIVOS | G2: VALORES
A3: ITEM | B3: DESCRIPCION | C3: TOTAL REPUESTOS | D3: Total M/O | E3: TOTAL LUBRICANTES | F3: SUBTOTAL | G3: IVA | H3: TOTAL
A4: 1 | B4: BOMBA DE COMBUSTIBLE ALTA PRESION | C4: 1377.23 | D4: 147.6 | F4: =SUM(C4:E4) -> 1524.83 | G4: =F4*0.15 -> 228.7245 | H4: =SUM(F4:G4) -> 1753.5545
A5: 2 | B5: BOMBA AGUA | C5: 151.24 | D5: 132.75 | F5: =SUM(C5:E5) -> 283.99 | G5: =F5*0.15 -> 42.5985 | H5: =SUM(F5:G5) -> 326.5885
A6: 3 | B6: BRAZO AUXILIAR COLUMNA DIRECCIÓN | C6: 122.65 | D6: 82.5 | F6: =SUM(C6:E6) -> 205.15 | G6: =F6*0.15 -> 30.7725 | H6: =SUM(F6:G6) -> 235.9225
A7: 4 | B7: AMORTIGUADORES DELANTEROS C/U | C7: 27.89 | D7: 28.5 | F7: =SUM(C7:E7) -> 56.39 | G7: =F7*0.15 -> 8.4585 | H7: =SUM(F7:G7) -> 64.8485
A8: 5 | B8: AMORTIGUADORES POSTERIORES C/U | C8: 31.57 | D8: 28.5 | F8: =SUM(C8:E8) -> 60.07 | G8: =F8*0.15 -> 9.0105 | H8: =SUM(F8:G8) -> 69.0805
A9: 6 | B9: DISCO DE EMBRAGUE | C9: 199.56 | D9: 123.75 | F9: =SUM(C9+C10+C11+C12+D9) -> 583.4 | G9: =F9*0.15 -> 87.51 | H9: =SUM(F9:G9) -> 670.91
B10: PLATO DE EMBRAGUE | C10: 220.5
B11: RODAMIENTO DE EMBRAGUE | C11: 33.6
B12: RODAMIENTO VOLANTE DE INERCIA | C12: 5.99
A13: 7 | B13: RODAMIENTOS PUNTAS DE EJE DELANTEROS C/U | C13: 16.8 | D13: 61.05 | F13: =SUM(C13:E13) -> 77.85 | G13: =F13*0.15 -> 11.6775 | H13: =SUM(F13:G13) -> 89.5275
A14: 8 | B14: RETENEDORES EJE DELANTEROS C/U | C14: 11.55 | D14: 82 | F14: =SUM(C14:E14) -> 93.55 | G14: =F14*0.15 -> 14.0325 | H14: =SUM(F14:G14) -> 107.5825
A15: 9 | B15: DISCOS DE FRENO DELANTEROS C/U | C15: 78.66 | D15: 30 | F15: =SUM(C15:E15) -> 108.66 | G15: =F15*0.15 -> 16.299 | H15: =SUM(F15:G15) -> 124.959
A16: 10 | B16: KIT ZAPATAS | C16: 84 | D16: 30 | F16: =SUM(C16:E16) -> 114 | G16: =F16*0.15 -> 17.1 | H16: =SUM(F16:G16) -> 131.1
A17: 11 | B17: BUJES DE PAQUETES DE RESORTES C/U | C17: 3.77 | D17: 82.5 | F17: =SUM(C17:E17) -> 86.27 | G17: =F17*0.15 -> 12.9405 | H17: =SUM(F17:G17) -> 99.2105
A18: 12 | B18: CRUCETAS DE CARDAN | C18: 14.88 | D18: 82.5 | F18: =SUM(C18:E18) -> 97.38 | G18: =F18*0.15 -> 14.607 | H18: =SUM(F18:G18) -> 111.987
A19: 13 | B19: BOMBA DE FRENO | C19: 121.77 | D19: 86.05 | F19: =SUM(C19:E19) -> 207.82 | G19: =F19*0.15 -> 31.173 | H19: =SUM(F19:G19) -> 238.993
A20: 14 | B20: BOMBA DE EMBRAGUE PRINCIPAL | C20: 14.44 | D20: 50.05 | F20: =SUM(C20:E20) -> 64.49 | G20: =F20*0.15 -> 9.6735 | H20: =SUM(F20:G20) -> 74.1635
B21: BOMBA DE EMBRAGUE SECUNDARIA | C21: 15 | D21: 50.05 | F21: =SUM(C21:E21) -> 65.05 | G21: =F21*0.15 -> 9.7575 | H21: =SUM(F21:G21) -> 74.8075
A22: 15 | B22: INYECTORES C/U | C22: 362.53 | D22: 41.25 | F22: =SUM(C22:E22) -> 403.78 | G22: =F22*0.15 -> 60.567 | H22: =SUM(F22:G22) -> 464.347
A23: 16 | B23: TURBO GEOMETRIA VARIABLE | C23: 547.6 | D23: 99.5 | F23: =SUM(C23:E23) -> 647.1 | G23: =F23*0.15 -> 97.065 | H23: =SUM(F23:G23) -> 744.165
A24: 17 | B24: DIRECCION ELECTROASISTIDA | C24: 635.99 | D24: 198 | F24: =SUM(C24:E24) -> 833.99 | G24: =F24*0.15 -> 125.0985 | H24: =SUM(F24:G24) -> 959.0885
A25: 18 | B25: MESA SUPERIOR LH | C25: 95.93 | D25: 51 | F25: =SUM(C25:E25) -> 146.93 | G25: =F25*0.15 -> 22.0395 | H25: =SUM(F25:G25) -> 168.9695
B26: MESA SUPERIOR RH | C26: 96.68 | D26: 51 | F26: =SUM(C26:E26) -> 147.68 | G26: =F26*0.15 -> 22.152 | H26: =SUM(F26:G26) -> 169.832
B27: MESA INFERIOR | C27: 96.92 | D27: 51 | F27: =SUM(C27:E27) -> 147.92 | G27: =F27*0.15 -> 22.188 | H27: =SUM(F27:G27) -> 170.108
B28: BRAZO MESA INFERIOR LH | C28: 26.32 | D28: 49.5 | F28: =SUM(C28:E28) -> 75.82 | G28: =F28*0.15 -> 11.373 | H28: =SUM(F28:G28) -> 87.193
B29: BRAZO MESA INFERIOR RH | C29: 25.55 | D29: 49.5 | F29: =SUM(C29:E29) -> 75.05 | G29: =F29*0.15 -> 11.2575 | H29: =SUM(F29:G29) -> 86.3075
A30: 19 | B30: CAJA DE CAMBIOS | C30: 1915.26 | D30: 132 | F30: =SUM(C30:E30) -> 2047.26 | G30: =F30*0.15 -> 307.089 | H30: =SUM(F30:G30) -> 2354.349
A31: 20 | B31: COMPRESOR A/C | C31: 124.59 | D31: 109.5 | F31: =SUM(C31:E31) -> 234.09 | G31: =F31*0.15 -> 35.1135 | H31: =SUM(F31:G31) -> 269.2035
A32: 21 | B32: BANDA DE SERVICIO | C32: 33.5 | D32: 14.85 | F32: =SUM(C32:E32) -> 48.35 | G32: =F32*0.15 -> 7.2525 | H32: =SUM(F32:G32) -> 55.6025
A33: 24 | B33: PAQUETES DE RESORTES POSTERIORES C/L | C33: 100.23 | D33: 66 | F33: =SUM(C33:E33) -> 166.23 | G33: =F33*0.15 -> 24.9345 | H33: =SUM(F33:G33) -> 191.1645
A34: 26 | B34: PASTILLAS DE FRENO DELANTERAS | C34: 29.16 | D34: 28.05 | F34: =SUM(C34:E34) -> 57.21 | G34: =F34*0.15 -> 8.5815 | H34: =SUM(F34:G34) -> 65.7915
A35: 28 | B35: PLUMAS (LIMPIAPRABRISAS) | C35: 30 | D35: 6.6 | F35: =SUM(C35:E35) -> 36.6 | G35: =F35*0.15 -> 5.49 | H35: =SUM(F35:G35) -> 42.09
A36: 29 | B36: FOCOS 1 CONTACTO | C36: 1.25 | D36: 6.6 | F36: =SUM(C36:E36) -> 7.85 | G36: =F36*0.15 -> 1.1775 | H36: =SUM(F36:G36) -> 9.0275
A37: 30 | B37: FOCOS 2 CONTACTOS | C37: 1.3 | D37: 6.6 | F37: =SUM(C37:E37) -> 7.9 | G37: =F37*0.15 -> 1.185 | H37: =SUM(F37:G37) -> 9.085
A38: 31 | B38: FOCOS H7 HALÓGENO | C38: 7 | D38: 6.6 | F38: =SUM(C38:E38) -> 13.6 | G38: =F38*0.15 -> 2.04 | H38: =SUM(F38:G38) -> 15.64
A39: 32 | B39: FOCOS H4 HALÓGENO | C39: 7.8 | D39: 6.6 | F39: =SUM(C39:E39) -> 14.4 | G39: =F39*0.15 -> 2.16 | H39: =SUM(F39:G39) -> 16.56
A40: 33 | B40: BATERIA | C40: 160 | D40: 6.6 | F40: =SUM(C40:E40) -> 166.6 | G40: =F40*0.15 -> 24.99 | H40: =SUM(F40:G40) -> 191.59
...

Sheet PLAN MANTENIMEINTO WINGLE 2,8
A1: WINGLE 2,8 DIESEL | B1: 5000 | C1: 10000 | D1: 15000 | E1: 20000 | F1: 25000 | G1: 30000 | H1: 35000 | I1: 40000 | J1: 45000 | K1: 50000 | L1: 55000 | M1: 60000 | N1: 65000 | O1: 70000 | P1: 75000 | Q1: 80000 | R1: 85000 | S1: 90000 | T1: 95000 | U1: 100000 | V1: 105000 | W1: 110000 | X1: 115000 | Y1: 120000
A2: ACEITE MOTOR (10W40) 6lt | B2: 43.98 | C2: 43.98 | D2: 43.98 | E2: 43.98 | F2: 43.98 | G2: 43.98 | H2: 43.98 | I2: 43.98 | J2: 43.98 | K2: 43.98 | L2: 43.98 | M2: 43.98 | N2: 43.98 | O2: 43.98 | P2: 43.98 | Q2: 43.98 | R2: 43.98 | S2: 43.98 | T2: 43.98 | U2: 43.98 | V2: 43.98 | W2: 43.98 | X2: 43.98 | Y2: 43.98
A3: ACEITE DE CAJA (75W90) 3lt | K3: 25.65 | U3: 25.65
A4: ACEITE DIFERENCIAL DELANTERO (80W90) 2lt | K4: 16.12 | U4: 16.12
A5: ACEITE DIFERENCIAL POSTERIOR (80W90) 3lt | K5: 24.18 | U5: 24.18
A6: ACEITE TRANSFER (ATF3-DEXRON3) 2 lt | K6: 15.84 | U6: 15.84
A7: ACEITE DIRECCION HIDRAULICA | K7: 7.92 | U7: 7.92
A8: LIQUIDO DE FRENOS | G8: 5 | M8: 5 | S8: 5
A9: TOTAL LUBRICANTES | B9: =SUM(B2:B8) -> 43.98 | C9: =SUM(C2:C8) -> 43.98 | D9: =SUM(D2:D8) -> 43.98 | E9: =SUM(E2:E8) -> 43.98 | F9: =SUM(F2:F8) -> 43.98 | G9: =SUM(G2:G8) -> 48.98 | H9: =SUM(H2:H8) -> 43.98 | I9: =SUM(I2:I8) -> 43.98 | ... Y9: =SUM(Y2:Y8) -> 43.98 | Z9: =SUM(B9:Y9) -> 1249.94
A10: FILTRO DE ACEITE | B10: 6.3 | C10: 6.3 | D10: 6.3 | E10: 6.3 | F10: 6.3 | G10: 6.3 | H10: 6.3 | I10: 6.3 | J10: 6.3 | K10: 6.3 | L10: 6.3 | M10: 6.3 | N10: 6.3 | O10: 6.3 | P10: 6.3 | Q10: 6.3 | R10: 6.3 | S10: 6.3 | T10: 6.3 | U10: 6.3 | V10: 6.3 | W10: 6.3 | X10: 6.3 | Y10: 6.3
A11: FILTROS DE COMBUSTIBLE | B11: 6.01 | C11: 6.01 | D11: 6.01 | E11: 6.01 | F11: 6.01 | G11: 6.01 | H11: 6.01 | I11: 6.01 | J11: 6.01 | K11: 6.01 | L11: 6.01 | M11: 6.01 | N11: 6.01 | O11: 6.01 | P11: 6.01 | Q11: 6.01 | R11: 6.01 | S11: 6.01 | T11: 6.01 | U11: 6.01 | V11: 6.01 | W11: 6.01 | X11: 6.01 | Y11: 6.01
A12: FILTRO TRAMPA DE AGUA/COMB | B12: 17.97 | C12: 17.97 | D12: 17.97 | E12: 17.97 | F12: 17.97 | G12: 17.97 | H12: 17.97 | I12: 17.97 | J12: 17.97 | K12: 17.97 | L12: 17.97 | M12: 17.97 | N12: 17.97 | O12: 17.97 | P12: 17.97 | Q12: 17.97 | R12: 17.97 | S12: 17.97 | T12: 17.97 | U12: 17.97 | V12: 17.97 | W12: 17.97 | X12: 17.97 | Y12: 17.97
A13: FILTRO DE AIRE | C13: 12.04 | E13: 12.04 | G13: 12.04 | I13: 12.04 | K13: 12.04 | M13: 12.04 | O13: 12.04 | Q13: 12.04 | S13: 12.04 | U13: 12.04 | W13: 12.04 | Y13: 12.04
A14: FILTRO DE CABINA A/C | C14: 5.58 | E14: 5.58 | G14: 5.58 | I14: 5.58 | K14: 5.58 | M14: 5.58 | O14: 5.58 | Q14: 5.58 | S14: 5.58 | U14: 5.58 | W14: 5.58 | Y14: 5.58
A15: PASTILLAS DE FRENO DEL | C15: 29.16 | E15: 29.16 | G15: 29.16 | I15: 29.16 | K15: 29.16 | M15: 29.16 | O15: 29.16 | Q15: 29.16 | S15: 29.16 | U15: 29.16 | W15: 29.16 | Y15: 29.16
A16: PASTILLAS DE FRENOS POST | C16: 29.63 | E16: 29.63 | G16: 29.63 | I16: 29.63 | K16: 29.63 | M16: 29.63 | O16: 29.63 | Q16: 29.63 | S16: 29.63 | U16: 29.63 | W16: 29.63 | Y16: 29.63
A17: LIQUIDO INYECTORES | C17: 7.01 | E17: 7.01 | G17: 7.01 | I17: 7.01 | K17: 7.01 | M17: 7.01 | O17: 7.01 | Q17: 7.01 | S17: 7.01 | U17: 7.01 | W17: 7.01 | Y17: 7.01
A18: LIMPIADOR DE FRENOS | C18: 5.6 | E18: 5.6 | G18: 5.6 | I18: 5.6 | K18: 5.6 | M18: 5.6 | O18: 5.6 | Q18: 5.6 | S18: 5.6 | U18: 5.6 | W18: 5.6 | Y18: 5.6
A19: LIMPIADOR DE ADMISION | C19: 6.02 | E19: 6.02 | G19: 6.02 | I19: 6.02 | K19: 6.02 | M19: 6.02 | O19: 6.02 | Q19: 6.02 | S19: 6.02 | U19: 6.02 | W19: 6.02 | Y19: 6.02
A20: REFRIGERANTE
A21: KIT DE DISTRIBUCIÓN | U21: 172.15
A22: SUMINISTROS | B22: 3 | C22: 3 | D22: 3 | E22: 3 | F22: 3 | G22: 3 | H22: 3 | I22: 3 | J22: 3 | K22: 3 | L22: 3 | M22: 3 | N22: 3 | O22: 3 | P22: 3 | Q22: 3 | R22: 3 | S22: 3 | T22: 3 | U22: 3 | V22: 3 | W22: 3 | X22: 3 | Y22: 3
A23: BANDA DE SERVICIO/ACCESORIOS | O23: 29.29
A24: TOTAL REPUESTOS | B24: =B10+B11+B12+B13+B15+B16+B17+B18+B19+B21+B22+B14+B23 -> 33.28 | C24: =C10+C11+C12+C13+C15+C16+C17+C18+C19+C21+C22+C14+C23 -> 128.32 | D24: =D10+D11+D12+D13+D15+D16+D17+D18+D19+D21+D22+D14+D23 -> 33.28 | E24: =E10+E11+E12+E13+E15+E16+E17+E18+E19+E21+E22+E14+E23 -> 128.32 | F24: =F10+F11+F12+F13+F15+F16+F17+F18+F19+F21+F22+F14+F23 -> 33.28 | G24: =G10+G11+G12+G13+G15+G16+G17+G18+G19+G21+G22+G14+G23 -> 128.32 | H24: =H10+H11+H12+H13+H15+H16+H17+H18+H19+H21+H22+H14+H23 -> 33.28 | I24: =SUM(I10:I23) -> 128.32 | J24: =SUM(J10:J23) -> 33.28 | K24: =SUM(K10:K23) -> 128.32 | L24: =SUM(L10:L23) -> 33.28 | M24: =SUM(M10:M23) -> 128.32 | N24: =SUM(N10:N23) -> 33.28 | O24: =SUM(O10:O23) -> 157.61 | P24: =SUM(P10:P23) -> 33.28 | ... Y24: =SUM(Y10:Y23) -> 128.32 | Z24: =SUM(B24:Y24) -> 2140.64
A25: MANO DE OBRA POR KILOMETRAJE | B25: 19.4 | C25: 107.5 | D25: 14.11 | E25: 132.19 | F25: 14.11 | G25: 125.84 | H25: 14.11 | I25: 163.94 | J25: 14.11 | K25: 119.84 | L25: 14.11 | M25: 147.01 | N25: 14.11 | O25: 98.68 | P25: 14.11 | Q25: 132.19 | R25: 14.11 | S25: 129.37 | T25: 14.11 | U25: 264.49 | V25: 14.11 | W25: 107.5 | X25: 14.11 | Y25: 132.19
A26: ALINEACION | C26: 17.16 | E26: 17.16 | G26: 17.16 | I26: 17.16 | K26: 17.16 | M26: 17.16 | O26: 17.16 | Q26: 17.16 | S26: 17.16 | U26: 17.16 | W26: 17.16 | Y26: 17.16
A27: BALANCEO | C27: 15.84 | E27: 15.84 | G27: 15.84 | I27: 15.84 | K27: 15.84 | M27: 15.84 | O27: 15.84 | Q27: 15.84 | S27: 15.84 | U27: 15.84 | W27: 15.84 | Y27: 15.84
A28: LIMPIEZA DE INYECTORES | C28: 16.5 | E28: 16.5 | G28: 16.5 | I28: 16.5 | K28: 16.5 | M28: 16.5 | O28: 16.5 | Q28: 16.5 | S28: 16.5 | U28: 16.5 | W28: 16.5 | Y28: 16.5
A29: TOTAL MANO DE OBRA | B29: =SUM(B25:B28) -> 19.4 | C29: =SUM(C25:C28) -> 157 | D29: =SUM(D25:D28) -> 14.11 | E29: =SUM(E25:E28) -> 181.69 | F29: =SUM(F25:F28) -> 14.11 | G29: =SUM(G25:G28) -> 175.34 | H29: =SUM(H25:H28) -> 14.11 | I29: =SUM(I25:I28) -> 213.44 | ... Y29: =SUM(Y25:Y28) -> 181.69 | Z29: =SUM(B29:Y29) -> 2429.35
A30: TOTAL COSTO MANTENIMIENTO POR KILOMETRAJE | B30: =B9+B24+B29 -> 96.66 | C30: =C9+C24+C29 -> 329.3 | D30: =D9+D24+D29 -> 91.37 | E30: =E9+E24+E29 -> 353.99 | F30: =F9+F24+F29 -> 91.37 | G30: =G9+G24+G29 -> 352.64 | H30: =H9+H24+H29 -> 91.37 | I30: =I9+I24+I29 -> 385.74 | ... Y30: =Y9+Y24+Y29 -> 353.99

Sheet MANTENIMIENTOS EPMMOP
A2: WINGLE 7 DIESEL | B2: INTERMEDIOS | C2: 5000 | D2: 10000 | E2: 15000 | L2: CANTIDAD VEHICULOS
A3: ACEITE MOTOR | B3: ='W7 DIESEL 120K'!U1 -> INTERMEDIOS | C3: 40.98 | D3: 40.98 | E3: 40.98 | G3: COSTOS MANTENIMIENTO 5000 KM | L3: 12
A4: FILTRO DE ACEITE | B4: ='W7 DIESEL 120K'!U2 -> 40.98 | C4: 6.01 | D4: 6.01 | E4: 6.01 | G4: 1 | H4: Total lubricantes | I4: Mantenimiento preventivo | J4: =C26*L3 -> 1140.48
A5: FILTROS DE COMBUSTIBLE | B5: ='W7 DIESEL 120K'!U3 -> 6.01 | C5: 6.5 | D5: 6.5 | E5: 6.5 | G5: 2 | H5: Total repuestos | J5: =C21*L3 -> 402.72
A6: FILTRO TRAMPA DE AGUA/COMB | B6: ='W7 DIESEL 120K'!U4 -> 6.5 | C6: 17.55 | D6: 17.55 | E6: 17.55 | G6: 3 | H6: Total mano de obra | J6: =C22*L3 -> 232.8
A7: FILTRO DE AIRE | B7: ='W7 DIESEL 120K'!U5 -> 17.55 | D7: 10.45 | G7: Total 1 + 2 + 3 | J7: =SUM(J4:J6) -> 1776
A8: FILTRO DE CABINA A/C | B8: ='W7 DIESEL 120K'!U6 -> 0 | D8: 7.69 | G8: Costos no incluyen IVA
A9: PASTILLAS DE FRENO DEL | B9: ='W7 DIESEL 120K'!U7 -> 0 | D9: 26.87
A10: PASTILLAS DE FRENOS POST | B10: ='W7 DIESEL 120K'!U8 -> 0 | D10: 27 | G10: COSTOS MANTENIMIENTO 10000 KM | L10: 5
A11: LIQUIDO INYECTORES | B11: ='W7 DIESEL 120K'!U9 -> 0 | G11: 1 | H11: Total lubricantes | I11: Mantenimiento preventivo | J11: =D26*L10 -> 204.9
A12: LIMPIADOR DE FRENOS | B12: ='W7 DIESEL 120K'!U10 -> 0 | D12: 5 | G12: 2 | H12: Total repuestos | J12: =D21*L10 -> 579.85
A13: LIMPIADOR DE ADMISION | B13: ='W7 DIESEL 120K'!U11 -> 0 | D13: 5.4 | G13: 3 | H13: Total mano de obra | J13: =D22*L10 -> 785
A14: REFRIGERANTE | B14: ='W7 DIESEL 120K'!U12 -> 0 | G14: Total 1 + 2 + 3 | J14: =SUM(J11:J13) -> 1569.75
A15: DISTRIBUCION | B15: ='W7 DIESEL 120K'!U13 -> 0 | G15: Costos no incluyen IVA
A16: ACEITE DE CAJA | B16: ='W7 DIESEL 120K'!U14 -> 0 | C16: 31.56
A17: ACEITE DIFERENCIAL/TRANSFER | B17: ='W7 DIESEL 120K'!U15 -> 0 | C17: 22.5 | G17: COSTOS MANTENIMIENTO 15000 KM | L17: 4
A18: SUMINISTROS | B18: ='W7 DIESEL 120K'!U16 -> 0 | C18: 3.5 | D18: 3.5 | E18: 3.5 | G18: 1 | H18: Total lubricantes | I18: Mantenimiento preventivo | J18: =E26*L17 -> 163.92
A19: ACEITE DIRECCION HIDRAULICA | B19: ='W7 DIESEL 120K'!U17 -> 3.5 | G19: 2 | H19: Total repuestos | J19: =E21*L17 -> 134.24
A20: LIQUIDO DE FRENOS | B20: ='W7 DIESEL 120K'!U18 -> 0 | C20: 0 | D20: 0 | E20: 0 | G20: 3 | H20: Total mano de obra | J20: =E22*L17 -> 59.12
A21: TOTAL REPUESTOS | B21: =B4+B5+B6+B7+B9+B10+B11+B12+B13+B15+B18+B8 -> 71.04 | C21: =C4+C5+C6+C7+C9+C10+C11+C12+C13+C15+C18+C8 -> 33.56 | D21: =D4+D5+D6+D7+D9+D10+D11+D12+D13+D15+D18+D8 -> 115.97 | E21: =E4+E5+E6+E7+E9+E10+E11+E12+E13+E15+E18+E8 -> 33.56 | G21: Total 1 + 2 + 3 | J21: =SUM(J18:J20) -> 357.28
A22: TOTAL MANO DE OBRA | B22: ='W7 DIESEL 120K'!U20 -> 33.56 | C22: 19.4 | D22: 157 | E22: 14.78 | G22: Costos no incluyen IVA
A23: ALINEACION | B23: 0 | D23: 17.16
A24: BALANCEO | D24: 15.84
A25: LIMPIEZA DE INYECTORES | B25: 0
A26: *LUBRICANTES | B26: =B3+B14+B16+B17+B19+B20 -> #VALUE! | C26: =C3+C14+C16+C17+C19+C20 -> 95.04 | D26: =D3+D14+D16+D17+D19+D20 -> 40.98 | E26: =E3+E14+E16+E17+E19+E20 -> 40.98
